Workbook
Name Datenschnitt_Asset: #N/A
Name Datenschnitt_Klasse: #N/A

Sheet Daten
A1: datetime | B1: date | C1: account_type | D1: category | E1: type | F1: asset_class | G1: name | H1: symbol | I1: shares | J1: price | K1: amount | L1: fee | M1: tax | N1: currency | O1: original_amount | P1: original_currency | Q1: fx_rate | R1: description | S1: transaction_id | T1: counterparty_name | U1: counterparty_iban | V1: payment_reference | W1: mcc_code
A2: 46128.449 | B2: 46128 | C2: JUNIOR | D2: CASH | E2: TRANSFER_INSTANT_INBOUND | I2: 0 | J2: 0 | K2: 1 | L2: 0 | M2: 0 | N2: EUR | O2: 0 | Q2: 0 | R2: Incoming transfer from Romeo Talla Fotsing und Josiane Tefouemewe Tsamo (DE04731500000040868242) | S2: 019d9578-9464-7066-b494-7d7ac268c592
A3: 46128.49 | B3: 46128 | C3: JUNIOR | D3: CASH | E3: TRANSFER_INSTANT_INBOUND | I3: 0 | J3: 0 | K3: 200 | L3: 0 | M3: 0 | N3: EUR | O3: 0 | Q3: 0 | R3: Incoming transfer from Romeo Talla Fotsing und Josiane Tefouemewe Tsamo (DE04731500000040868242) | S3: 019d95ae-d14b-7ce5-9883-9075f8f497d4
A4: 46128.509 | B4: 46128 | C4: JUNIOR | D4: TRADING | E4: BUY | F4: FUND | G4: FTSE All-World USD (Acc) | H4: IE00BK5BQT80 | I4: 1 | J4: 151.76 | K4: -151.76 | L4: -1 | M4: 0 | N4: EUR | O4: 0 | Q4: 0 | R4: Buy trade IE00BK5BQT80 Vanguard Funds PLC - Vanguard FTSE All-World UCITS ETF (USD) Accumulating, quantity: 1 | S4: d9eaa861-91fb-45f4-acd7-b1b533f8c8b0
A5: 46128.509 | B5: 46128 | C5: JUNIOR | D5: TRADING | E5: BUY | F5: FUND | G5: FTSE All-World USD (Acc) | H5: IE00BK5BQT80 | I5: 0.31787 | J5: 151.76 | K5: -48.24 | L5: 0 | M5: 0 | N5: EUR | O5: 0 | Q5: 0 | R5: Buy trade IE00BK5BQT80 Vanguard Funds PLC - Vanguard FTSE All-World UCITS ETF (USD) Accumulating, quantity: 0.31787 | S5: 44551e93-932b-4042-bce5-98723e5fb807
A6: 46143.147 | B6: 46143 | C6: JUNIOR | D6: CASH | I6: 0 | J6: 0 | K6: 0.02 | L6: 0 | M6: 0 | N6: EUR | O6: 0 | Q6: 0 | R6: Kindergeld cash reward f0137a7c-f51f-4cbc-a3ab-c5840f6567af for reservation: dcbe6208-c733-4cb7-a3fe-c2437f4788a9 | S6: 019de129-ee19-7a66-bb90-2fdd54a6cb7b
A7: 46146.784 | B7: 46146 | C7: JUNIOR | D7: TRADING | E7: BUY | F7: FUND | G7: FTSE All-World USD (Acc) | H7: IE00BK5BQT80 | I7: 0.000128 | J7: 155.42 | K7: -0.02 | L7: 0 | M7: 0 | N7: EUR | O7: 0 | Q7: 0 | R7: Savings plan execution IE00BK5BQT80 Vanguard Funds PLC - Vanguard FTSE All-World UCITS ETF (USD) Accumulating, quantity: 0.000128 | S7: 050d3eb5-35ec-4240-9436-6aab52752344
A8: 46149.471 | B8: 46149 | C8: JUNIOR | D8: TRADING | E8: BUY | F8: FUND | G8: FTSE All-World USD (Acc) | H8: IE00BK5BQT80 | I8: 0.315696 | J8: 158.36 | K8: -49.99 | L8: -1 | M8: 0 | N8: EUR | O8: 0 | Q8: 0 | R8: Buy trade IE00BK5BQT80 Vanguard Funds PLC - Vanguard FTSE All-World UCITS ETF (USD) Accumulating, quantity: 0.315696 | S8: 18c05775-3699-469a-bdb8-37f71e68fa0d
A9: 46149.471 | B9: 46149 | C9: JUNIOR | D9: CASH | E9: TRANSFER_IN | G9: Roméo Talla Fotsing | I9: 0 | J9: 0 | K9: 51 | L9: 0 | M9: 0 | N9: EUR | O9: 0 | Q9: 0 | R9: Incoming transfer from Roméo Talla Fotsing (DE96100123455602601111) | S9: 019e01ba-e286-79b3-8ddb-5e62f083226b | T9: Roméo Talla Fotsing | U9: DE96100123455602601111
A10: 46169.943 | B10: 46169 | C10: JUNIOR | D10: CASH | E10: TRANSFER_IN | G10: Roméo Talla Fotsing | I10: 0 | J10: 0 | K10: 1 | L10: 0 | M10: 0 | N10: EUR | O10: 0 | Q10: 0 | R10: Incoming transfer from Roméo Talla Fotsing (DE96100123455602601111) | S10: 019e6b28-e107-75c0-9352-b746b4e26a47 | T10: Roméo Talla Fotsing | U10: DE96100123455602601111
A11: 46169.943 | B11: 46169 | C11: JUNIOR | D11: CASH | E11: TRANSFER_IN | G11: Roméo Talla Fotsing | I11: 0 | J11: 0 | K11: 50 | L11: 0 | M11: 0 | N11: EUR | O11: 0 | Q11: 0 | R11: Incoming transfer from Roméo Talla Fotsing (DE96100123455602601111) | S11: 019e6b28-1757-76f2-966d-e3c21525330a | T11: Roméo Talla Fotsing | U11: DE96100123455602601111
A12: 46169.943 | B12: 46169 | C12: JUNIOR | D12: TRADING | E12: BUY | F12: FUND | G12: FTSE All-World USD (Acc) | H12: IE00BK5BQT80 | I12: 0.307012 | J12: 162.82 | K12: -49.99 | L12: -1 | M12: 0 | N12: EUR | O12: 0 | Q12: 0 | R12: Buy trade IE00BK5BQT80 Vanguard Funds PLC - Vanguard FTSE All-World UCITS ETF (USD) Accumulating, quantity: 0.307012 | S12: 20544b6f-9fba-4929-9599-bc1bcee23b68
A13: 46174.252 | B13: 46174 | C13: JUNIOR | D13: CASH | I13: 0 | J13: 0 | K13: 0.04 | L13: 0 | M13: 0 | N13: EUR | O13: 0 | Q13: 0 | R13: Kindergeld cash reward d3526df3-cfef-4382-88ef-2ac6f467847b for reservation: 9d2d0c67-b16e-4b64-a09a-565b3eda42f7 | S13: 019e8159-e26c-7cbd-b04e-a5847cf30331
A14: 46175.837 | B14: 46175 | C14: JUNIOR | D14: TRADING | E14: BUY | F14: FUND | G14: FTSE All-World USD (Acc) | H14: IE00BK5BQT80 | I14: 0.000242 | J14: 164.7 | K14: -0.04 | L14: 0 | M14: 0 | N14: EUR | O14: 0 | Q14: 0 | R14: Savings plan execution IE00BK5BQT80 Vanguard Funds PLC - Vanguard FTSE All-World UCITS ETF (USD) Accumulating, quantity: 0.000242 | S14: e9db5bfb-b872-4d5b-b992-76abf489b7f7
A15: 46199.678 | B15: 46199 | C15: JUNIOR | D15: TRADING | E15: BUY | F15: FUND | G15: FTSE All-World USD (Acc) | H15: IE00BK5BQT80 | I15: 0.30656 | J15: 163.1 | K15: -50 | L15: -1 | M15: 0 | N15: EUR | O15: 0 | Q15: 0 | R15: Buy trade IE00BK5BQT80 Vanguard Funds PLC - Vanguard FTSE All-World UCITS ETF (USD) Accumulating, quantity: 0.30656 | S15: aface5e1-5949-467c-bc1d-83b0cb743731
A16: 46199.678 | B16: 46199 | C16: JUNIOR | D16: CASH | E16: TRANSFER_IN | G16: Roméo Talla Fotsing | I16: 0 | J16: 0 | K16: 51 | L16: 0 | M16: 0 | N16: EUR | O16: 0 | Q16: 0 | R16: Incoming transfer from Roméo Talla Fotsing (DE96100123455602601111) | S16: 019f044a-0bbd-74ea-bbce-e1dd99586a97 | T16: Roméo Talla Fotsing | U16: DE96100123455602601111
A17: 46204.271 | B17: 46204 | C17: JUNIOR | D17: CASH | I17: 0 | J17: 0 | K17: 0.05 | L17: 0 | M17: 0 | N17: EUR | O17: 0 | Q17: 0 | R17: Kindergeld cash reward f80d1401-18a2-41c1-a61b-c663837bc8c4 for reservation: caef7b51-c0a4-436f-beb3-21eba9270f8d | S17: 019f1bf1-99ea-7a67-bc47-a5229c698d9b
A18: 46205.747 | B18: 46205 | C18: JUNIOR | D18: TRADING | E18: BUY | F18: FUND | G18: FTSE All-World USD (Acc) | H18: IE00BK5BQT80 | I18: 0.000302 | J18: 165.46 | K18: -0.05 | L18: 0 | M18: 0 | N18: EUR | O18: 0 | Q18: 0 | R18: Savings plan execution IE00BK5BQT80 Vanguard Funds PLC - Vanguard FTSE All-World UCITS ETF (USD) Accumulating, quantity: 0.000302 | S18: a352de68-a694-4141-97d1-d0c77c5aa306
A19: 46232.953 | B19: 46232 | C19: JUNIOR | D19: CASH | E19: TRANSFER_IN | G19: Roméo Talla Fotsing | I19: 0 | J19: 0 | K19: 51 | L19: 0 | M19: 0 | N19: EUR | O19: 0 | Q19: 0 | R19: Incoming transfer from Roméo Talla Fotsing (DE96100123455602601111) | S19: 019fafa6-64d6-770e-98c7-80d506bc35bd | T19: Roméo Talla Fotsing | U19: DE96100123455602601111
A20: 46232.953 | B20: 46232 | C20: JUNIOR | D20: TRADING | E20: BUY | F20: FUND | G20: FTSE All-World USD (Acc) | H20: IE00BK5BQT80 | I20: 0.311293 | J20: 160.62 | K20: -50 | L20: -1 | M20: 0 | N20: EUR | O20: 0 | Q20: 0 | R20: Buy trade IE00BK5BQT80 Vanguard Funds PLC - Vanguard FTSE All-World UCITS ETF (USD) Accumulating, quantity: 0.311293 | S20: bcdfc290-4bb4-47e7-b4ee-65b1acb4411a
A21: 46237.162 | B21: 46237 | C21: JUNIOR | D21: CASH | I21: 0 | J21: 0 | K21: 0.06 | L21: 0 | M21: 0 | N21: EUR | O21: 0 | Q21: 0 | R21: Kindergeld cash reward 719268aa-ecb8-489a-83fe-8e57eb695941 for reservation: 7c9117b3-b83a-4f74-9968-a7cbaf44d458 | S21: 019fc552-b875-733e-b79c-090eb869efaf
A22: 46237.779 | B22: 46237 | C22: JUNIOR | D22: TRADING | E22: BUY | F22: FUND | G22: FTSE All-World USD (Acc) | H22: IE00BK5BQT80 | I22: 0.000363 | J22: 164.9401 | K22: -0.06 | L22: 0 | M22: 0 | N22: EUR | O22: 0 | Q22: 0 | R22: Savings plan execution IE00BK5BQT80 Vanguard Funds PLC - Vanguard FTSE All-World UCITS ETF (USD) Accumulating, quantity: 0.000363 | S22: b2d934f7-b091-4be5-86fe-791b8d089507
A23: 46266.183 | B23: 46266 | C23: JUNIOR | D23: CASH | I23: 0 | J23: 0 | K23: 0.05 | L23: 0 | M23: 0 | N23: EUR | O23: 0 | Q23: 0 | R23: Kindergeld cash reward e24fd1ba-ac78-4878-aa65-c7b545fade5a for reservation: cd2ec422-4fbd-4dc0-9dc0-61206c8b41cc | S23: 01a05ac6-c260-7b22-9178-9edffc0c30ef
A24: 46267.739 | B24: 46267 | C24: JUNIOR | D24: TRADING | E24: BUY | F24: FUND | G24: FTSE All-World USD (Acc) | H24: IE00BK5BQT80 | I24: 0.000299 | J24: 166.9 | K24: -0.05 | L24: 0 | M24: 0 | N24: EUR | O24: 0 | Q24: 0 | R24: Savings plan execution IE00BK5BQT80 Vanguard Funds PLC - Vanguard FTSE All-World UCITS ETF (USD) Accumulating, quantity: 0.000299 | S24: efb1c7fd-2a9e-4536-884f-4d1a66aa44ba

Sheet Auswertung
A1: Asset | B1: Klasse | C1: Symbol | D1: Käufe Stück | E1: Verkäufe Stück | F1: Bestand | G1: Investiert € | H1: Verkauft € | I1: Gebühren € | J1: Netto P&L € | K1: Status | L1: Einstandskurs € | M1: Aktueller Kurs € | N1: Aktuell nicht realisierte P&L € | O1: Aktuelle Position € | P1: Aktuell Investiert € | Q1: Aktuelle Rendite | R1: Realisierte P&L Verkäufe € | S1: Investiertes Kapital Verkäufe € | T1: Anzahl Kauforders | U1: Anzahl Verkaufsorders | V1: Rendite Verkäufe | W1: Gesamte Rendite
A2: FTSE All-World USD (Acc) | B2: FUND | C2: IE00BK5BQT80 | D2: =SUMIFS(Daten!I:I,Daten!H:H,C2,Daten!E:E,"BUY") -> 2.559765 | E2: =-SUMIFS(Daten!I:I,Daten!H:H,C2,Daten!E:E,"SELL") -> 0 | F2: =D2-E2 -> 2.559765 | G2: =-SUMIFS(Daten!K:K,Daten!H:H,C2,Daten!E:E,"BUY") -> 400.2 | H2: =SUMIFS(Daten!K:K,Daten!H:H,C2,Daten!E:E,"SELL") -> 0 | I2: =SUMIFS(Daten!L:L,Daten!H:H,C2)*-1 -> 5 | J2: =H2-G2-I2 -> -405.2 | K2: =IF(F2>0,"OFFEN","GESCHLOSSEN") -> OFFEN | L2: 158.21 | M2: 169.74 | N2: =IF(K2="GESCHLOSSEN", 0, IF(K2="OFFEN", ((M2*F2)-(L2*F2)), "")) -> 29.51409 | O2: =IF(F2>0,F2*M2,0) -> 434.49451 | P2: =IF(F2>0,F2*L2,0) -> 404.98042 | Q2: =IF(K2="GESCHLOSSEN", 0, IF(K2="OFFEN", (N2/(L2*F2)))) -> 0.072877821 | R2: =IF(K2="GESCHLOSSEN", H2-G2-I2 + SUMIFS(Daten!K:K,Daten!H:H,C2,Daten!E:E,"DIVIDEND"), IF(K2="OFFEN", IF(E2=0, 0, H2+SUMIFS(Daten!K:K,Daten!H:H,C2,Daten!E:E,"DIVIDEND")-(G2-(F2*L2))-I2 ), "")) -> 0 | S2: =IF(E2=0, 0, (G2-(F2*L2))+I2 ) -> 0 | T2: =COUNTIFS(Daten!H:H,C2,Daten!E:E,"BUY",Daten!L:L,"<0") -> 5 | U2: =COUNTIFS(Daten!H:H,C2,Daten!E:E,"SELL",Daten!L:L,"<0") -> 0 | V2: =IF(S2>0,R2/S2,0) -> 0 | W2: =IF(K2="GESCHLOSSEN", J2/(G2+I2), IF(K2="OFFEN", ((H2+M2*F2)-G2-I2)/G2, "")) -> 0.073199678
AB76: =IF(K9="GESCHLOSSEN", 0, IF(K9="OFFEN", IF(E2=0, G9+I9, H2+SUMIFS(Daten!K:K,Daten!G:G,A2,Daten!E:E,"DIVIDEND")-(G2-(F2*L2))-I2 ), "")) | AC76: =IF(K6="GESCHLOSSEN", H6-G6-I6 + SUMIFS(Daten!K:K,Daten!G:G,A6,Daten!E:E,"DIVIDEND"), IF(K6="OFFEN", IF(E6=0, -I6, H6+SUMIFS(Daten!K:K,Daten!G:G,A6,Daten!E:E,"DIVIDEND")-(G6-(F6*L6))-I6 ), ""))
AC77: =H2 -(G2-(F2*L2)) -I2 -> -0.21957935
AC78: =H4-G4-I4 + SUMIFS(Daten!K:K,Daten!G:G,A4,Daten!E:E,"DIVIDEND") -> 0
AC83: =_xlfn.MAXIFS(Daten!B:B,Daten!G:G,A14,Daten!E:E,"SELL") -> 0 | AD83: =SUMIFS(Daten!L:L,Daten!G:G,A14,Daten!E:E,"BUY",Daten!B:B,"<"&_xlfn.MAXIFS(Daten!B:B,Daten!G:G,A14,Daten!E:E,"SELL"))*-1 -> 0
AC84: =SUMIFS(Daten!L:L,Daten!G:G,A14,Daten!E:E,"BUY")*-1 -> 0 | AD84: =SUMIFS(Daten!L:L,Daten!G:G,A14,Daten!E:E,"BUY",Daten!B:B,"<"&AC83)*-1 -> 0
AC85: =SUMIFS(Daten!L:L,Daten!G:G,A14,Daten!E:E,"SELL")*-1 -> 0
AC86: =H14-(G14-(F14*L14))-SUMIFS(Daten!L:L,Daten!G:G,A14,Daten!E:E,"SELL")*-1 -> 0 | AD86: =H14-(G14-(F14*L14))-SUMIFS(Daten!L:L,Daten!G:G,A14,Daten!E:E,"SELL")*-1 - SUMIFS(Daten!L:L,Daten!G:G,A14,Daten!E:E,"BUY",Daten!B:B,"<"&_xlfn.MAXIFS(Daten!B:B,Daten!G:G,A14,Daten!E:E,"SELL"))*-1 -> 0

Sheet Dashboard
A1: Portfolio KPIs
A3: Anzahl Assets | B3: =COUNTA(Auswertung!A:A) - 1 -> 1 | C3: =IF(ABS(B3)>0,B3/B3,0) -> 1
A4: Anzahl STOCK | B4: =COUNTIFS(Auswertung!B:B,"STOCK") -> 0 | C4: =IF(ABS(B3)>0,B4/B3,0) -> 0
A5: Anzahl FUND | B5: =COUNTIFS(Auswertung!B:B,"FUND") -> 1 | C5: =IF(ABS(B3)>0,B5/B3,0) -> 1
A6: Anzahl CRYPTO | B6: =COUNTIFS(Auswertung!B:B,"CRYPTO") -> 0 | C6: =IF(ABS(B3)>0,B6/B3,0) -> 0
A8: Offene Assets | B8: =COUNTIFS(Auswertung!K:K,"OFFEN") -> 1 | C8: =IF(ABS(B8)>0,B8/B8,0) -> 1
A9: Offene STOCK | B9: =COUNTIFS(Auswertung!B:B,"STOCK",Auswertung!K:K,"OFFEN") -> 0 | C9: =IF(ABS(B8)>0,B9/B8,0) -> 0
A10: Offene FUND | B10: =COUNTIFS(Auswertung!B:B,"FUND",Auswertung!K:K,"OFFEN") -> 1 | C10: =IF(ABS(B8)>0,B10/B8,0) -> 1
A11: Offene CRYPTO | B11: =COUNTIFS(Auswertung!B:B,"CRYPTO",Auswertung!K:K,"OFFEN") -> 0 | C11: =IF(ABS(B8)>0,B11/B8,0) -> 0
A13: Closed Assets | B13: =COUNTIFS(Auswertung!K:K,"GESCHLOSSEN") -> 0
A14: Closed STOCK | B14: =COUNTIFS(Auswertung!B:B,"STOCK",Auswertung!K:K,"GESCHLOSSEN") -> 0
A15: Closed FUND | B15: =COUNTIFS(Auswertung!B:B,"FUND",Auswertung!K:K,"GESCHLOSSEN") -> 0
A16: Closed CRYPTO | B16: =COUNTIFS(Auswertung!B:B,"CRYPTO",Auswertung!K:K,"GESCHLOSSEN") -> 0
A18: Brutto Investiert | B18: =SUM(Auswertung!G:G)-SUMIFS(Daten!L:L,Daten!E:E,"BUY") -> 405.2 | D18: =-SUMIFS(Daten!K:K,Daten!E:E,"BUY")-SUMIFS(Daten!L:L,Daten!E:E,"BUY") -> 405.2
A19: Brutto Investiert STOCK&FUND | B19: =SUMIFS(Auswertung!G:G,Auswertung!B:B,"STOCK")+SUMIFS(Auswertung!G:G,Auswertung!B:B,"FUND")-SUMIFS(Daten!L:L,Daten!E:E,"BUY",Daten!F:F,"STOCK")-SUMIFS(Daten!L:L,Daten!E:E,"BUY",Daten!F:F,"FUND") -> 405.2 | C19: =IF(ABS(B18)>0,B19/B18,0) -> 1 | D19: =-SUMIFS(Daten!K:K,Daten!F:F,"STOCK",Daten!E:E,"BUY")-SUMIFS(Daten!K:K,Daten!F:F,"FUND",Daten!E:E,"BUY")-SUMIFS(Daten!L:L,Daten!E:E,"BUY",Daten!F:F,"STOCK")-SUMIFS(Daten!L:L,Daten!E:E,"BUY",Daten!F:F,"FUND") -> 405.2
A20: Brutto Investiert STOCK | B20: =SUMIFS(Auswertung!G:G,Auswertung!B:B,"STOCK")-SUMIFS(Daten!L:L,Daten!E:E,"BUY",Daten!F:F,"STOCK") -> 0 | C20: =IF(ABS(B18)>0,B20/B18,0) -> 0 | D20: =-SUMIFS(Daten!K:K,Daten!F:F,"STOCK",Daten!E:E,"BUY")-SUMIFS(Daten!L:L,Daten!E:E,"BUY",Daten!F:F,"STOCK") -> 0
A21: Brutto Investiert FUND | B21: =SUMIFS(Auswertung!G:G,Auswertung!B:B,"FUND")-SUMIFS(Daten!L:L,Daten!E:E,"BUY",Daten!F:F,"FUND") -> 405.2 | C21: =IF(ABS(B18)>0,B21/B18,0) -> 1 | D21: =-SUMIFS(Daten!K:K,Daten!F:F,"FUND",Daten!E:E,"BUY")-SUMIFS(Daten!L:L,Daten!E:E,"BUY",Daten!F:F,"FUND") -> 405.2
A22: Brutto Investiert CRYPTO | B22: =SUMIFS(Auswertung!G:G,Auswertung!B:B,"CRYPTO")-SUMIFS(Daten!L:L,Daten!E:E,"BUY",Daten!F:F,"CRYPTO") -> 0 | C22: =IF(ABS(B18)>0,B22/B18,0) -> 0 | D22: =-SUMIFS(Daten!K:K,Daten!F:F,"CRYPTO",Daten!E:E,"BUY")-SUMIFS(Daten!L:L,Daten!E:E,"BUY",Daten!F:F,"CRYPTO") -> 0
A24: Netto Investiert | B24: =SUM(Auswertung!G:G) -> 400.2 | D24: =-SUMIFS(Daten!K:K,Daten!E:E,"BUY") -> 400.2
A25: Netto Investiert STOCK&FUND | B25: =SUMIFS(Auswertung!G:G,Auswertung!B:B,"STOCK")+SUMIFS(Auswertung!G:G,Auswertung!B:B,"FUND") -> 400.2 | C25: =IF(ABS(B24)>0,B25/B24,0) -> 1 | D25: =-SUMIFS(Daten!K:K,Daten!F:F,"STOCK",Daten!E:E,"BUY")-SUMIFS(Daten!K:K,Daten!F:F,"FUND",Daten!E:E,"BUY") -> 400.2
A26: Netto Investiert STOCK | B26: =SUMIFS(Auswertung!G:G,Auswertung!B:B,"STOCK") -> 0 | C26: =IF(ABS(B24)>0,B26/B24,0) -> 0 | D26: =-SUMIFS(Daten!K:K,Daten!F:F,"STOCK",Daten!E:E,"BUY") -> 0
A27: Netto Investiert FUND | B27: =SUMIFS(Auswertung!G:G,Auswertung!B:B,"FUND") -> 400.2 | C27: =IF(ABS(B24)>0,B27/B24,0) -> 1 | D27: =-SUMIFS(Daten!K:K,Daten!F:F,"FUND",Daten!E:E,"BUY") -> 400.2
A28: Netto Investiert CRYPTO | B28: =SUMIFS(Auswertung!G:G,Auswertung!B:B,"CRYPTO") -> 0 | C28: =IF(ABS(B24)>0,B28/B24,0) -> 0 | D28: =-SUMIFS(Daten!K:K,Daten!F:F,"CRYPTO",Daten!E:E,"BUY") -> 0
A30: Brutto Verkauft | B30: =SUM(Auswertung!H:H)-SUMIFS(Daten!L:L,Daten!E:E,"SELL") -> 0 | D30: =SUMIFS(Daten!K:K,Daten!E:E,"SELL")-SUMIFS(Daten!L:L,Daten!E:E,"SELL") -> 0
A31: Brutto Verkauft STOCK&FUND | B31: =SUMIFS(Auswertung!H:H,Auswertung!B:B,"STOCK")+SUMIFS(Auswertung!H:H,Auswertung!B:B,"FUND")-SUMIFS(Daten!L:L,Daten!E:E,"SELL",Daten!F:F,"STOCK")-SUMIFS(Daten!L:L,Daten!E:E,"SELL",Daten!F:F,"FUND") -> 0 | C31: =IF(ABS(B30)>0,B31/B30,0) -> 0 | D31: =SUMIFS(Daten!K:K,Daten!F:F,"STOCK",Daten!E:E,"SELL")+SUMIFS(Daten!K:K,Daten!F:F,"FUND",Daten!E:E,"SELL")-SUMIFS(Daten!L:L,Daten!E:E,"SELL",Daten!F:F,"STOCK")-SUMIFS(Daten!L:L,Daten!E:E,"SELL",Daten!F:F,"FUND") -> 0
A32: Brutto Verkauft STOCK | B32: =SUMIFS(Auswertung!H:H,Auswertung!B:B,"STOCK")-SUMIFS(Daten!L:L,Daten!E:E,"SELL",Daten!F:F,"STOCK") -> 0 | C32: =IF(ABS(B30)>0,B32/B30,0) -> 0 | D32: =SUMIFS(Daten!K:K,Daten!F:F,"STOCK",Daten!E:E,"SELL")-SUMIFS(Daten!L:L,Daten!E:E,"SELL",Daten!F:F,"STOCK") -> 0
A33: Brutto Verkauft FUND | B33: =SUMIFS(Auswertung!H:H,Auswertung!B:B,"FUND")-SUMIFS(Daten!L:L,Daten!E:E,"SELL",Daten!F:F,"FUND") -> 0 | C33: =IF(ABS(B30)>0,B33/B30,0) -> 0 | D33: =SUMIFS(Daten!K:K,Daten!F:F,"FUND",Daten!E:E,"SELL")-SUMIFS(Daten!L:L,Daten!E:E,"SELL",Daten!F:F,"FUND") -> 0
A34: Brutto Verkauft CRYPTO | B34: =SUMIFS(Auswertung!H:H,Auswertung!B:B,"CRYPTO")-SUMIFS(Daten!L:L,Daten!E:E,"SELL",Daten!F:F,"CRYPTO") -> 0 | C34: =IF(ABS(B30)>0,B33/B30,0) -> 0 | D34: =SUMIFS(Daten!K:K,Daten!F:F,"CRYPTO",Daten!E:E,"SELL")-SUMIFS(Daten!L:L,Daten!E:E,"SELL",Daten!F:F,"CRYPTO") -> 0
A36: Netto Verkauft | B36: =SUM(Auswertung!H:H) -> 0 | D36: =SUMIFS(Daten!K:K,Daten!E:E,"SELL") -> 0
A37: Netto Verkauft STOCK&FUND | B37: =SUMIFS(Auswertung!H:H,Auswertung!B:B,"STOCK")+SUMIFS(Auswertung!H:H,Auswertung!B:B,"FUND") -> 0 | C37: =IF(ABS(B36)>0,B37/B36,0) -> 0 | D37: =SUMIFS(Daten!K:K,Daten!F:F,"STOCK",Daten!E:E,"SELL")+SUMIFS(Daten!K:K,Daten!F:F,"FUND",Daten!E:E,"SELL") -> 0
A38: Netto Verkauft STOCK | B38: =SUMIFS(Auswertung!H:H,Auswertung!B:B,"STOCK") -> 0 | C38: =IF(ABS(B36)>0,B38/B36,0) -> 0 | D38: =SUMIFS(Daten!K:K,Daten!F:F,"STOCK",Daten!E:E,"SELL") -> 0
A39: Netto Verkauft FUND | B39: =SUMIFS(Auswertung!H:H,Auswertung!B:B,"FUND") -> 0 | C39: =IF(ABS(B36)>0,B39/B36,0) -> 0 | D39: =SUMIFS(Daten!K:K,Daten!F:F,"FUND",Daten!E:E,"SELL") -> 0
A40: Netto Verkauft CRYPTO | B40: =SUMIFS(Auswertung!H:H,Auswertung!B:B,"CRYPTO") -> 0 | C40: =IF(ABS(B36)>0,B40/B36,0) -> 0 | D40: =SUMIFS(Daten!K:K,Daten!F:F,"CRYPTO",Daten!E:E,"SELL") -> 0
A42: Gebühren | B42: =SUM(Auswertung!I:I) -> 5 | C42: =-SUM(Daten!L:L) -> 5
A43: Gebüren STOCK&FUND | B43: =SUMIFS(Auswertung!I:I,Auswertung!B:B,"STOCK")+SUMIFS(Auswertung!I:I,Auswertung!B:B,"FUND") -> 5 | C43: =-SUMIFS(Daten!L:L,Daten!F:F,"STOCK")-SUMIFS(Daten!L:L,Daten!F:F,"FUND") -> 5 | D43: =IF(ABS(C42)>0,C43/C42,0) -> 1
A44: Gebüren STOCK | B44: =SUMIFS(Auswertung!I:I,Auswertung!B:B,"STOCK") -> 0 | C44: =-SUMIFS(Daten!L:L,Daten!F:F,"STOCK") -> 0 | D44: =IF(ABS(C42)>0,C44/C42,0) -> 0
A45: Gebüren FUND | B45: =SUMIFS(Auswertung!I:I,Auswertung!B:B,"FUND") -> 5 | C45: =-SUMIFS(Daten!L:L,Daten!F:F,"FUND") -> 5 | D45: =IF(ABS(C42)>0,C45/C42,0) -> 1
A46: Gebühren CRYPTO | B46: =SUMIFS(Auswertung!I:I,Auswertung!B:B,"CRYPTO") -> 0 | C46: =-SUMIFS(Daten!L:L,Daten!F:F,"CRYPTO") -> 0 | D46: =IF(ABS(C42)>0,C46/C42,0) -> 0
A48: Gebühren Käufe | B48: =-SUMIFS(Daten!L:L,Daten!E:E,"BUY") -> 5
A49: Gebüren Käufe STOCK&FUND | B49: =-SUMIFS(Daten!L:L,Daten!E:E,"BUY",Daten!F:F,"STOCK")-SUMIFS(Daten!L:L,Daten!E:E,"BUY",Daten!F:F,"FUND") -> 5 | C49: =IF(ABS(B48)>0,B49/B48,0) -> 1
...

Sheet Pivot
A3: Assets | B3: Einkaufswert | C3: Aktueller Wert | E3: Aktueller Wert | G3: Aktueller Wert | J3: Einkaufswert | L3: Verkaufserlöse Gewinn/Verlust
A4: FUND | B4: 404.98042 | C4: 434.49451 | E4: 434.49451 | G4: 434.49451 | J4: 404.98042 | L4: 0
A5: (Leer) | I5: G/V:
A6: Gesamtergebnis | B6: 404.98042 | C6: 434.49451 | E6: =GETPIVOTDATA("Aktuelle Position €",$E$3) -> 434.49451 | G6: =GETPIVOTDATA("Aktuelle Position €",$G$3) -> 434.49451 | I6: =G6-J6 -> 29.51409 | J6: =GETPIVOTDATA("Aktuell Investiert €",$J$3) -> 404.98042 | L6: =GETPIVOTDATA("Realisierte P&L Verkäufe €",$L$3) -> 0
A13: Assets | B13: Aktueller Wert | E13: Assets | F13: Aktueller Wert
A14: FUND | B14: 434.49451 | E14: FUND | F14: 434.49451
A15: FTSE All-World USD (Acc) | B15: 434.49451 | E15: (Leer)
A16: (Leer) | E16: Gesamtergebnis | F16: 434.49451
A17: (Leer)
A18: Gesamtergebnis | B18: 434.49451

Sheet Portfolio
A8: Assets | B8: Bestand | C8: Kurswert | D8: Aktueller Wert
A9: FUND
A10: FTSE All-World USD (Acc) | B10: 2.559765 | C10: 169.74 | D10: 434.49451
A11: FUND Ergebnis | B11: 2.559765 | C11: 169.74 | D11: 434.49451
A13: (Leer)
A14: (Leer)
A15: (Leer) Ergebnis
A17: Gesamtergebnis | B17: 2.559765 | C17: 169.74 | D17: 434.49451

Sheet Auswertung_2026

Sheet Auswertung_2025

Sheet Definitions
A1: KPI | B1: Bedeutung
A2: Portfolio-Wert | B2: Aktueller Gesamtwert aller Positionen
A3: Investiertes Kapital | B3: Summe aller Einzahlungen und Käufe
A4: Gewinn/Verlust (P&L) | B4: Wie viel Gewinn(Proft) oder Verlust(Lost) erzielt wurde
A5: Rendite (%) | B5: Gewinn oder Verlust im Verhältnis zum eingesetzten Kapital
A6: Anzahl Positionen | B6: Wie viele Wertpapiere/Kryptos im Portfolio sind
A7: Asset-Allokation | B7: Verteilung auf Aktien, ETFs, Krypto usw.
A8: Cash-Bestand | B8: Nicht investiertes Guthaben
A9: Gebühren | B9: Summe aller Handelskosten
A10: Realisierte Gewinne | B10: Gewinne aus bereits verkauften Positionen
A11: Nicht realisierte Gewinne | B11: Gewinne/Verluste aus aktuellen Positionen
