Workbook
Name Datenschnitt_Asset: #N/A
Name Datenschnitt_Klasse: #N/A

Sheet Daten
A1: datetime | B1: date | C1: account_type | D1: category | E1: type | F1: asset_class | G1: name | H1: symbol | I1: shares | J1: price | K1: amount | L1: fee | M1: tax | N1: currency | O1: original_amount | P1: original_currency | Q1: fx_rate | R1: description | S1: transaction_id | T1: counterparty_name | U1: counterparty_iban | V1: payment_reference | W1: mcc_code
A2: 46127.386 | B2: 46127 | C2: JUNIOR | D2: CASH | E2: TRANSFER_IN | I2: 0 | J2: 0 | K2: 10 | L2: 0 | M2: 0 | N2: EUR | O2: 0 | Q2: 0 | R2: Incoming transfer from Roméo Talla Fotsing (DE96100123455602601111) | S2: 019d8fff-883f-7691-b1a0-d7be7cf45875
A3: 46127.741 | B3: 46127 | C3: JUNIOR | D3: CASH | E3: TRANSFER_OUT | I3: 0 | J3: 0 | K3: -10 | L3: 0 | M3: 0 | N3: EUR | O3: 0 | Q3: 0 | R3: Outgoing transfer for Roméo Talla Fotsing (DE96100123455602601111) | S3: 019d91d3-0c5c-7f8d-a688-973edea44017
A4: 46128.442 | B4: 46128 | C4: JUNIOR | D4: CASH | E4: TRANSFER_INSTANT_INBOUND | I4: 0 | J4: 0 | K4: 1 | L4: 0 | M4: 0 | N4: EUR | O4: 0 | Q4: 0 | R4: Incoming transfer from Romeo Talla Fotsing und Josiane Tefouemewe Tsamo (DE04731500000040868242) | S4: 019d956f-c4f6-79bc-929e-d14af3a26907
A5: 46128.488 | B5: 46128 | C5: JUNIOR | D5: CASH | E5: TRANSFER_INSTANT_INBOUND | I5: 0 | J5: 0 | K5: 200 | L5: 0 | M5: 0 | N5: EUR | O5: 0 | Q5: 0 | R5: Incoming transfer from Romeo Talla Fotsing und Josiane Tefouemewe Tsamo (DE04731500000040868242) | S5: 019d95ac-4023-7176-b841-3cb64639177d
A6: 46128.508 | B6: 46128 | C6: JUNIOR | D6: TRADING | E6: BUY | F6: FUND | G6: FTSE All-World USD (Acc) | H6: IE00BK5BQT80 | I6: 1 | J6: 151.78 | K6: -151.78 | L6: -1 | M6: 0 | N6: EUR | O6: 0 | Q6: 0 | R6: Buy trade IE00BK5BQT80 Vanguard Funds PLC - Vanguard FTSE All-World UCITS ETF (USD) Accumulating, quantity: 1 | S6: 83394b0d-c02f-417d-8aef-f45a52798140
A7: 46128.508 | B7: 46128 | C7: JUNIOR | D7: TRADING | E7: BUY | F7: FUND | G7: FTSE All-World USD (Acc) | H7: IE00BK5BQT80 | I7: 0.31787 | J7: 151.78 | K7: -48.25 | L7: 0 | M7: 0 | N7: EUR | O7: 0 | Q7: 0 | R7: Buy trade IE00BK5BQT80 Vanguard Funds PLC - Vanguard FTSE All-World UCITS ETF (USD) Accumulating, quantity: 0.31787 | S7: 26aa346e-f107-4aaf-803a-c2489e040d34
A8: 46128.836 | B8: 46128 | C8: JUNIOR | D8: CASH | E8: TRANSFER_INSTANT_INBOUND | I8: 0 | J8: 0 | K8: 60 | L8: 0 | M8: 0 | N8: EUR | O8: 0 | Q8: 0 | R8: Incoming transfer from ROMEO TALLA FOTSING (DE16300209005310514271) | S8: 019d9776-48b1-74ea-85a1-887b5bba56bc
A9: 46128.839 | B9: 46128 | C9: JUNIOR | D9: TRADING | E9: BUY | F9: FUND | G9: FTSE All-World USD (Acc) | H9: IE00BK5BQT80 | I9: 0.389336 | J9: 151.54 | K9: -59 | L9: -1 | M9: 0 | N9: EUR | O9: 0 | Q9: 0 | R9: Buy trade IE00BK5BQT80 Vanguard Funds PLC - Vanguard FTSE All-World UCITS ETF (USD) Accumulating, quantity: 0.389336 | S9: e9e39643-a2b2-4ccf-87af-1f2ffafc8431
A10: 46128.84 | B10: 46128 | C10: JUNIOR | D10: CASH | E10: TRANSFER_OUT | I10: 0 | J10: 0 | K10: -0.27 | L10: 0 | M10: 0 | N10: EUR | O10: 0 | Q10: 0 | R10: Outgoing transfer for Roméo Talla Fotsing (DE96100123455602601111) | S10: 019d977b-58c3-7807-9406-0778a9794523
A11: 46128.838 | B11: 46128 | C11: JUNIOR | D11: CASH | E11: TRANSFER_INSTANT_INBOUND | I11: 0 | J11: 0 | K11: 0.3 | L11: 0 | M11: 0 | N11: EUR | O11: 0 | Q11: 0 | R11: Incoming transfer from ROMEO TALLA FOTSING (DE16300209005310514271) | S11: 019d9779-70c1-7c80-91e5-69ef8fb76c2a
A12: 46143.135 | B12: 46143 | C12: JUNIOR | D12: CASH | I12: 0 | J12: 0 | K12: 0.02 | L12: 0 | M12: 0 | N12: EUR | O12: 0 | Q12: 0 | R12: Kindergeld cash reward 1c971be4-8592-4cb4-acb0-61395e0b67d1 for reservation: c345759e-d06a-4555-b2d1-cab44018f7e5 | S12: 019de11a-7bd6-77eb-bf66-edc10872aeec
A13: 46146.78 | B13: 46146 | C13: JUNIOR | D13: TRADING | E13: BUY | F13: FUND | G13: FTSE All-World USD (Acc) | H13: IE00BK5BQT80 | I13: 0.000128 | J13: 155.46 | K13: -0.02 | L13: 0 | M13: 0 | N13: EUR | O13: 0 | Q13: 0 | R13: Savings plan execution IE00BK5BQT80 Vanguard Funds PLC - Vanguard FTSE All-World UCITS ETF (USD) Accumulating, quantity: 0.000128 | S13: 9817eb8e-0953-463d-ac84-e3d7993d86fe
A14: 46149.47 | B14: 46149 | C14: JUNIOR | D14: TRADING | E14: BUY | F14: FUND | G14: FTSE All-World USD (Acc) | H14: IE00BK5BQT80 | I14: 0.315736 | J14: 158.36 | K14: -50 | L14: -1 | M14: 0 | N14: EUR | O14: 0 | Q14: 0 | R14: Buy trade IE00BK5BQT80 Vanguard Funds PLC - Vanguard FTSE All-World UCITS ETF (USD) Accumulating, quantity: 0.315736 | S14: 25bd0be4-73c4-43db-bde8-cd6d821d08bd
A15: 46149.47 | B15: 46149 | C15: JUNIOR | D15: CASH | E15: TRANSFER_IN | G15: Roméo Talla Fotsing | I15: 0 | J15: 0 | K15: 51 | L15: 0 | M15: 0 | N15: EUR | O15: 0 | Q15: 0 | R15: Incoming transfer from Roméo Talla Fotsing (DE96100123455602601111) | S15: 019e01b9-8abc-768e-9178-6134bd2fe1e2 | T15: Roméo Talla Fotsing | U15: DE96100123455602601111
A16: 46169.942 | B16: 46169 | C16: JUNIOR | D16: CASH | E16: TRANSFER_IN | G16: Roméo Talla Fotsing | I16: 0 | J16: 0 | K16: 51 | L16: 0 | M16: 0 | N16: EUR | O16: 0 | Q16: 0 | R16: Incoming transfer from Roméo Talla Fotsing (DE96100123455602601111) | S16: 019e6b27-a8b3-7c11-93ab-5197c9a75e66 | T16: Roméo Talla Fotsing | U16: DE96100123455602601111
A17: 46169.942 | B17: 46169 | C17: JUNIOR | D17: TRADING | E17: BUY | F17: FUND | G17: FTSE All-World USD (Acc) | H17: IE00BK5BQT80 | I17: 0.307049 | J17: 162.8 | K17: -49.99 | L17: -1 | M17: 0 | N17: EUR | O17: 0 | Q17: 0 | R17: Buy trade IE00BK5BQT80 Vanguard Funds PLC - Vanguard FTSE All-World UCITS ETF (USD) Accumulating, quantity: 0.307049 | S17: ccd0e548-775c-457a-a6de-e6e4d785debe
A18: 46174.251 | B18: 46174 | C18: JUNIOR | D18: CASH | I18: 0 | J18: 0 | K18: 0.05 | L18: 0 | M18: 0 | N18: EUR | O18: 0 | Q18: 0 | R18: Kindergeld cash reward 37ff4e29-7c9e-41df-a062-63bc6d0cc72a for reservation: 2cfff6c1-e33a-4c93-bee4-2b1d7047f534 | S18: 019e8158-32d6-7b00-ad58-df993af5a8d3
A19: 46175.836 | B19: 46175 | C19: JUNIOR | D19: TRADING | E19: BUY | F19: FUND | G19: FTSE All-World USD (Acc) | H19: IE00BK5BQT80 | I19: 0.000303 | J19: 164.7 | K19: -0.05 | L19: 0 | M19: 0 | N19: EUR | O19: 0 | Q19: 0 | R19: Savings plan execution IE00BK5BQT80 Vanguard Funds PLC - Vanguard FTSE All-World UCITS ETF (USD) Accumulating, quantity: 0.000303 | S19: 89a986d7-e148-4149-a88a-b45a6d92cc41
A20: 46199.678 | B20: 46199 | C20: JUNIOR | D20: TRADING | E20: BUY | F20: FUND | G20: FTSE All-World USD (Acc) | H20: IE00BK5BQT80 | I20: 0.306522 | J20: 163.12 | K20: -50 | L20: -1 | M20: 0 | N20: EUR | O20: 0 | Q20: 0 | R20: Buy trade IE00BK5BQT80 Vanguard Funds PLC - Vanguard FTSE All-World UCITS ETF (USD) Accumulating, quantity: 0.306522 | S20: 3e9e4e02-13fb-4f2f-9232-ec9fdcf1ddd6
A21: 46199.678 | B21: 46199 | C21: JUNIOR | D21: CASH | E21: TRANSFER_IN | G21: Roméo Talla Fotsing | I21: 0 | J21: 0 | K21: 51 | L21: 0 | M21: 0 | N21: EUR | O21: 0 | Q21: 0 | R21: Incoming transfer from Roméo Talla Fotsing (DE96100123455602601111) | S21: 019f0449-9dc5-7375-9a1a-a752f5529856 | T21: Roméo Talla Fotsing | U21: DE96100123455602601111
A22: 46204.208 | B22: 46204 | C22: JUNIOR | D22: CASH | I22: 0 | J22: 0 | K22: 0.06 | L22: 0 | M22: 0 | N22: EUR | O22: 0 | Q22: 0 | R22: Kindergeld cash reward 207dbdfe-d48f-46c6-8630-0b84d50e138d for reservation: 74df3cbf-8058-4937-ae21-42cabf2f73a8 | S22: 019f1b9d-fb58-7305-bdc6-d9f129243512
A23: 46205.734 | B23: 46205 | C23: JUNIOR | D23: TRADING | E23: BUY | F23: FUND | G23: FTSE All-World USD (Acc) | H23: IE00BK5BQT80 | I23: 0.000362 | J23: 165.44 | K23: -0.06 | L23: 0 | M23: 0 | N23: EUR | O23: 0 | Q23: 0 | R23: Savings plan execution IE00BK5BQT80 Vanguard Funds PLC - Vanguard FTSE All-World UCITS ETF (USD) Accumulating, quantity: 0.000362 | S23: bc470a60-e397-4200-ac7e-8eec5ac5002e
A24: 46232.953 | B24: 46232 | C24: JUNIOR | D24: CASH | E24: TRANSFER_IN | G24: Roméo Talla Fotsing | I24: 0 | J24: 0 | K24: 51 | L24: 0 | M24: 0 | N24: EUR | O24: 0 | Q24: 0 | R24: Incoming transfer from Roméo Talla Fotsing (DE96100123455602601111) | S24: 019fafa5-ca2e-703f-8c5e-5bb90f7c2b27 | T24: Roméo Talla Fotsing | U24: DE96100123455602601111
A25: 46232.953 | B25: 46232 | C25: JUNIOR | D25: TRADING | E25: BUY | F25: FUND | G25: FTSE All-World USD (Acc) | H25: IE00BK5BQT80 | I25: 0.311293 | J25: 160.62 | K25: -50 | L25: -1 | M25: 0 | N25: EUR | O25: 0 | Q25: 0 | R25: Buy trade IE00BK5BQT80 Vanguard Funds PLC - Vanguard FTSE All-World UCITS ETF (USD) Accumulating, quantity: 0.311293 | S25: 16965537-0fbc-45ef-b757-be2e46410000
A26: 46237.161 | B26: 46237 | C26: JUNIOR | D26: CASH | I26: 0 | J26: 0 | K26: 0.07 | L26: 0 | M26: 0 | N26: EUR | O26: 0 | Q26: 0 | R26: Kindergeld cash reward 3cc00566-9dd6-41ac-ba76-49f3938606c0 for reservation: fca38b17-6a6b-487d-ab4e-4916e61132bb | S26: 019fc552-3206-78b9-b070-b3d12fbaeb73
A27: 46237.78 | B27: 46237 | C27: JUNIOR | D27: TRADING | E27: BUY | F27: FUND | G27: FTSE All-World USD (Acc) | H27: IE00BK5BQT80 | I27: 0.000424 | J27: 164.9401 | K27: -0.07 | L27: 0 | M27: 0 | N27: EUR | O27: 0 | Q27: 0 | R27: Savings plan execution IE00BK5BQT80 Vanguard Funds PLC - Vanguard FTSE All-World UCITS ETF (USD) Accumulating, quantity: 0.000424 | S27: a008839f-6dde-4f38-8808-cbb1ea273ea1
A28: 46266.179 | B28: 46266 | C28: JUNIOR | D28: CASH | I28: 0 | J28: 0 | K28: 0.06 | L28: 0 | M28: 0 | N28: EUR | O28: 0 | Q28: 0 | R28: Kindergeld cash reward a6b65297-b926-4150-bc1f-e433b955f6f3 for reservation: e7cefca1-ca85-451c-80b1-1fa9101a2962 | S28: 01a05ac1-d1d3-7db8-bbcc-57674726456e
A29: 46267.739 | B29: 46267 | C29: JUNIOR | D29: TRADING | E29: BUY | F29: FUND | G29: FTSE All-World USD (Acc) | H29: IE00BK5BQT80 | I29: 0.000359 | J29: 166.9 | K29: -0.06 | L29: 0 | M29: 0 | N29: EUR | O29: 0 | Q29: 0 | R29: Savings plan execution IE00BK5BQT80 Vanguard Funds PLC - Vanguard FTSE All-World UCITS ETF (USD) Accumulating, quantity: 0.000359 | S29: 0028a83f-2207-464d-bffe-6e5b7b8a209e
A30: 46295.53 | B30: 46295 | C30: JUNIOR | D30: CASH | E30: TRANSFER_INSTANT_INBOUND | G30: ROMEO TALLA FOTSING | I30: 0 | J30: 0 | K30: 51 | L30: 0 | M30: 0 | N30: EUR | O30: 0 | Q30: 0 | R30: Incoming transfer from ROMEO TALLA FOTSING (DE16300209005310514271) | S30: 01a0f1e9-a83d-7435-8a91-aac572d31cb2 | T30: ROMEO TALLA FOTSING | U30: DE16300209005310514271
A31: 46295.632 | B31: 46295 | C31: JUNIOR | D31: TRADING | E31: BUY | F31: STOCK | G31: DroneShield | H31: AU000000DRO2 | I31: 47.709923 | J31: 1.048 | K31: -50 | L31: -1 | M31: 0 | N31: EUR | O31: 0 | Q31: 0 | R31: Buy trade AU000000DRO2 DRONESHIELD LTD, quantity: 47.709923 | S31: 314c83be-d3b1-41e2-ae49-697738aec412

Sheet Auswertung
A1: Asset | B1: Klasse | C1: Symbol | D1: Käufe Stück | E1: Verkäufe Stück | F1: Bestand | G1: Investiert € | H1: Verkauft € | I1: Gebühren € | J1: Tax | K1: Netto P&L € | L1: Status | M1: Einstandskurs € | N1: Aktueller Kurs € | O1: Aktuell nicht realisierte P&L € | P1: Aktuelle Position € | Q1: Aktuell Investiert € | R1: Aktuelle Rendite | S1: Realisierte P&L Verkäufe € | T1: Investiertes Kapital Verkäufe € | U1: Anzahl Kauforders | V1: Anzahl Verkaufsorders | W1: Rendite Verkäufe | X1: Gesamte Rendite
A2: DroneShield | B2: STOCK | C2: AU000000DRO2 | D2: =SUMIFS(Daten!I:I,Daten!H:H,C2,Daten!E:E,"BUY") -> 47.709923 | E2: =-SUMIFS(Daten!I:I,Daten!H:H,C2,Daten!E:E,"SELL") -> 0 | F2: =D2-E2 -> 47.709923 | G2: =-SUMIFS(Daten!K:K,Daten!H:H,C2,Daten!E:E,"BUY") -> 50 | H2: =SUMIFS(Daten!K:K,Daten!H:H,C2,Daten!E:E,"SELL") -> 0 | I2: =SUMIFS(Daten!L:L,Daten!H:H,C2)*-1 -> 1 | J2: =-SUMIFS(Daten!M:M,Daten!E:E,"SELL",Daten!H:H,C2) -> 0 | K2: =H2-G2-I2-J2 -> -51 | L2: =IF(F2>0,"OFFEN","GESCHLOSSEN") -> OFFEN | M2: 1.069 | N2: 1.0419 | O2: =IF(L2="GESCHLOSSEN", 0, IF(L2="OFFEN", ((N2*F2)-(M2*F2)), "")) -> -1.2929389 | P2: =IF(F2>0,F2*N2,0) -> 49.708969 | Q2: =IF(F2>0,F2*M2,0) -> 51.001908 | R2: =IF(L2="GESCHLOSSEN", 0, IF(L2="OFFEN", (O2/(M2*F2)))) -> -0.025350795 | S2: =IF(L2="GESCHLOSSEN", H2-G2-I2 + SUMIFS(Daten!K:K,Daten!H:H,C2,Daten!E:E,"DIVIDEND"), IF(L2="OFFEN", IF(E2=0, 0, H2+SUMIFS(Daten!K:K,Daten!H:H,C2,Daten!E:E,"DIVIDEND")-(G2-(F2*M2))-I2 ), "")) -> 0 | T2: =IF(E2=0, 0, (G2-(F2*M2))+I2 ) -> 0 | U2: =COUNTIFS(Daten!H:H,C2,Daten!E:E,"BUY",Daten!L:L,"<0") -> 1 | V2: =COUNTIFS(Daten!H:H,C2,Daten!E:E,"SELL",Daten!L:L,"<0") -> 0 | W2: =IF(T2>0,S2/T2,0) -> 0 | X2: =IF(L2="GESCHLOSSEN", K2/(G2+I2), IF(L2="OFFEN", ((H2+N2*F2)-G2-I2)/G2, "")) -> -0.025820625
A3: FTSE All-World USD (Acc) | B3: FUND | C3: IE00BK5BQT80 | D3: =SUMIFS(Daten!I:I,Daten!H:H,C3,Daten!E:E,"BUY") -> 2.949382 | E3: =-SUMIFS(Daten!I:I,Daten!H:H,C3,Daten!E:E,"SELL") -> 0 | F3: =D3-E3 -> 2.949382 | G3: =-SUMIFS(Daten!K:K,Daten!H:H,C3,Daten!E:E,"BUY") -> 459.28 | H3: =SUMIFS(Daten!K:K,Daten!H:H,C3,Daten!E:E,"SELL") -> 0 | I3: =SUMIFS(Daten!L:L,Daten!H:H,C3)*-1 -> 6 | J3: =-SUMIFS(Daten!M:M,Daten!E:E,"SELL",Daten!H:H,C3) -> 0 | K3: =H3-G3-I3-J3 -> -465.28 | L3: =IF(F3>0,"OFFEN","GESCHLOSSEN") -> OFFEN | M3: 157.67 | N3: 169.74 | O3: =IF(L3="GESCHLOSSEN", 0, IF(L3="OFFEN", ((N3*F3)-(M3*F3)), "")) -> 35.599041 | P3: =IF(F3>0,F3*N3,0) -> 500.6281 | Q3: =IF(F3>0,F3*M3,0) -> 465.02906 | R3: =IF(L3="GESCHLOSSEN", 0, IF(L3="OFFEN", (O3/(M3*F3)))) -> 0.076552293 | S3: =IF(L3="GESCHLOSSEN", H3-G3-I3 + SUMIFS(Daten!K:K,Daten!H:H,C3,Daten!E:E,"DIVIDEND"), IF(L3="OFFEN", IF(E3=0, 0, H3+SUMIFS(Daten!K:K,Daten!H:H,C3,Daten!E:E,"DIVIDEND")-(G3-(F3*M3))-I3 ), "")) -> 0 | T3: =IF(E3=0, 0, (G3-(F3*M3))+I3 ) -> 0 | U3: =COUNTIFS(Daten!H:H,C3,Daten!E:E,"BUY",Daten!L:L,"<0") -> 6 | V3: =COUNTIFS(Daten!H:H,C3,Daten!E:E,"SELL",Daten!L:L,"<0") -> 0 | W3: =IF(T3>0,S3/T3,0) -> 0 | X3: =IF(L3="GESCHLOSSEN", K3/(G3+I3), IF(L3="OFFEN", ((H3+N3*F3)-G3-I3)/G3, "")) -> 0.076964163
AC76: =IF(L9="GESCHLOSSEN", 0, IF(L9="OFFEN", IF(E2=0, G9+I9, H2+SUMIFS(Daten!K:K,Daten!G:G,A2,Daten!E:E,"DIVIDEND")-(G2-(F2*M2))-I2 ), "")) | AD76: =IF(L6="GESCHLOSSEN", H6-G6-I6 + SUMIFS(Daten!K:K,Daten!G:G,A6,Daten!E:E,"DIVIDEND"), IF(L6="OFFEN", IF(E6=0, -I6, H6+SUMIFS(Daten!K:K,Daten!G:G,A6,Daten!E:E,"DIVIDEND")-(G6-(F6*M6))-I6 ), ""))
AD77: =H2 -(G2-(F2*M2)) -I2 -> 0.001907687
AD78: =H4-G4-I4 + SUMIFS(Daten!K:K,Daten!G:G,A4,Daten!E:E,"DIVIDEND") -> 0
AD83: =_xlfn.MAXIFS(Daten!B:B,Daten!G:G,A14,Daten!E:E,"SELL") -> 0 | AE83: =SUMIFS(Daten!L:L,Daten!G:G,A14,Daten!E:E,"BUY",Daten!B:B,"<"&_xlfn.MAXIFS(Daten!B:B,Daten!G:G,A14,Daten!E:E,"SELL"))*-1 -> 0
AD84: =SUMIFS(Daten!L:L,Daten!G:G,A14,Daten!E:E,"BUY")*-1 -> 0 | AE84: =SUMIFS(Daten!L:L,Daten!G:G,A14,Daten!E:E,"BUY",Daten!B:B,"<"&AD83)*-1 -> 0
AD85: =SUMIFS(Daten!L:L,Daten!G:G,A14,Daten!E:E,"SELL")*-1 -> 0
AD86: =H14-(G14-(F14*M14))-SUMIFS(Daten!L:L,Daten!G:G,A14,Daten!E:E,"SELL")*-1 -> 0 | AE86: =H14-(G14-(F14*M14))-SUMIFS(Daten!L:L,Daten!G:G,A14,Daten!E:E,"SELL")*-1 - SUMIFS(Daten!L:L,Daten!G:G,A14,Daten!E:E,"BUY",Daten!B:B,"<"&_xlfn.MAXIFS(Daten!B:B,Daten!G:G,A14,Daten!E:E,"SELL"))*-1 -> 0

Sheet Dashboard
A1: Portfolio KPIs
A3: Anzahl Assets | B3: =COUNTA(Auswertung!A:A) - 1 -> 2 | C3: =IF(ABS(B3)>0,B3/B3,0) -> 1
A4: Anzahl STOCK | B4: =COUNTIFS(Auswertung!B:B,"STOCK") -> 1 | C4: =IF(ABS(B3)>0,B4/B3,0) -> 0.5
A5: Anzahl FUND | B5: =COUNTIFS(Auswertung!B:B,"FUND") -> 1 | C5: =IF(ABS(B3)>0,B5/B3,0) -> 0.5
A6: Anzahl CRYPTO | B6: =COUNTIFS(Auswertung!B:B,"CRYPTO") -> 0 | C6: =IF(ABS(B3)>0,B6/B3,0) -> 0
A8: Offene Assets | B8: =COUNTIFS(Auswertung!L:L,"OFFEN") -> 2 | C8: =IF(ABS(B8)>0,B8/B8,0) -> 1
A9: Offene STOCK | B9: =COUNTIFS(Auswertung!B:B,"STOCK",Auswertung!L:L,"OFFEN") -> 1 | C9: =IF(ABS(B8)>0,B9/B8,0) -> 0.5
A10: Offene FUND | B10: =COUNTIFS(Auswertung!B:B,"FUND",Auswertung!L:L,"OFFEN") -> 1 | C10: =IF(ABS(B8)>0,B10/B8,0) -> 0.5
A11: Offene CRYPTO | B11: =COUNTIFS(Auswertung!B:B,"CRYPTO",Auswertung!L:L,"OFFEN") -> 0 | C11: =IF(ABS(B8)>0,B11/B8,0) -> 0
A13: Closed Assets | B13: =COUNTIFS(Auswertung!L:L,"GESCHLOSSEN") -> 0
A14: Closed STOCK | B14: =COUNTIFS(Auswertung!B:B,"STOCK",Auswertung!L:L,"GESCHLOSSEN") -> 0
A15: Closed FUND | B15: =COUNTIFS(Auswertung!B:B,"FUND",Auswertung!L:L,"GESCHLOSSEN") -> 0
A16: Closed CRYPTO | B16: =COUNTIFS(Auswertung!B:B,"CRYPTO",Auswertung!L:L,"GESCHLOSSEN") -> 0
A18: Brutto Investiert | B18: =SUM(Auswertung!G:G)-SUMIFS(Daten!L:L,Daten!E:E,"BUY") -> 516.28 | D18: =-SUMIFS(Daten!K:K,Daten!E:E,"BUY")-SUMIFS(Daten!L:L,Daten!E:E,"BUY") -> 516.28
A19: Brutto Investiert STOCK&FUND | B19: =SUMIFS(Auswertung!G:G,Auswertung!B:B,"STOCK")+SUMIFS(Auswertung!G:G,Auswertung!B:B,"FUND")-SUMIFS(Daten!L:L,Daten!E:E,"BUY",Daten!F:F,"STOCK")-SUMIFS(Daten!L:L,Daten!E:E,"BUY",Daten!F:F,"FUND") -> 516.28 | C19: =IF(ABS(B18)>0,B19/B18,0) -> 1 | D19: =-SUMIFS(Daten!K:K,Daten!F:F,"STOCK",Daten!E:E,"BUY")-SUMIFS(Daten!K:K,Daten!F:F,"FUND",Daten!E:E,"BUY")-SUMIFS(Daten!L:L,Daten!E:E,"BUY",Daten!F:F,"STOCK")-SUMIFS(Daten!L:L,Daten!E:E,"BUY",Daten!F:F,"FUND") -> 516.28
A20: Brutto Investiert STOCK | B20: =SUMIFS(Auswertung!G:G,Auswertung!B:B,"STOCK")-SUMIFS(Daten!L:L,Daten!E:E,"BUY",Daten!F:F,"STOCK") -> 51 | C20: =IF(ABS(B18)>0,B20/B18,0) -> 0.098783606 | D20: =-SUMIFS(Daten!K:K,Daten!F:F,"STOCK",Daten!E:E,"BUY")-SUMIFS(Daten!L:L,Daten!E:E,"BUY",Daten!F:F,"STOCK") -> 51
A21: Brutto Investiert FUND | B21: =SUMIFS(Auswertung!G:G,Auswertung!B:B,"FUND")-SUMIFS(Daten!L:L,Daten!E:E,"BUY",Daten!F:F,"FUND") -> 465.28 | C21: =IF(ABS(B18)>0,B21/B18,0) -> 0.90121639 | D21: =-SUMIFS(Daten!K:K,Daten!F:F,"FUND",Daten!E:E,"BUY")-SUMIFS(Daten!L:L,Daten!E:E,"BUY",Daten!F:F,"FUND") -> 465.28
A22: Brutto Investiert CRYPTO | B22: =SUMIFS(Auswertung!G:G,Auswertung!B:B,"CRYPTO")-SUMIFS(Daten!L:L,Daten!E:E,"BUY",Daten!F:F,"CRYPTO") -> 0 | C22: =IF(ABS(B18)>0,B22/B18,0) -> 0 | D22: =-SUMIFS(Daten!K:K,Daten!F:F,"CRYPTO",Daten!E:E,"BUY")-SUMIFS(Daten!L:L,Daten!E:E,"BUY",Daten!F:F,"CRYPTO") -> 0
A24: Netto Investiert | B24: =SUM(Auswertung!G:G) -> 509.28 | D24: =-SUMIFS(Daten!K:K,Daten!E:E,"BUY") -> 509.28
A25: Netto Investiert STOCK&FUND | B25: =SUMIFS(Auswertung!G:G,Auswertung!B:B,"STOCK")+SUMIFS(Auswertung!G:G,Auswertung!B:B,"FUND") -> 509.28 | C25: =IF(ABS(B24)>0,B25/B24,0) -> 1 | D25: =-SUMIFS(Daten!K:K,Daten!F:F,"STOCK",Daten!E:E,"BUY")-SUMIFS(Daten!K:K,Daten!F:F,"FUND",Daten!E:E,"BUY") -> 509.28
A26: Netto Investiert STOCK | B26: =SUMIFS(Auswertung!G:G,Auswertung!B:B,"STOCK") -> 50 | C26: =IF(ABS(B24)>0,B26/B24,0) -> 0.09817782 | D26: =-SUMIFS(Daten!K:K,Daten!F:F,"STOCK",Daten!E:E,"BUY") -> 50
A27: Netto Investiert FUND | B27: =SUMIFS(Auswertung!G:G,Auswertung!B:B,"FUND") -> 459.28 | C27: =IF(ABS(B24)>0,B27/B24,0) -> 0.90182218 | D27: =-SUMIFS(Daten!K:K,Daten!F:F,"FUND",Daten!E:E,"BUY") -> 459.28
A28: Netto Investiert CRYPTO | B28: =SUMIFS(Auswertung!G:G,Auswertung!B:B,"CRYPTO") -> 0 | C28: =IF(ABS(B24)>0,B28/B24,0) -> 0 | D28: =-SUMIFS(Daten!K:K,Daten!F:F,"CRYPTO",Daten!E:E,"BUY") -> 0
A30: Brutto Verkauft | B30: =SUM(Auswertung!H:H)-SUMIFS(Daten!L:L,Daten!E:E,"SELL") -> 0 | D30: =SUMIFS(Daten!K:K,Daten!E:E,"SELL")-SUMIFS(Daten!L:L,Daten!E:E,"SELL") -> 0
A31: Brutto Verkauft STOCK&FUND | B31: =SUMIFS(Auswertung!H:H,Auswertung!B:B,"STOCK")+SUMIFS(Auswertung!H:H,Auswertung!B:B,"FUND")-SUMIFS(Daten!L:L,Daten!E:E,"SELL",Daten!F:F,"STOCK")-SUMIFS(Daten!L:L,Daten!E:E,"SELL",Daten!F:F,"FUND") -> 0 | C31: =IF(ABS(B30)>0,B31/B30,0) -> 0 | D31: =SUMIFS(Daten!K:K,Daten!F:F,"STOCK",Daten!E:E,"SELL")+SUMIFS(Daten!K:K,Daten!F:F,"FUND",Daten!E:E,"SELL")-SUMIFS(Daten!L:L,Daten!E:E,"SELL",Daten!F:F,"STOCK")-SUMIFS(Daten!L:L,Daten!E:E,"SELL",Daten!F:F,"FUND") -> 0
A32: Brutto Verkauft STOCK | B32: =SUMIFS(Auswertung!H:H,Auswertung!B:B,"STOCK")-SUMIFS(Daten!L:L,Daten!E:E,"SELL",Daten!F:F,"STOCK") -> 0 | C32: =IF(ABS(B30)>0,B32/B30,0) -> 0 | D32: =SUMIFS(Daten!K:K,Daten!F:F,"STOCK",Daten!E:E,"SELL")-SUMIFS(Daten!L:L,Daten!E:E,"SELL",Daten!F:F,"STOCK") -> 0
A33: Brutto Verkauft FUND | B33: =SUMIFS(Auswertung!H:H,Auswertung!B:B,"FUND")-SUMIFS(Daten!L:L,Daten!E:E,"SELL",Daten!F:F,"FUND") -> 0 | C33: =IF(ABS(B30)>0,B33/B30,0) -> 0 | D33: =SUMIFS(Daten!K:K,Daten!F:F,"FUND",Daten!E:E,"SELL")-SUMIFS(Daten!L:L,Daten!E:E,"SELL",Daten!F:F,"FUND") -> 0
A34: Brutto Verkauft CRYPTO | B34: =SUMIFS(Auswertung!H:H,Auswertung!B:B,"CRYPTO")-SUMIFS(Daten!L:L,Daten!E:E,"SELL",Daten!F:F,"CRYPTO") -> 0 | C34: =IF(ABS(B30)>0,B33/B30,0) -> 0 | D34: =SUMIFS(Daten!K:K,Daten!F:F,"CRYPTO",Daten!E:E,"SELL")-SUMIFS(Daten!L:L,Daten!E:E,"SELL",Daten!F:F,"CRYPTO") -> 0
A36: Netto Verkauft | B36: =SUM(Auswertung!H:H) -> 0 | D36: =SUMIFS(Daten!K:K,Daten!E:E,"SELL") -> 0
A37: Netto Verkauft STOCK&FUND | B37: =SUMIFS(Auswertung!H:H,Auswertung!B:B,"STOCK")+SUMIFS(Auswertung!H:H,Auswertung!B:B,"FUND") -> 0 | C37: =IF(ABS(B36)>0,B37/B36,0) -> 0 | D37: =SUMIFS(Daten!K:K,Daten!F:F,"STOCK",Daten!E:E,"SELL")+SUMIFS(Daten!K:K,Daten!F:F,"FUND",Daten!E:E,"SELL") -> 0
A38: Netto Verkauft STOCK | B38: =SUMIFS(Auswertung!H:H,Auswertung!B:B,"STOCK") -> 0 | C38: =IF(ABS(B36)>0,B38/B36,0) -> 0 | D38: =SUMIFS(Daten!K:K,Daten!F:F,"STOCK",Daten!E:E,"SELL") -> 0
A39: Netto Verkauft FUND | B39: =SUMIFS(Auswertung!H:H,Auswertung!B:B,"FUND") -> 0 | C39: =IF(ABS(B36)>0,B39/B36,0) -> 0 | D39: =SUMIFS(Daten!K:K,Daten!F:F,"FUND",Daten!E:E,"SELL") -> 0
A40: Netto Verkauft CRYPTO | B40: =SUMIFS(Auswertung!H:H,Auswertung!B:B,"CRYPTO") -> 0 | C40: =IF(ABS(B36)>0,B40/B36,0) -> 0 | D40: =SUMIFS(Daten!K:K,Daten!F:F,"CRYPTO",Daten!E:E,"SELL") -> 0
A42: Gebühren | B42: =SUM(Auswertung!I:I) -> 7 | C42: =-SUM(Daten!L:L) -> 7
A43: Gebüren STOCK&FUND | B43: =SUMIFS(Auswertung!I:I,Auswertung!B:B,"STOCK")+SUMIFS(Auswertung!I:I,Auswertung!B:B,"FUND") -> 7 | C43: =-SUMIFS(Daten!L:L,Daten!F:F,"STOCK")-SUMIFS(Daten!L:L,Daten!F:F,"FUND") -> 7 | D43: =IF(ABS(C42)>0,C43/C42,0) -> 1
A44: Gebüren STOCK | B44: =SUMIFS(Auswertung!I:I,Auswertung!B:B,"STOCK") -> 1 | C44: =-SUMIFS(Daten!L:L,Daten!F:F,"STOCK") -> 1 | D44: =IF(ABS(C42)>0,C44/C42,0) -> 0.14285714
A45: Gebüren FUND | B45: =SUMIFS(Auswertung!I:I,Auswertung!B:B,"FUND") -> 6 | C45: =-SUMIFS(Daten!L:L,Daten!F:F,"FUND") -> 6 | D45: =IF(ABS(C42)>0,C45/C42,0) -> 0.85714286
A46: Gebühren CRYPTO | B46: =SUMIFS(Auswertung!I:I,Auswertung!B:B,"CRYPTO") -> 0 | C46: =-SUMIFS(Daten!L:L,Daten!F:F,"CRYPTO") -> 0 | D46: =IF(ABS(C42)>0,C46/C42,0) -> 0
A48: Gebühren Käufe | B48: =-SUMIFS(Daten!L:L,Daten!E:E,"BUY") -> 7
A49: Gebüren Käufe STOCK&FUND | B49: =-SUMIFS(Daten!L:L,Daten!E:E,"BUY",Daten!F:F,"STOCK")-SUMIFS(Daten!L:L,Daten!E:E,"BUY",Daten!F:F,"FUND") -> 7 | C49: =IF(ABS(B48)>0,B49/B48,0) -> 1
...

Sheet Pivot
A3: Assets | B3: Einkaufswert | C3: Aktueller Wert | E3: Aktueller Wert | G3: Aktueller Wert | J3: Einkaufswert | L3: Verkaufserlöse Gewinn/Verlust
A4: FUND | B4: 465.02906 | C4: 500.6281 | E4: 550.33707 | G4: 550.33707 | J4: 516.03097 | L4: 0
A5: STOCK | B5: 51.001908 | C5: 49.708969 | I5: G/V:
A6: Gesamtergebnis | B6: 516.03097 | C6: 550.33707 | E6: =GETPIVOTDATA("Aktuelle Position €",$E$3) -> 550.33707 | G6: =GETPIVOTDATA("Aktuelle Position €",$G$3) -> 550.33707 | I6: =G6-J6 -> 34.306102 | J6: =GETPIVOTDATA("Aktuell Investiert €",$J$3) -> 516.03097 | L6: =GETPIVOTDATA("Realisierte P&L Verkäufe €",$L$3) -> 0
A13: Assets | B13: Aktueller Wert | E13: Assets | F13: Aktueller Wert
A14: FUND | B14: 500.6281 | E14: FUND | F14: 500.6281
A15: FTSE All-World USD (Acc) | B15: 500.6281 | E15: STOCK | F15: 49.708969
A16: STOCK | B16: 49.708969 | E16: Gesamtergebnis | F16: 550.33707
A17: DroneShield | B17: 49.708969
A18: Gesamtergebnis | B18: 550.33707

Sheet Portfolio
A8: Assets | B8: Bestand | C8: Kurswert | D8: Aktueller Wert
A9: FUND
A10: FTSE All-World USD (Acc) | B10: 2.949382 | C10: 169.74 | D10: 500.6281
A11: FUND Ergebnis | B11: 2.949382 | C11: 169.74 | D11: 500.6281
A13: STOCK
A14: DroneShield | B14: 47.709923 | C14: 1.0419 | D14: 49.708969
A15: STOCK Ergebnis | B15: 47.709923 | C15: 1.0419 | D15: 49.708969
A17: Gesamtergebnis | B17: 50.659305 | C17: 170.7819 | D17: 550.33707

Sheet Auswertung_2026

Sheet Auswertung_2025

Sheet Definitions
A1: KPI | B1: Bedeutung
A2: Portfolio-Wert | B2: Aktueller Gesamtwert aller Positionen
A3: Investiertes Kapital | B3: Summe aller Einzahlungen und Käufe
A4: Gewinn/Verlust (P&L) | B4: Wie viel Gewinn(Proft) oder Verlust(Lost) erzielt wurde
A5: Rendite (%) | B5: Gewinn oder Verlust im Verhältnis zum eingesetzten Kapital
A6: Anzahl Positionen | B6: Wie viele Wertpapiere/Kryptos im Portfolio sind
A7: Asset-Allokation | B7: Verteilung auf Aktien, ETFs, Krypto usw.
A8: Cash-Bestand | B8: Nicht investiertes Guthaben
A9: Gebühren | B9: Summe aller Handelskosten
A10: Realisierte Gewinne | B10: Gewinne aus bereits verkauften Positionen
A11: Nicht realisierte Gewinne | B11: Gewinne/Verluste aus aktuellen Positionen
