Workbook
Name Datenschnitt_Asset: #N/A
Name Datenschnitt_Klasse: #N/A

Sheet Daten
A1: datetime | B1: date | C1: account_type | D1: category | E1: type | F1: asset_class | G1: name | H1: symbol | I1: shares | J1: price | K1: amount | L1: fee | M1: tax | N1: currency | O1: original_amount | P1: original_currency | Q1: fx_rate | R1: description | S1: transaction_id | T1: counterparty_name | U1: counterparty_iban | V1: payment_reference | W1: mcc_code
A2: 45865.639 | B2: 45865 | C2: DEFAULT | D2: CASH | E2: TRANSFER_INSTANT_INBOUND | I2: 0 | J2: 0 | K2: 1 | L2: 0 | M2: 0 | N2: EUR | O2: 0 | Q2: 0 | R2: Incoming transfer from ROMEO TALLA FOTSING | S2: 424eaa0e-2c58-4651-aa44-7b5a953a5a64
A3: 45867.644 | B3: 45867 | C3: DEFAULT | D3: CASH | E3: TRANSFER_INSTANT_INBOUND | I3: 0 | J3: 0 | K3: 39 | L3: 0 | M3: 0 | N3: EUR | O3: 0 | Q3: 0 | R3: Incoming transfer from ROMEO TALLA FOTSING | S3: e95f0d7f-e43e-4fd6-b6ab-5dc0b1a435ce
A4: 45908.513 | B4: 45908 | C4: DEFAULT | D4: TRADING | E4: BUY | F4: STOCK | G4: Hensoldt | H4: DE000HAG0005 | I4: 0.009325 | J4: 91.15 | K4: -0.85 | L4: 0 | M4: 0 | N4: EUR | O4: 0 | Q4: 0 | R4: Buy trade DE000HAG0005 HENSOLDT AG INH O.N., quantity: 0.009325 | S4: 0727b23c-23a7-4222-a59d-0c9bc60ef4f3
A5: 45908.513 | B5: 45908 | C5: DEFAULT | D5: TRADING | E5: BUY | F5: STOCK | G5: Hensoldt | H5: DE000HAG0005 | I5: 1 | J5: 91.15 | K5: -91.15 | L5: -1 | M5: 0 | N5: EUR | O5: 0 | Q5: 0 | R5: Buy trade DE000HAG0005 HENSOLDT AG INH O.N., quantity: 1 | S5: a629c8cf-59e5-427d-9d60-e150262d0229
A6: 45908.518 | B6: 45908 | C6: DEFAULT | D6: CASH | E6: TRANSFER_INSTANT_INBOUND | I6: 0 | J6: 0 | K6: 100 | L6: 0 | M6: 0 | N6: EUR | O6: 0 | Q6: 0 | R6: Incoming transfer from ROMEO TALLA FOTSING | S6: 53ff5df6-b9e9-4706-9b7e-909c42bd2b4b
A7: 45908.518 | B7: 45908 | C7: DEFAULT | D7: TRADING | E7: BUY | F7: STOCK | G7: NVIDIA | H7: US67066G1040 | I7: 0.004184 | J7: 143.4 | K7: -0.6 | L7: 0 | M7: 0 | N7: EUR | O7: 0 | Q7: 0 | R7: Buy trade US67066G1040 NVIDIA CORP. DL-,001, quantity: 0.004184 | S7: 1cf6e467-defb-4230-8695-cfdce5f7c8b1
A8: 45908.518 | B8: 45908 | C8: DEFAULT | D8: TRADING | E8: BUY | F8: STOCK | G8: NVIDIA | H8: US67066G1040 | I8: 1 | J8: 143.4 | K8: -143.4 | L8: -1 | M8: 0 | N8: EUR | O8: 0 | Q8: 0 | R8: Buy trade US67066G1040 NVIDIA CORP. DL-,001, quantity: 1 | S8: 9758550e-bb56-4291-9669-769e8743d26a
A9: 45908.717 | B9: 45908 | C9: DEFAULT | D9: CASH | E9: TRANSFER_INSTANT_INBOUND | I9: 0 | J9: 0 | K9: 100 | L9: 0 | M9: 0 | N9: EUR | O9: 0 | Q9: 0 | R9: Incoming transfer from ROMEO TALLA FOTSING | S9: 0d9897c9-c8fd-4778-968d-1a938e62e15e
A10: 45908.718 | B10: 45908 | C10: DEFAULT | D10: TRADING | E10: BUY | F10: STOCK | G10: Siemens Energy | H10: DE000ENER6Y0 | I10: 1 | J10: 88.46 | K10: -88.46 | L10: -1 | M10: 0 | N10: EUR | O10: 0 | Q10: 0 | R10: Buy trade DE000ENER6Y0 SIEMENS ENERGY AG NA O.N., quantity: 1 | S10: c7a53c80-2e60-48ab-9f12-9783bb111234
A11: 45908.718 | B11: 45908 | C11: DEFAULT | D11: TRADING | E11: BUY | F11: STOCK | G11: Siemens Energy | H11: DE000ENER6Y0 | I11: 0.017408 | J11: 88.46 | K11: -1.54 | L11: 0 | M11: 0 | N11: EUR | O11: 0 | Q11: 0 | R11: Buy trade DE000ENER6Y0 SIEMENS ENERGY AG NA O.N., quantity: 0.017408 | S11: 747eaf82-a1bb-436c-be67-e001ace15c63
A12: 45908.723 | B12: 45908 | C12: DEFAULT | D12: CASH | E12: TRANSFER_INSTANT_INBOUND | I12: 0 | J12: 0 | K12: 50 | L12: 0 | M12: 0 | N12: EUR | O12: 0 | Q12: 0 | R12: Incoming transfer from ROMEO TALLA FOTSING | S12: 982366f6-521f-44fe-bd80-efb1401d2fee
A13: 45908.513 | B13: 45908 | C13: DEFAULT | D13: CASH | E13: TRANSFER_INSTANT_INBOUND | I13: 0 | J13: 0 | K13: 100 | L13: 0 | M13: 0 | N13: EUR | O13: 0 | Q13: 0 | R13: Incoming transfer from ROMEO TALLA FOTSING | S13: af3b470a-85d9-43a5-a66f-f48c9956c0b5
A14: 45908.725 | B14: 45908 | C14: DEFAULT | D14: TRADING | E14: BUY | F14: STOCK | G14: Infineon Technologies | H14: DE0006231004 | I14: 0.871199 | J14: 32.065 | K14: -27.93 | L14: 0 | M14: 0 | N14: EUR | O14: 0 | Q14: 0 | R14: Buy trade DE0006231004 INFINEON TECH.AG NA O.N., quantity: 0.871199 | S14: 23d47dc4-4c9a-40f5-bef3-2d480cd8e83c
A15: 45908.725 | B15: 45908 | C15: DEFAULT | D15: TRADING | E15: BUY | F15: STOCK | G15: Infineon Technologies | H15: DE0006231004 | I15: 1 | J15: 32.065 | K15: -32.07 | L15: -1 | M15: 0 | N15: EUR | O15: 0 | Q15: 0 | R15: Buy trade DE0006231004 INFINEON TECH.AG NA O.N., quantity: 1 | S15: 433c455d-7391-4e56-999a-61950885dbc2
A16: 45909.868 | B16: 45909 | C16: DEFAULT | D16: CASH | E16: TRANSFER_INSTANT_INBOUND | I16: 0 | J16: 0 | K16: 185 | L16: 0 | M16: 0 | N16: EUR | O16: 0 | Q16: 0 | R16: Incoming transfer from ROMEO TALLA FOTSING | S16: e582d7a8-1263-40e7-9c23-1bc6a34c6822
A17: 45909.877 | B17: 45909 | C17: DEFAULT | D17: CASH | E17: TRANSFER_INSTANT_INBOUND | I17: 0 | J17: 0 | K17: 50 | L17: 0 | M17: 0 | N17: EUR | O17: 0 | Q17: 0 | R17: Incoming transfer from ROMEO TALLA FOTSING | S17: e25dd191-37d8-403a-9c16-c0e3cbb411d0
A18: 45909.87 | B18: 45909 | C18: DEFAULT | D18: CASH | E18: TRANSFER_INSTANT_INBOUND | I18: 0 | J18: 0 | K18: 1 | L18: 0 | M18: 0 | N18: EUR | O18: 0 | Q18: 0 | R18: Incoming transfer from ROMEO TALLA FOTSING | S18: 9cf1e7fa-4740-4383-a0c1-7766064d658d
A19: 45909.878 | B19: 45909 | C19: DEFAULT | D19: TRADING | E19: BUY | F19: CRYPTO | G19: Solana | H19: SOL | I19: 1.004294 | J19: 187.214 | K19: -188.02 | L19: -1 | M19: 0 | N19: EUR | O19: 0 | Q19: 0 | R19: Buy trade XF000SOL0012 Solana, quantity: 1.004294 | S19: afbcad62-3fc9-4099-9e9b-8900285f53e8
A20: 45909.881 | B20: 45909 | C20: DEFAULT | D20: TRADING | E20: BUY | F20: CRYPTO | G20: XRP | H20: XRP | I20: 4.324764 | J20: 2.543402 | K20: -11 | L20: -1 | M20: 0 | N20: EUR | O20: 0 | Q20: 0 | R20: Buy trade XF000XRP0018 XRP, quantity: 4.324764 | S20: 230d489b-9016-478a-8352-d0c5a4b91285
A21: 45909.884 | B21: 45909 | C21: DEFAULT | D21: TRADING | E21: BUY | F21: CRYPTO | G21: Cardano | H21: ADA | I21: 13.490816 | J21: 0.741244 | K21: -10 | L21: -1 | M21: 0 | N21: EUR | O21: 0 | Q21: 0 | R21: Buy trade XF000ADA0018 Cardano, quantity: 13.490816 | S21: b14b2296-7649-45b6-96d4-0adb5bf4ccd1
A22: 45909.891 | B22: 45909 | C22: DEFAULT | D22: TRADING | E22: BUY | F22: STOCK | G22: ThyssenKrupp | H22: DE0007500001 | I22: 2 | J22: 10.055 | K22: -20.11 | L22: -1 | M22: 0 | N22: EUR | O22: 0 | Q22: 0 | R22: Buy trade DE0007500001 THYSSENKRUPP AG O.N., quantity: 2 | S22: da29a441-a07c-49b7-9b99-80a529e4e573
A23: 45909.891 | B23: 45909 | C23: DEFAULT | D23: TRADING | E23: BUY | F23: STOCK | G23: ThyssenKrupp | H23: DE0007500001 | I23: 0.186878 | J23: 10.055 | K23: -1.88 | L23: 0 | M23: 0 | N23: EUR | O23: 0 | Q23: 0 | R23: Buy trade DE0007500001 THYSSENKRUPP AG O.N., quantity: 0.186878 | S23: 969d0b29-b80f-44a2-9ae6-5cd0d9357879
A24: 45910.354 | B24: 45910 | C24: DEFAULT | D24: TRADING | E24: SELL | F24: STOCK | G24: NVIDIA | H24: US67066G1040 | I24: -0.026957 | J24: 148.38 | K24: 4 | L24: -1 | M24: 0 | N24: EUR | O24: 0 | Q24: 0 | R24: Sell trade US67066G1040 NVIDIA CORP. DL-,001, quantity: 0.026957 | S24: 70655a16-2cfd-4223-b0c9-8f308f9dd5d2
A25: 45910.357 | B25: 45910 | C25: DEFAULT | D25: TRADING | E25: BUY | F25: STOCK | G25: NVIDIA | H25: US67066G1040 | I25: 0.350215 | J25: 148.48 | K25: -52 | L25: -1 | M25: 0 | N25: EUR | O25: 0 | Q25: 0 | R25: Buy trade US67066G1040 NVIDIA CORP. DL-,001, quantity: 0.350215 | S25: 9b0d29d2-6ed3-47ac-99ce-e87af3ec296e
A26: 45910.845 | B26: 45910 | C26: DEFAULT | D26: CASH | E26: TRANSFER_INSTANT_INBOUND | I26: 0 | J26: 0 | K26: 80 | L26: 0 | M26: 0 | N26: EUR | O26: 0 | Q26: 0 | R26: Incoming transfer from ROMEO TALLA FOTSING | S26: de466bec-4087-4c0a-8202-9aaf20516527
A27: 45910.357 | B27: 45910 | C27: DEFAULT | D27: CASH | E27: TRANSFER_INSTANT_INBOUND | I27: 0 | J27: 0 | K27: 50 | L27: 0 | M27: 0 | N27: EUR | O27: 0 | Q27: 0 | R27: Incoming transfer from ROMEO TALLA FOTSING | S27: 4c71c45a-503c-4c74-96ce-9f37f9f8b41a
A28: 45910.845 | B28: 45910 | C28: DEFAULT | D28: TRADING | E28: BUY | F28: STOCK | G28: RENK Group | H28: DE000RENK730 | I28: 1 | J28: 69.61 | K28: -69.61 | L28: -1 | M28: 0 | N28: EUR | O28: 0 | Q28: 0 | R28: Buy trade DE000RENK730 RENK GROUP AG INH O.N., quantity: 1 | S28: b604100c-0247-458c-829f-5bd7424f8603
A29: 45910.845 | B29: 45910 | C29: DEFAULT | D29: TRADING | E29: BUY | F29: STOCK | G29: RENK Group | H29: DE000RENK730 | I29: 0.134894 | J29: 69.61 | K29: -9.39 | L29: 0 | M29: 0 | N29: EUR | O29: 0 | Q29: 0 | R29: Buy trade DE000RENK730 RENK GROUP AG INH O.N., quantity: 0.134894 | S29: 728d465d-af9d-4e7c-8d16-17bcdeade476
A30: 45911.735 | B30: 45911 | C30: DEFAULT | D30: TRADING | E30: BUY | F30: STOCK | G30: Palantir Technologies | H30: US69608A1088 | I30: 0.052408 | J30: 141.58 | K30: -7.42 | L30: 0 | M30: 0 | N30: EUR | O30: 0 | Q30: 0 | R30: Buy trade US69608A1088 PALANTIR TECHNOLOGIES INC, quantity: 0.052408 | S30: 33934593-6ada-44ba-a54e-3b261f040217
A31: 45911.735 | B31: 45911 | C31: DEFAULT | D31: TRADING | E31: BUY | F31: STOCK | G31: Palantir Technologies | H31: US69608A1088 | I31: 1 | J31: 141.58 | K31: -141.58 | L31: -1 | M31: 0 | N31: EUR | O31: 0 | Q31: 0 | R31: Buy trade US69608A1088 PALANTIR TECHNOLOGIES INC, quantity: 1 | S31: 8ef7b29c-5d9e-4ffb-bfb7-9db3512a4693
A32: 45911.737 | B32: 45911 | C32: DEFAULT | D32: TRADING | E32: BUY | F32: STOCK | G32: RWE | H32: DE0007037129 | I32: 1 | J32: 35.81 | K32: -35.81 | L32: -1 | M32: 0 | N32: EUR | O32: 0 | Q32: 0 | R32: Buy trade DE0007037129 RWE AG ST O.N., quantity: 1 | S32: c7dc6691-719e-4fc2-ab45-33cbda29778b
A33: 45911.737 | B33: 45911 | C33: DEFAULT | D33: TRADING | E33: BUY | F33: STOCK | G33: RWE | H33: DE0007037129 | I33: 0.368332 | J33: 35.81 | K33: -13.19 | L33: 0 | M33: 0 | N33: EUR | O33: 0 | Q33: 0 | R33: Buy trade DE0007037129 RWE AG ST O.N., quantity: 0.368332 | S33: 06d1bbf5-d51f-43e8-b726-11fcb04b32f9
A34: 45911.982 | B34: 45911 | C34: DEFAULT | D34: TRADING | E34: BUY | F34: CRYPTO | G34: Chainlink | H34: LINK | I34: 2.367195 | J34: 20.6995 | K34: -49 | L34: -1 | M34: 0 | N34: EUR | O34: 0 | Q34: 0 | R34: Buy trade XF000LINK010 Chainlink, quantity: 2.367195 | S34: c99405ed-4454-4ee5-aa95-c21cee2c3fe4
A35: 45911.991 | B35: 45911 | C35: DEFAULT | D35: CASH | E35: TRANSFER_INSTANT_INBOUND | I35: 0 | J35: 0 | K35: 30 | L35: 0 | M35: 0 | N35: EUR | O35: 0 | Q35: 0 | R35: Incoming transfer from ROMEO TALLA FOTSING | S35: 61d73e9b-080e-4b38-8e9c-cfa53831534d
A36: 45911.981 | B36: 45911 | C36: DEFAULT | D36: CASH | E36: TRANSFER_INSTANT_INBOUND | I36: 0 | J36: 0 | K36: 49.01 | L36: 0 | M36: 0 | N36: EUR | O36: 0 | Q36: 0 | R36: Incoming transfer from ROMEO TALLA FOTSING | S36: 831bbaff-b1d8-4fce-ba2e-95946db4c5c9
A37: 45911.734 | B37: 45911 | C37: DEFAULT | D37: CASH | E37: TRANSFER_INSTANT_INBOUND | I37: 0 | J37: 0 | K37: 200 | L37: 0 | M37: 0 | N37: EUR | O37: 0 | Q37: 0 | R37: Incoming transfer from ROMEO TALLA FOTSING | S37: c3f80c0e-b161-4698-a026-5e62bb5941db
A38: 45911.992 | B38: 45911 | C38: DEFAULT | D38: TRADING | E38: BUY | F38: CRYPTO | G38: Render | H38: XF0RENDER015 | I38: 3.17 | J38: 3.46387 | K38: -10.98 | L38: -1 | M38: 0 | N38: EUR | O38: 0 | Q38: 0 | R38: Buy trade XF0RENDER015 Render Token, quantity: 3.17 | S38: 46bdf702-e375-4a1f-85a5-70d506e3a587
A39: 45911.992 | B39: 45911 | C39: DEFAULT | D39: TRADING | E39: BUY | F39: CRYPTO | G39: Polkadot | H39: DOT | I39: 4.691738 | J39: 3.62339 | K39: -17 | L39: -1 | M39: 0 | N39: EUR | O39: 0 | Q39: 0 | R39: Buy trade XF000DOT0011 Polkadot, quantity: 4.691738 | S39: c890608d-0d09-41fc-9e89-ee26200b50dc
A40: 45916.714 | B40: 45916 | C40: DEFAULT | D40: CASH | E40: TRANSFER_INSTANT_INBOUND | I40: 0 | J40: 0 | K40: 81 | L40: 0 | M40: 0 | N40: EUR | O40: 0 | Q40: 0 | R40: Incoming transfer from ROMEO TALLA FOTSING | S40: 61a8a189-a7cf-4d84-9a65-f99f55ab70b0
...

Sheet Auswertung
A1: Asset | B1: Klasse | C1: Symbol | D1: Käufe Stück | E1: Verkäufe Stück | F1: Bestand | G1: Investiert € | H1: Verkauft € | I1: Gebühren € | J1: Tax | K1: Netto P&L € | L1: Status | M1: Einstandskurs € | N1: Aktueller Kurs € | O1: Aktuell nicht realisierte P&L € | P1: Aktuelle Position € | Q1: Aktuell Investiert € | R1: Aktuelle Rendite | S1: Realisierte P&L Verkäufe € | T1: Investiertes Kapital Verkäufe € | U1: Anzahl Kauforders | V1: Anzahl Verkaufsorders | W1: Rendite Verkäufe | X1: Gesamte Rendite
A2: Algorand | B2: CRYPTO | C2: ALGO | D2: =SUMIFS(Daten!I:I,Daten!H:H,C2,Daten!E:E,"BUY") -> 160.77443 | E2: =-SUMIFS(Daten!I:I,Daten!H:H,C2,Daten!E:E,"SELL") -> 0 | F2: =D2-E2 -> 160.77443 | G2: =-SUMIFS(Daten!K:K,Daten!H:H,C2,Daten!E:E,"BUY") -> 19 | H2: =SUMIFS(Daten!K:K,Daten!H:H,C2,Daten!E:E,"SELL") -> 0 | I2: =SUMIFS(Daten!L:L,Daten!H:H,C2)*-1 -> 1 | J2: =-SUMIFS(Daten!M:M,Daten!E:E,"SELL",Daten!H:H,C2) -> 0 | K2: =H2-G2-I2-J2 -> -20 | L2: =IF(F2>0,"OFFEN","GESCHLOSSEN") -> OFFEN | M2: 0.1244 | N2: 0.105914 | O2: =IF(L2="GESCHLOSSEN", 0, IF(L2="OFFEN", ((N2*F2)-(M2*F2)), "")) -> -2.972076 | P2: =IF(F2>0,F2*N2,0) -> 17.028262 | Q2: =IF(F2>0,F2*M2,0) -> 20.000338 | R2: =IF(L2="GESCHLOSSEN", 0, IF(L2="OFFEN", (O2/(M2*F2)))) -> -0.14860129 | S2: =IF(L2="GESCHLOSSEN", H2-G2-I2 + SUMIFS(Daten!K:K,Daten!H:H,C2,Daten!E:E,"DIVIDEND"), IF(L2="OFFEN", IF(E2=0, 0, H2+SUMIFS(Daten!K:K,Daten!H:H,C2,Daten!E:E,"DIVIDEND")-(G2-(F2*M2))-I2 ), "")) -> 0 | T2: =IF(E2=0, 0, (G2-(F2*M2))+I2 ) -> 0 | U2: =COUNTIFS(Daten!H:H,C2,Daten!E:E,"BUY",Daten!L:L,"<0") -> 1 | V2: =COUNTIFS(Daten!H:H,C2,Daten!E:E,"SELL",Daten!L:L,"<0") -> 0 | W2: =IF(T2>0,S2/T2,0) -> 0 | X2: =IF(L2="GESCHLOSSEN", K2/(G2+I2), IF(L2="OFFEN", ((H2+N2*F2)-G2-I2)/G2, "")) -> -0.15640724
A3: Bayer | B3: STOCK | C3: DE000BAY0017 | D3: =SUMIFS(Daten!I:I,Daten!H:H,C3,Daten!E:E,"BUY") -> 15.014427 | E3: =-SUMIFS(Daten!I:I,Daten!H:H,C3,Daten!E:E,"SELL") -> 14.432513 | F3: =D3-E3 -> 0.581914 | G3: =-SUMIFS(Daten!K:K,Daten!H:H,C3,Daten!E:E,"BUY") -> 555.97 | H3: =SUMIFS(Daten!K:K,Daten!H:H,C3,Daten!E:E,"SELL") -> 660.92 | I3: =SUMIFS(Daten!L:L,Daten!H:H,C3)*-1 -> 8 | J3: =-SUMIFS(Daten!M:M,Daten!E:E,"SELL",Daten!H:H,C3) -> 0 | K3: =H3-G3-I3-J3 -> 96.95 | L3: =IF(F3>0,"OFFEN","GESCHLOSSEN") -> OFFEN | M3: 33.66 | N3: 42.966 | O3: =IF(L3="GESCHLOSSEN", 0, IF(L3="OFFEN", ((N3*F3)-(M3*F3)), "")) -> 5.4152917 | P3: =IF(F3>0,F3*N3,0) -> 25.002517 | Q3: =IF(F3>0,F3*M3,0) -> 19.587225 | R3: =IF(L3="GESCHLOSSEN", 0, IF(L3="OFFEN", (O3/(M3*F3)))) -> 0.27647059 | S3: =IF(L3="GESCHLOSSEN", H3-G3-I3 + SUMIFS(Daten!K:K,Daten!H:H,C3,Daten!E:E,"DIVIDEND"), IF(L3="OFFEN", IF(E3=0, 0, H3+SUMIFS(Daten!K:K,Daten!H:H,C3,Daten!E:E,"DIVIDEND")-(G3-(F3*M3))-I3 ), "")) -> 117.14723 | T3: =IF(E3=0, 0, (G3-(F3*M3))+I3 ) -> 544.38277 | U3: =COUNTIFS(Daten!H:H,C3,Daten!E:E,"BUY",Daten!L:L,"<0") -> 5 | V3: =COUNTIFS(Daten!H:H,C3,Daten!E:E,"SELL",Daten!L:L,"<0") -> 3 | W3: =IF(T3>0,S3/T3,0) -> 0.21519275 | X3: =IF(L3="GESCHLOSSEN", K3/(G3+I3), IF(L3="OFFEN", ((H3+N3*F3)-G3-I3)/G3, "")) -> 0.21935089
A4: BP | B4: STOCK | C4: GB0007980591 | D4: =SUMIFS(Daten!I:I,Daten!H:H,C4,Daten!E:E,"BUY") -> 107.18673 | E4: =-SUMIFS(Daten!I:I,Daten!H:H,C4,Daten!E:E,"SELL") -> 107.18673 | F4: =D4-E4 -> 0 | G4: =-SUMIFS(Daten!K:K,Daten!H:H,C4,Daten!E:E,"BUY") -> 650 | H4: =SUMIFS(Daten!K:K,Daten!H:H,C4,Daten!E:E,"SELL") -> 684.86 | I4: =SUMIFS(Daten!L:L,Daten!H:H,C4)*-1 -> 7 | J4: =-SUMIFS(Daten!M:M,Daten!E:E,"SELL",Daten!H:H,C4) -> 0 | K4: =H4-G4-I4-J4 -> 27.86 | L4: =IF(F4>0,"OFFEN","GESCHLOSSEN") -> GESCHLOSSEN | M4: 0 | N4: 0 | O4: =IF(L4="GESCHLOSSEN", 0, IF(L4="OFFEN", ((N4*F4)-(M4*F4)), "")) -> 0 | P4: =IF(F4>0,F4*N4,0) -> 0 | Q4: =IF(F4>0,F4*M4,0) -> 0 | R4: =IF(L4="GESCHLOSSEN", 0, IF(L4="OFFEN", (O4/(M4*F4)))) -> 0 | S4: =IF(L4="GESCHLOSSEN", H4-G4-I4 + SUMIFS(Daten!K:K,Daten!H:H,C4,Daten!E:E,"DIVIDEND"), IF(L4="OFFEN", IF(E4=0, 0, H4+SUMIFS(Daten!K:K,Daten!H:H,C4,Daten!E:E,"DIVIDEND")-(G4-(F4*M4))-I4 ), "")) -> 31.26 | T4: =IF(E4=0, 0, (G4-(F4*M4))+I4 ) -> 657 | U4: =COUNTIFS(Daten!H:H,C4,Daten!E:E,"BUY",Daten!L:L,"<0") -> 4 | V4: =COUNTIFS(Daten!H:H,C4,Daten!E:E,"SELL",Daten!L:L,"<0") -> 3 | W4: =IF(T4>0,S4/T4,0) -> 0.047579909 | X4: =IF(L4="GESCHLOSSEN", K4/(G4+I4), IF(L4="OFFEN", ((H4+N4*F4)-G4-I4)/G4, "")) -> 0.042404871
A5: BTQ Technologies | B5: STOCK | C5: CA0558691014 | D5: =SUMIFS(Daten!I:I,Daten!H:H,C5,Daten!E:E,"BUY") -> 147.77105 | E5: =-SUMIFS(Daten!I:I,Daten!H:H,C5,Daten!E:E,"SELL") -> 147.77105 | F5: =D5-E5 -> 0 | G5: =-SUMIFS(Daten!K:K,Daten!H:H,C5,Daten!E:E,"BUY") -> 626 | H5: =SUMIFS(Daten!K:K,Daten!H:H,C5,Daten!E:E,"SELL") -> 727.03 | I5: =SUMIFS(Daten!L:L,Daten!H:H,C5)*-1 -> 13 | J5: =-SUMIFS(Daten!M:M,Daten!E:E,"SELL",Daten!H:H,C5) -> 0 | K5: =H5-G5-I5-J5 -> 88.03 | L5: =IF(F5>0,"OFFEN","GESCHLOSSEN") -> GESCHLOSSEN | M5: 0 | N5: 0 | O5: =IF(L5="GESCHLOSSEN", 0, IF(L5="OFFEN", ((N5*F5)-(M5*F5)), "")) -> 0 | P5: =IF(F5>0,F5*N5,0) -> 0 | Q5: =IF(F5>0,F5*M5,0) -> 0 | R5: =IF(L5="GESCHLOSSEN", 0, IF(L5="OFFEN", (O5/(M5*F5)))) -> 0 | S5: =IF(L5="GESCHLOSSEN", H5-G5-I5 + SUMIFS(Daten!K:K,Daten!H:H,C5,Daten!E:E,"DIVIDEND"), IF(L5="OFFEN", IF(E5=0, 0, H5+SUMIFS(Daten!K:K,Daten!H:H,C5,Daten!E:E,"DIVIDEND")-(G5-(F5*M5))-I5 ), "")) -> 88.03 | T5: =IF(E5=0, 0, (G5-(F5*M5))+I5 ) -> 639 | U5: =COUNTIFS(Daten!H:H,C5,Daten!E:E,"BUY",Daten!L:L,"<0") -> 12 | V5: =COUNTIFS(Daten!H:H,C5,Daten!E:E,"SELL",Daten!L:L,"<0") -> 1 | W5: =IF(T5>0,S5/T5,0) -> 0.13776213 | X5: =IF(L5="GESCHLOSSEN", K5/(G5+I5), IF(L5="OFFEN", ((H5+N5*F5)-G5-I5)/G5, "")) -> 0.13776213
A6: BYD | B6: STOCK | C6: CNE100000296 | D6: =SUMIFS(Daten!I:I,Daten!H:H,C6,Daten!E:E,"BUY") -> 22.577083 | E6: =-SUMIFS(Daten!I:I,Daten!H:H,C6,Daten!E:E,"SELL") -> 22.577083 | F6: =D6-E6 -> 0 | G6: =-SUMIFS(Daten!K:K,Daten!H:H,C6,Daten!E:E,"BUY") -> 244 | H6: =SUMIFS(Daten!K:K,Daten!H:H,C6,Daten!E:E,"SELL") -> 242.46 | I6: =SUMIFS(Daten!L:L,Daten!H:H,C6)*-1 -> 5 | J6: =-SUMIFS(Daten!M:M,Daten!E:E,"SELL",Daten!H:H,C6) -> 0 | K6: =H6-G6-I6-J6 -> -6.54 | L6: =IF(F6>0,"OFFEN","GESCHLOSSEN") -> GESCHLOSSEN | M6: 0 | N6: 0 | O6: =IF(L6="GESCHLOSSEN", 0, IF(L6="OFFEN", ((N6*F6)-(M6*F6)), "")) -> 0 | P6: =IF(F6>0,F6*N6,0) -> 0 | Q6: =IF(F6>0,F6*M6,0) -> 0 | R6: =IF(L6="GESCHLOSSEN", 0, IF(L6="OFFEN", (O6/(M6*F6)))) -> 0 | S6: =IF(L6="GESCHLOSSEN", H6-G6-I6 + SUMIFS(Daten!K:K,Daten!H:H,C6,Daten!E:E,"DIVIDEND"), IF(L6="OFFEN", IF(E6=0, 0, H6+SUMIFS(Daten!K:K,Daten!H:H,C6,Daten!E:E,"DIVIDEND")-(G6-(F6*M6))-I6 ), "")) -> -6.54 | T6: =IF(E6=0, 0, (G6-(F6*M6))+I6 ) -> 249 | U6: =COUNTIFS(Daten!H:H,C6,Daten!E:E,"BUY",Daten!L:L,"<0") -> 3 | V6: =COUNTIFS(Daten!H:H,C6,Daten!E:E,"SELL",Daten!L:L,"<0") -> 2 | W6: =IF(T6>0,S6/T6,0) -> -0.02626506 | X6: =IF(L6="GESCHLOSSEN", K6/(G6+I6), IF(L6="OFFEN", ((H6+N6*F6)-G6-I6)/G6, "")) -> -0.02626506
A7: Cardano | B7: CRYPTO | C7: ADA | D7: =SUMIFS(Daten!I:I,Daten!H:H,C7,Daten!E:E,"BUY") -> 714.06128 | E7: =-SUMIFS(Daten!I:I,Daten!H:H,C7,Daten!E:E,"SELL") -> 0 | F7: =D7-E7 -> 714.06128 | G7: =-SUMIFS(Daten!K:K,Daten!H:H,C7,Daten!E:E,"BUY") -> 178.99 | H7: =SUMIFS(Daten!K:K,Daten!H:H,C7,Daten!E:E,"SELL") -> 0 | I7: =SUMIFS(Daten!L:L,Daten!H:H,C7)*-1 -> 5 | J7: =-SUMIFS(Daten!M:M,Daten!E:E,"SELL",Daten!H:H,C7) -> 0 | K7: =H7-G7-I7-J7 -> -183.99 | L7: =IF(F7>0,"OFFEN","GESCHLOSSEN") -> OFFEN | M7: 0.258 | N7: 0.212991 | O7: =IF(L7="GESCHLOSSEN", 0, IF(L7="OFFEN", ((N7*F7)-(M7*F7)), "")) -> -32.139184 | P7: =IF(F7>0,F7*N7,0) -> 152.08863 | Q7: =IF(F7>0,F7*M7,0) -> 184.22781 | R7: =IF(L7="GESCHLOSSEN", 0, IF(L7="OFFEN", (O7/(M7*F7)))) -> -0.17445349 | S7: =IF(L7="GESCHLOSSEN", H7-G7-I7 + SUMIFS(Daten!K:K,Daten!H:H,C7,Daten!E:E,"DIVIDEND"), IF(L7="OFFEN", IF(E7=0, 0, H7+SUMIFS(Daten!K:K,Daten!H:H,C7,Daten!E:E,"DIVIDEND")-(G7-(F7*M7))-I7 ), "")) -> 0 | T7: =IF(E7=0, 0, (G7-(F7*M7))+I7 ) -> 0 | U7: =COUNTIFS(Daten!H:H,C7,Daten!E:E,"BUY",Daten!L:L,"<0") -> 5 | V7: =COUNTIFS(Daten!H:H,C7,Daten!E:E,"SELL",Daten!L:L,"<0") -> 0 | W7: =IF(T7>0,S7/T7,0) -> 0 | X7: =IF(L7="GESCHLOSSEN", K7/(G7+I7), IF(L7="OFFEN", ((H7+N7*F7)-G7-I7)/G7, "")) -> -0.17822992
A8: Centrotherm Photovoltaics | B8: STOCK | C8: DE000A1TNMM9 | D8: =SUMIFS(Daten!I:I,Daten!H:H,C8,Daten!E:E,"BUY") -> 23.832335 | E8: =-SUMIFS(Daten!I:I,Daten!H:H,C8,Daten!E:E,"SELL") -> 23.832335 | F8: =D8-E8 -> 0 | G8: =-SUMIFS(Daten!K:K,Daten!H:H,C8,Daten!E:E,"BUY") -> 199 | H8: =SUMIFS(Daten!K:K,Daten!H:H,C8,Daten!E:E,"SELL") -> 252.62 | I8: =SUMIFS(Daten!L:L,Daten!H:H,C8)*-1 -> 3 | J8: =-SUMIFS(Daten!M:M,Daten!E:E,"SELL",Daten!H:H,C8) -> 0 | K8: =H8-G8-I8-J8 -> 50.62 | L8: =IF(F8>0,"OFFEN","GESCHLOSSEN") -> GESCHLOSSEN | M8: 0 | N8: 0 | O8: =IF(L8="GESCHLOSSEN", 0, IF(L8="OFFEN", ((N8*F8)-(M8*F8)), "")) -> 0 | P8: =IF(F8>0,F8*N8,0) -> 0 | Q8: =IF(F8>0,F8*M8,0) -> 0 | R8: =IF(L8="GESCHLOSSEN", 0, IF(L8="OFFEN", (O8/(M8*F8)))) -> 0 | S8: =IF(L8="GESCHLOSSEN", H8-G8-I8 + SUMIFS(Daten!K:K,Daten!H:H,C8,Daten!E:E,"DIVIDEND"), IF(L8="OFFEN", IF(E8=0, 0, H8+SUMIFS(Daten!K:K,Daten!H:H,C8,Daten!E:E,"DIVIDEND")-(G8-(F8*M8))-I8 ), "")) -> 50.62 | T8: =IF(E8=0, 0, (G8-(F8*M8))+I8 ) -> 202 | U8: =COUNTIFS(Daten!H:H,C8,Daten!E:E,"BUY",Daten!L:L,"<0") -> 1 | V8: =COUNTIFS(Daten!H:H,C8,Daten!E:E,"SELL",Daten!L:L,"<0") -> 2 | W8: =IF(T8>0,S8/T8,0) -> 0.25059406 | X8: =IF(L8="GESCHLOSSEN", K8/(G8+I8), IF(L8="OFFEN", ((H8+N8*F8)-G8-I8)/G8, "")) -> 0.25059406
A9: Chainlink | B9: CRYPTO | C9: LINK | D9: =SUMIFS(Daten!I:I,Daten!H:H,C9,Daten!E:E,"BUY") -> 39.670691 | E9: =-SUMIFS(Daten!I:I,Daten!H:H,C9,Daten!E:E,"SELL") -> 24.110118 | F9: =D9-E9 -> 15.560573 | G9: =-SUMIFS(Daten!K:K,Daten!H:H,C9,Daten!E:E,"BUY") -> 422.62 | H9: =SUMIFS(Daten!K:K,Daten!H:H,C9,Daten!E:E,"SELL") -> 263.53 | I9: =SUMIFS(Daten!L:L,Daten!H:H,C9)*-1 -> 8 | J9: =-SUMIFS(Daten!M:M,Daten!E:E,"SELL",Daten!H:H,C9) -> 0 | K9: =H9-G9-I9-J9 -> -167.09 | L9: =IF(F9>0,"OFFEN","GESCHLOSSEN") -> OFFEN | M9: 11.67 | N9: 11.47 | O9: =IF(L9="GESCHLOSSEN", 0, IF(L9="OFFEN", ((N9*F9)-(M9*F9)), "")) -> -3.1121146 | P9: =IF(F9>0,F9*N9,0) -> 178.47977 | Q9: =IF(F9>0,F9*M9,0) -> 181.59189 | R9: =IF(L9="GESCHLOSSEN", 0, IF(L9="OFFEN", (O9/(M9*F9)))) -> -0.017137961 | S9: =IF(L9="GESCHLOSSEN", H9-G9-I9 + SUMIFS(Daten!K:K,Daten!H:H,C9,Daten!E:E,"DIVIDEND"), IF(L9="OFFEN", IF(E9=0, 0, H9+SUMIFS(Daten!K:K,Daten!H:H,C9,Daten!E:E,"DIVIDEND")-(G9-(F9*M9))-I9 ), "")) -> 14.501887 | T9: =IF(E9=0, 0, (G9-(F9*M9))+I9 ) -> 249.02811 | U9: =COUNTIFS(Daten!H:H,C9,Daten!E:E,"BUY",Daten!L:L,"<0") -> 7 | V9: =COUNTIFS(Daten!H:H,C9,Daten!E:E,"SELL",Daten!L:L,"<0") -> 1 | W9: =IF(T9>0,S9/T9,0) -> 0.058233935 | X9: =IF(L9="GESCHLOSSEN", K9/(G9+I9), IF(L9="OFFEN", ((H9+N9*F9)-G9-I9)/G9, "")) -> 0.026950386
A10: Core MSCI EM IMI USD (Acc) | B10: FUND | C10: IE00BKM4GZ66 | D10: =SUMIFS(Daten!I:I,Daten!H:H,C10,Daten!E:E,"BUY") -> 14.461017 | E10: =-SUMIFS(Daten!I:I,Daten!H:H,C10,Daten!E:E,"SELL") -> 0 | F10: =D10-E10 -> 14.461017 | G10: =-SUMIFS(Daten!K:K,Daten!H:H,C10,Daten!E:E,"BUY") -> 698.08 | H10: =SUMIFS(Daten!K:K,Daten!H:H,C10,Daten!E:E,"SELL") -> 0 | I10: =SUMIFS(Daten!L:L,Daten!H:H,C10)*-1 -> 1 | J10: =-SUMIFS(Daten!M:M,Daten!E:E,"SELL",Daten!H:H,C10) -> 0 | K10: =H10-G10-I10-J10 -> -699.08 | L10: =IF(F10>0,"OFFEN","GESCHLOSSEN") -> OFFEN | M10: 48.34 | N10: 48.937 | O10: =IF(L10="GESCHLOSSEN", 0, IF(L10="OFFEN", ((N10*F10)-(M10*F10)), "")) -> 8.6332271 | P10: =IF(F10>0,F10*N10,0) -> 707.67879 | Q10: =IF(F10>0,F10*M10,0) -> 699.04556 | R10: =IF(L10="GESCHLOSSEN", 0, IF(L10="OFFEN", (O10/(M10*F10)))) -> 0.012350021 | S10: =IF(L10="GESCHLOSSEN", H10-G10-I10 + SUMIFS(Daten!K:K,Daten!H:H,C10,Daten!E:E,"DIVIDEND"), IF(L10="OFFEN", IF(E10=0, 0, H10+SUMIFS(Daten!K:K,Daten!H:H,C10,Daten!E:E,"DIVIDEND")-(G10-(F10*M10))-I10 ), "")) -> 0 | T10: =IF(E10=0, 0, (G10-(F10*M10))+I10 ) -> 0 | U10: =COUNTIFS(Daten!H:H,C10,Daten!E:E,"BUY",Daten!L:L,"<0") -> 1 | V10: =COUNTIFS(Daten!H:H,C10,Daten!E:E,"SELL",Daten!L:L,"<0") -> 0 | W10: =IF(T10>0,S10/T10,0) -> 0 | X10: =IF(L10="GESCHLOSSEN", K10/(G10+I10), IF(L10="OFFEN", ((H10+N10*F10)-G10-I10)/G10, "")) -> 0.01231777
A11: Core MSCI World USD (Acc) | B11: FUND | C11: IE00B4L5Y983 | D11: =SUMIFS(Daten!I:I,Daten!H:H,C11,Daten!E:E,"BUY") -> 9.064302 | E11: =-SUMIFS(Daten!I:I,Daten!H:H,C11,Daten!E:E,"SELL") -> 9.064302 | F11: =D11-E11 -> 0 | G11: =-SUMIFS(Daten!K:K,Daten!H:H,C11,Daten!E:E,"BUY") -> 1049.99 | H11: =SUMIFS(Daten!K:K,Daten!H:H,C11,Daten!E:E,"SELL") -> 1179.9 | I11: =SUMIFS(Daten!L:L,Daten!H:H,C11)*-1 -> 9 | J11: =-SUMIFS(Daten!M:M,Daten!E:E,"SELL",Daten!H:H,C11) -> 16.5 | K11: =H11-G11-I11-J11 -> 104.41 | L11: =IF(F11>0,"OFFEN","GESCHLOSSEN") -> GESCHLOSSEN | M11: 0 | N11: 0 | O11: =IF(L11="GESCHLOSSEN", 0, IF(L11="OFFEN", ((N11*F11)-(M11*F11)), "")) -> 0 | P11: =IF(F11>0,F11*N11,0) -> 0 | Q11: =IF(F11>0,F11*M11,0) -> 0 | R11: =IF(L11="GESCHLOSSEN", 0, IF(L11="OFFEN", (O11/(M11*F11)))) -> 0 | S11: =IF(L11="GESCHLOSSEN", H11-G11-I11 + SUMIFS(Daten!K:K,Daten!H:H,C11,Daten!E:E,"DIVIDEND"), IF(L11="OFFEN", IF(E11=0, 0, H11+SUMIFS(Daten!K:K,Daten!H:H,C11,Daten!E:E,"DIVIDEND")-(G11-(F11*M11))-I11 ), "")) -> 120.91 | T11: =IF(E11=0, 0, (G11-(F11*M11))+I11 ) -> 1058.99 | U11: =COUNTIFS(Daten!H:H,C11,Daten!E:E,"BUY",Daten!L:L,"<0") -> 7 | V11: =COUNTIFS(Daten!H:H,C11,Daten!E:E,"SELL",Daten!L:L,"<0") -> 2 | W11: =IF(T11>0,S11/T11,0) -> 0.11417483 | X11: =IF(L11="GESCHLOSSEN", K11/(G11+I11), IF(L11="OFFEN", ((H11+N11*F11)-G11-I11)/G11, "")) -> 0.098593943
A12: Core S&P 500 USD (Acc) | B12: FUND | C12: IE00B5BMR087 | D12: =SUMIFS(Daten!I:I,Daten!H:H,C12,Daten!E:E,"BUY") -> 2.862315 | E12: =-SUMIFS(Daten!I:I,Daten!H:H,C12,Daten!E:E,"SELL") -> 1.526442 | F12: =D12-E12 -> 1.335873 | G12: =-SUMIFS(Daten!K:K,Daten!H:H,C12,Daten!E:E,"BUY") -> 1837.88 | H12: =SUMIFS(Daten!K:K,Daten!H:H,C12,Daten!E:E,"SELL") -> 1134 | I12: =SUMIFS(Daten!L:L,Daten!H:H,C12)*-1 -> 10 | J12: =-SUMIFS(Daten!M:M,Daten!E:E,"SELL",Daten!H:H,C12) -> 13.16 | K12: =H12-G12-I12-J12 -> -727.04 | L12: =IF(F12>0,"OFFEN","GESCHLOSSEN") -> OFFEN | M12: 674.19 | N12: 749.4 | O12: =IF(L12="GESCHLOSSEN", 0, IF(L12="OFFEN", ((N12*F12)-(M12*F12)), "")) -> 100.47101 | P12: =IF(F12>0,F12*N12,0) -> 1001.1032 | Q12: =IF(F12>0,F12*M12,0) -> 900.63222 | R12: =IF(L12="GESCHLOSSEN", 0, IF(L12="OFFEN", (O12/(M12*F12)))) -> 0.11155609 | S12: =IF(L12="GESCHLOSSEN", H12-G12-I12 + SUMIFS(Daten!K:K,Daten!H:H,C12,Daten!E:E,"DIVIDEND"), IF(L12="OFFEN", IF(E12=0, 0, H12+SUMIFS(Daten!K:K,Daten!H:H,C12,Daten!E:E,"DIVIDEND")-(G12-(F12*M12))-I12 ), "")) -> 186.75222 | T12: =IF(E12=0, 0, (G12-(F12*M12))+I12 ) -> 947.24778 | U12: =COUNTIFS(Daten!H:H,C12,Daten!E:E,"BUY",Daten!L:L,"<0") -> 8 | V12: =COUNTIFS(Daten!H:H,C12,Daten!E:E,"SELL",Daten!L:L,"<0") -> 2 | W12: =IF(T12>0,S12/T12,0) -> 0.19715245 | X12: =IF(L12="GESCHLOSSEN", K12/(G12+I12), IF(L12="OFFEN", ((H12+N12*F12)-G12-I12)/G12, "")) -> 0.15627964
A13: Core Stoxx Europe 600 EUR (Acc) | B13: FUND | C13: LU0908500753 | D13: =SUMIFS(Daten!I:I,Daten!H:H,C13,Daten!E:E,"BUY") -> 2.337223 | E13: =-SUMIFS(Daten!I:I,Daten!H:H,C13,Daten!E:E,"SELL") -> 0 | F13: =D13-E13 -> 2.337223 | G13: =-SUMIFS(Daten!K:K,Daten!H:H,C13,Daten!E:E,"BUY") -> 703.81 | H13: =SUMIFS(Daten!K:K,Daten!H:H,C13,Daten!E:E,"SELL") -> 0 | I13: =SUMIFS(Daten!L:L,Daten!H:H,C13)*-1 -> 3 | J13: =-SUMIFS(Daten!M:M,Daten!E:E,"SELL",Daten!H:H,C13) -> 0 | K13: =H13-G13-I13-J13 -> -706.81 | L13: =IF(F13>0,"OFFEN","GESCHLOSSEN") -> OFFEN | M13: 302.41 | N13: 311.45 | O13: =IF(L13="GESCHLOSSEN", 0, IF(L13="OFFEN", ((N13*F13)-(M13*F13)), "")) -> 21.128496 | P13: =IF(F13>0,F13*N13,0) -> 727.9281 | Q13: =IF(F13>0,F13*M13,0) -> 706.79961 | R13: =IF(L13="GESCHLOSSEN", 0, IF(L13="OFFEN", (O13/(M13*F13)))) -> 0.029893191 | S13: =IF(L13="GESCHLOSSEN", H13-G13-I13 + SUMIFS(Daten!K:K,Daten!H:H,C13,Daten!E:E,"DIVIDEND"), IF(L13="OFFEN", IF(E13=0, 0, H13+SUMIFS(Daten!K:K,Daten!H:H,C13,Daten!E:E,"DIVIDEND")-(G13-(F13*M13))-I13 ), "")) -> 0 | T13: =IF(E13=0, 0, (G13-(F13*M13))+I13 ) -> 0 | U13: =COUNTIFS(Daten!H:H,C13,Daten!E:E,"BUY",Daten!L:L,"<0") -> 3 | V13: =COUNTIFS(Daten!H:H,C13,Daten!E:E,"SELL",Daten!L:L,"<0") -> 0 | W13: =IF(T13>0,S13/T13,0) -> 0 | X13: =IF(L13="GESCHLOSSEN", K13/(G13+I13), IF(L13="OFFEN", ((H13+N13*F13)-G13-I13)/G13, "")) -> 0.030005404
... A63: Zinzino | B63: STOCK | C63: SE0002480442 | D63: =SUMIFS(Daten!I:I,Daten!H:H,C63,Daten!E:E,"BUY") -> 8.503401 | E63: =-SUMIFS(Daten!I:I,Daten!H:H,C63,Daten!E:E,"SELL") -> 0 | F63: =D63-E63 -> 8.503401 | G63: =-SUMIFS(Daten!K:K,Daten!H:H,C63,Daten!E:E,"BUY") -> 100 | H63: =SUMIFS(Daten!K:K,Daten!H:H,C63,Daten!E:E,"SELL") -> 0 | I63: =SUMIFS(Daten!L:L,Daten!H:H,C63)*-1 -> 1 | J63: =-SUMIFS(Daten!M:M,Daten!E:E,"SELL",Daten!H:H,C63) -> 0 | K63: =H63-G63-I63-J63 -> -101 | L63: =IF(F63>0,"OFFEN","GESCHLOSSEN") -> OFFEN | M63: 11.88 | N63: 11.3337 | O63: =IF(L63="GESCHLOSSEN", 0, IF(L63="OFFEN", ((N63*F63)-(M63*F63)), "")) -> -4.645408 | P63: =IF(F63>0,F63*N63,0) -> 96.374996 | Q63: =IF(F63>0,F63*M63,0) -> 101.0204 | R63: =IF(L63="GESCHLOSSEN", 0, IF(L63="OFFEN", (O63/(M63*F63)))) -> -0.045984848 | S63: =IF(L63="GESCHLOSSEN", H63-G63-I63 + SUMIFS(Daten!K:K,Daten!H:H,C63,Daten!E:E,"DIVIDEND"), IF(L63="OFFEN", IF(E63=0, 0, H63+SUMIFS(Daten!K:K,Daten!H:H,C63,Daten!E:E,"DIVIDEND")-(G63-(F63*M63))-I63 ), "")) -> 0 | T63: =IF(E63=0, 0, (G63-(F63*M63))+I63 ) -> 0 | U63: =COUNTIFS(Daten!H:H,C63,Daten!E:E,"BUY",Daten!L:L,"<0") -> 1 | V63: =COUNTIFS(Daten!H:H,C63,Daten!E:E,"SELL",Daten!L:L,"<0") -> 0 | W63: =IF(T63>0,S63/T63,0) -> 0 | X63: =IF(L63="GESCHLOSSEN", K63/(G63+I63), IF(L63="OFFEN", ((H63+N63*F63)-G63-I63)/G63, "")) -> -0.046250041
E72: {=SUMPRODUCT( (Daten!$H$2:$H$10000=C51)* (Daten!$E$2:$E$10000="BUY")* Daten!$I$2:$I$10000* Daten!$J$2:$J$10000 )} -> 600.06207 | F72: =-SUMIFS(Daten!L:L,Daten!H:H,C51,Daten!E:E,"BUY") -> 7 | G72: =(E72+F72)/D51 -> 102.74799
E73: {=-SUMPRODUCT( (Daten!$H$2:$H$10000=C2)* (Daten!$E$2:$E$10000="SELL")* Daten!$I$2:$I$10000* Daten!$J$2:$J$10000 )} -> 0 | F73: =-SUMIFS(Daten!L:L,Daten!H:H,C2,Daten!E:E,"SELL") -> 0 | G73: =(E72+F72-E73-F73)/(D2-E2) -> 3.7758621 | H73: =(E73+F73)/E3 -> 0
H75: =(D3*M3)/F3 -> 868.48849

Sheet Dashboard
A1: Portfolio KPIs
A3: Anzahl Assets | B3: =COUNTA(Auswertung!A:A) - 1 -> 62 | C3: =IF(ABS(B3)>0,B3/B3,0) -> 1
A4: Anzahl STOCK | B4: =COUNTIFS(Auswertung!B:B,"STOCK") -> 39 | C4: =IF(ABS(B3)>0,B4/B3,0) -> 0.62903226
A5: Anzahl FUND | B5: =COUNTIFS(Auswertung!B:B,"FUND") -> 14 | C5: =IF(ABS(B3)>0,B5/B3,0) -> 0.22580645
A6: Anzahl CRYPTO | B6: =COUNTIFS(Auswertung!B:B,"CRYPTO") -> 9 | C6: =IF(ABS(B3)>0,B6/B3,0) -> 0.14516129
A8: Offene Assets | B8: =COUNTIFS(Auswertung!L:L,"OFFEN") -> 28 | C8: =IF(ABS(B8)>0,B8/B8,0) -> 1
A9: Offene STOCK | B9: =COUNTIFS(Auswertung!B:B,"STOCK",Auswertung!L:L,"OFFEN") -> 9 | C9: =IF(ABS(B8)>0,B9/B8,0) -> 0.32142857
A10: Offene FUND | B10: =COUNTIFS(Auswertung!B:B,"FUND",Auswertung!L:L,"OFFEN") -> 11 | C10: =IF(ABS(B8)>0,B10/B8,0) -> 0.39285714
A11: Offene CRYPTO | B11: =COUNTIFS(Auswertung!B:B,"CRYPTO",Auswertung!L:L,"OFFEN") -> 8 | C11: =IF(ABS(B8)>0,B11/B8,0) -> 0.28571429
A13: Closed Assets | B13: =COUNTIFS(Auswertung!L:L,"GESCHLOSSEN") -> 34
A14: Closed STOCK | B14: =COUNTIFS(Auswertung!B:B,"STOCK",Auswertung!L:L,"GESCHLOSSEN") -> 30
A15: Closed FUND | B15: =COUNTIFS(Auswertung!B:B,"FUND",Auswertung!L:L,"GESCHLOSSEN") -> 3
A16: Closed CRYPTO | B16: =COUNTIFS(Auswertung!B:B,"CRYPTO",Auswertung!L:L,"GESCHLOSSEN") -> 1
A18: Brutto Investiert | B18: =SUM(Auswertung!G:G)-SUMIFS(Daten!L:L,Daten!E:E,"BUY") -> 25883.054 | D18: =-SUMIFS(Daten!K:K,Daten!E:E,"BUY")-SUMIFS(Daten!L:L,Daten!E:E,"BUY") -> 25776.53
A19: Brutto Investiert STOCK&FUND | B19: =SUMIFS(Auswertung!G:G,Auswertung!B:B,"STOCK")+SUMIFS(Auswertung!G:G,Auswertung!B:B,"FUND")-SUMIFS(Daten!L:L,Daten!E:E,"BUY",Daten!F:F,"STOCK")-SUMIFS(Daten!L:L,Daten!E:E,"BUY",Daten!F:F,"FUND") -> 23457.26 | C19: =IF(ABS(B18)>0,B19/B18,0) -> 0.90627868 | D19: =-SUMIFS(Daten!K:K,Daten!F:F,"STOCK",Daten!E:E,"BUY")-SUMIFS(Daten!K:K,Daten!F:F,"FUND",Daten!E:E,"BUY")-SUMIFS(Daten!L:L,Daten!E:E,"BUY",Daten!F:F,"STOCK")-SUMIFS(Daten!L:L,Daten!E:E,"BUY",Daten!F:F,"FUND") -> 23457.26
A20: Brutto Investiert STOCK | B20: =SUMIFS(Auswertung!G:G,Auswertung!B:B,"STOCK")-SUMIFS(Daten!L:L,Daten!E:E,"BUY",Daten!F:F,"STOCK") -> 13755.09 | C20: =IF(ABS(B18)>0,B20/B18,0) -> 0.53143227 | D20: =-SUMIFS(Daten!K:K,Daten!F:F,"STOCK",Daten!E:E,"BUY")-SUMIFS(Daten!L:L,Daten!E:E,"BUY",Daten!F:F,"STOCK") -> 13755.09
A21: Brutto Investiert FUND | B21: =SUMIFS(Auswertung!G:G,Auswertung!B:B,"FUND")-SUMIFS(Daten!L:L,Daten!E:E,"BUY",Daten!F:F,"FUND") -> 9702.17 | C21: =IF(ABS(B18)>0,B21/B18,0) -> 0.37484642 | D21: =-SUMIFS(Daten!K:K,Daten!F:F,"FUND",Daten!E:E,"BUY")-SUMIFS(Daten!L:L,Daten!E:E,"BUY",Daten!F:F,"FUND") -> 9702.17
A22: Brutto Investiert CRYPTO | B22: =SUMIFS(Auswertung!G:G,Auswertung!B:B,"CRYPTO")-SUMIFS(Daten!L:L,Daten!E:E,"BUY",Daten!F:F,"CRYPTO") -> 2319.27 | C22: =IF(ABS(B18)>0,B22/B18,0) -> 0.089605732 | D22: =-SUMIFS(Daten!K:K,Daten!F:F,"CRYPTO",Daten!E:E,"BUY")-SUMIFS(Daten!L:L,Daten!E:E,"BUY",Daten!F:F,"CRYPTO") -> 2319.27
A24: Netto Investiert | B24: =SUM(Auswertung!G:G) -> 25656.054 | D24: =-SUMIFS(Daten!K:K,Daten!E:E,"BUY") -> 25549.53
A25: Netto Investiert STOCK&FUND | B25: =SUMIFS(Auswertung!G:G,Auswertung!B:B,"STOCK")+SUMIFS(Auswertung!G:G,Auswertung!B:B,"FUND") -> 23272.26 | C25: =IF(ABS(B24)>0,B25/B24,0) -> 0.9070865 | D25: =-SUMIFS(Daten!K:K,Daten!F:F,"STOCK",Daten!E:E,"BUY")-SUMIFS(Daten!K:K,Daten!F:F,"FUND",Daten!E:E,"BUY") -> 23272.26
A26: Netto Investiert STOCK | B26: =SUMIFS(Auswertung!G:G,Auswertung!B:B,"STOCK") -> 13622.09 | C26: =IF(ABS(B24)>0,B26/B24,0) -> 0.53095032 | D26: =-SUMIFS(Daten!K:K,Daten!F:F,"STOCK",Daten!E:E,"BUY") -> 13622.09
A27: Netto Investiert FUND | B27: =SUMIFS(Auswertung!G:G,Auswertung!B:B,"FUND") -> 9650.17 | C27: =IF(ABS(B24)>0,B27/B24,0) -> 0.37613618 | D27: =-SUMIFS(Daten!K:K,Daten!F:F,"FUND",Daten!E:E,"BUY") -> 9650.17
A28: Netto Investiert CRYPTO | B28: =SUMIFS(Auswertung!G:G,Auswertung!B:B,"CRYPTO") -> 2277.27 | C28: =IF(ABS(B24)>0,B28/B24,0) -> 0.088761507 | D28: =-SUMIFS(Daten!K:K,Daten!F:F,"CRYPTO",Daten!E:E,"BUY") -> 2277.27
A30: Brutto Verkauft | B30: =SUM(Auswertung!H:H)-SUMIFS(Daten!L:L,Daten!E:E,"SELL") -> 16730.788 | D30: =SUMIFS(Daten!K:K,Daten!E:E,"SELL")-SUMIFS(Daten!L:L,Daten!E:E,"SELL") -> 15862.3
A31: Brutto Verkauft STOCK&FUND | B31: =SUMIFS(Auswertung!H:H,Auswertung!B:B,"STOCK")+SUMIFS(Auswertung!H:H,Auswertung!B:B,"FUND")-SUMIFS(Daten!L:L,Daten!E:E,"SELL",Daten!F:F,"STOCK")-SUMIFS(Daten!L:L,Daten!E:E,"SELL",Daten!F:F,"FUND") -> 14446.26 | C31: =IF(ABS(B30)>0,B31/B30,0) -> 0.86345363 | D31: =SUMIFS(Daten!K:K,Daten!F:F,"STOCK",Daten!E:E,"SELL")+SUMIFS(Daten!K:K,Daten!F:F,"FUND",Daten!E:E,"SELL")-SUMIFS(Daten!L:L,Daten!E:E,"SELL",Daten!F:F,"STOCK")-SUMIFS(Daten!L:L,Daten!E:E,"SELL",Daten!F:F,"FUND") -> 14446.26
A32: Brutto Verkauft STOCK | B32: =SUMIFS(Auswertung!H:H,Auswertung!B:B,"STOCK")-SUMIFS(Daten!L:L,Daten!E:E,"SELL",Daten!F:F,"STOCK") -> 10544.71 | C32: =IF(ABS(B30)>0,B32/B30,0) -> 0.6302578 | D32: =SUMIFS(Daten!K:K,Daten!F:F,"STOCK",Daten!E:E,"SELL")-SUMIFS(Daten!L:L,Daten!E:E,"SELL",Daten!F:F,"STOCK") -> 10544.71
A33: Brutto Verkauft FUND | B33: =SUMIFS(Auswertung!H:H,Auswertung!B:B,"FUND")-SUMIFS(Daten!L:L,Daten!E:E,"SELL",Daten!F:F,"FUND") -> 3901.55 | C33: =IF(ABS(B30)>0,B33/B30,0) -> 0.23319582 | D33: =SUMIFS(Daten!K:K,Daten!F:F,"FUND",Daten!E:E,"SELL")-SUMIFS(Daten!L:L,Daten!E:E,"SELL",Daten!F:F,"FUND") -> 3901.55
A34: Brutto Verkauft CRYPTO | B34: =SUMIFS(Auswertung!H:H,Auswertung!B:B,"CRYPTO")-SUMIFS(Daten!L:L,Daten!E:E,"SELL",Daten!F:F,"CRYPTO") -> 1416.04 | C34: =IF(ABS(B30)>0,B33/B30,0) -> 0.23319582 | D34: =SUMIFS(Daten!K:K,Daten!F:F,"CRYPTO",Daten!E:E,"SELL")-SUMIFS(Daten!L:L,Daten!E:E,"SELL",Daten!F:F,"CRYPTO") -> 1416.04
A36: Netto Verkauft | B36: =SUM(Auswertung!H:H) -> 16659.788 | D36: =SUMIFS(Daten!K:K,Daten!E:E,"SELL") -> 15791.3
A37: Netto Verkauft STOCK&FUND | B37: =SUMIFS(Auswertung!H:H,Auswertung!B:B,"STOCK")+SUMIFS(Auswertung!H:H,Auswertung!B:B,"FUND") -> 14379.26 | C37: =IF(ABS(B36)>0,B37/B36,0) -> 0.8631118 | D37: =SUMIFS(Daten!K:K,Daten!F:F,"STOCK",Daten!E:E,"SELL")+SUMIFS(Daten!K:K,Daten!F:F,"FUND",Daten!E:E,"SELL") -> 14379.26
A38: Netto Verkauft STOCK | B38: =SUMIFS(Auswertung!H:H,Auswertung!B:B,"STOCK") -> 10485.71 | C38: =IF(ABS(B36)>0,B38/B36,0) -> 0.62940235 | D38: =SUMIFS(Daten!K:K,Daten!F:F,"STOCK",Daten!E:E,"SELL") -> 10485.71
A39: Netto Verkauft FUND | B39: =SUMIFS(Auswertung!H:H,Auswertung!B:B,"FUND") -> 3893.55 | C39: =IF(ABS(B36)>0,B39/B36,0) -> 0.23370945 | D39: =SUMIFS(Daten!K:K,Daten!F:F,"FUND",Daten!E:E,"SELL") -> 3893.55
A40: Netto Verkauft CRYPTO | B40: =SUMIFS(Auswertung!H:H,Auswertung!B:B,"CRYPTO") -> 1412.04 | C40: =IF(ABS(B36)>0,B40/B36,0) -> 0.084757379 | D40: =SUMIFS(Daten!K:K,Daten!F:F,"CRYPTO",Daten!E:E,"SELL") -> 1412.04
A42: Gebühren | B42: =SUM(Auswertung!I:I) -> 298 | C42: =-SUM(Daten!L:L) -> 298
A43: Gebüren STOCK&FUND | B43: =SUMIFS(Auswertung!I:I,Auswertung!B:B,"STOCK")+SUMIFS(Auswertung!I:I,Auswertung!B:B,"FUND") -> 252 | C43: =-SUMIFS(Daten!L:L,Daten!F:F,"STOCK")-SUMIFS(Daten!L:L,Daten!F:F,"FUND") -> 252 | D43: =IF(ABS(C42)>0,C43/C42,0) -> 0.84563758
A44: Gebüren STOCK | B44: =SUMIFS(Auswertung!I:I,Auswertung!B:B,"STOCK") -> 192 | C44: =-SUMIFS(Daten!L:L,Daten!F:F,"STOCK") -> 192 | D44: =IF(ABS(C42)>0,C44/C42,0) -> 0.6442953
A45: Gebüren FUND | B45: =SUMIFS(Auswertung!I:I,Auswertung!B:B,"FUND") -> 60 | C45: =-SUMIFS(Daten!L:L,Daten!F:F,"FUND") -> 60 | D45: =IF(ABS(C42)>0,C45/C42,0) -> 0.20134228
A46: Gebühren CRYPTO | B46: =SUMIFS(Auswertung!I:I,Auswertung!B:B,"CRYPTO") -> 46 | C46: =-SUMIFS(Daten!L:L,Daten!F:F,"CRYPTO") -> 46 | D46: =IF(ABS(C42)>0,C46/C42,0) -> 0.15436242
A48: Gebühren Käufe | B48: =-SUMIFS(Daten!L:L,Daten!E:E,"BUY") -> 227
A49: Gebüren Käufe STOCK&FUND | B49: =-SUMIFS(Daten!L:L,Daten!E:E,"BUY",Daten!F:F,"STOCK")-SUMIFS(Daten!L:L,Daten!E:E,"BUY",Daten!F:F,"FUND") -> 185 | C49: =IF(ABS(B48)>0,B49/B48,0) -> 0.81497797
...

Sheet Pivot
A3: Assets | B3: Einkaufswert | C3: Aktueller Wert | E3: Aktueller Wert | G3: Aktueller Wert | J3: Einkaufswert | L3: Verkaufserlöse Gewinn/Verlust
A4: CRYPTO | B4: 1000.3808 | C4: 896.29628 | E4: 10305.706 | G4: 10305.706 | J4: 11672.452 | L4: 1619.5447
A5: FUND | B5: 6252.4706 | C5: 5994.519 | I5: G/V:
A6: STOCK | B6: 4419.6001 | C6: 3414.8904 | E6: =GETPIVOTDATA("Aktuelle Position €",$E$3) -> 10305.706 | G6: =GETPIVOTDATA("Aktuelle Position €",$G$3) -> 10305.706 | I6: =G6-J6 -> -1366.7459 | J6: =GETPIVOTDATA("Aktuell Investiert €",$J$3) -> 11672.452 | L6: =GETPIVOTDATA("Realisierte P&L Verkäufe €",$L$3) -> 1619.5447
A7: (Leer)
A8: Gesamtergebnis | B8: 11672.452 | C8: 10305.706
A13: Assets | B13: Aktueller Wert | E13: Assets | F13: Aktueller Wert
A14: CRYPTO | B14: 896.29628 | E14: CRYPTO | F14: 896.29628
A15: Algorand | B15: 17.028262 | E15: FUND | F15: 5994.519
A16: Cardano | B16: 152.08863 | E16: STOCK | F16: 3414.8904
A17: Chainlink | B17: 178.47977 | E17: (Leer)
A18: Dogecoin | B18: 102.80426 | E18: Gesamtergebnis | F18: 10305.706
A19: Polkadot | B19: 84.844857
A20: Polygon | B20: 20.02619
A21: Render | B21: 42.33
A22: XRP | B22: 298.69431
A23: FUND | B23: 5994.519
A24: Core MSCI EM IMI USD (Acc) | B24: 707.67879
A25: Core S&P 500 USD (Acc) | B25: 1001.1032
A26: Core Stoxx Europe 600 EUR (Acc) | B26: 727.9281
A27: Defense USD (Acc) | B27: 359.96695
A28: Drone USD (ACC) | B28: 461.82631
A29: MSCI Robotics & AI ESG Screened EUR (Acc) | B29: 625.68
A30: MSCI World Consumer Staples USD (Acc) | B30: 404.58332
... A45: Gesamtergebnis | B45: 10305.706

Sheet Portfolio
A8: Assets | B8: Bestand | C8: Kurswert | D8: Aktueller Wert
A9: CRYPTO
A10: Algorand | B10: 160.77443 | C10: 0.105914 | D10: 17.028262
A11: Cardano | B11: 714.06128 | C11: 0.212991 | D11: 152.08863
A12: Chainlink | B12: 15.560573 | C12: 11.47 | D12: 178.47977
A13: Dogecoin | B13: 1356.0241 | C13: 0.075813 | D13: 102.80426
A14: Polkadot | B14: 80.193627 | C14: 1.058 | D14: 84.844857
A15: Polygon | B15: 223.93146 | C15: 0.08943 | D15: 20.02619
A16: Render | B16: 24.9 | C16: 1.7 | D16: 42.33
A17: XRP | B17: 238.95545 | C17: 1.25 | D17: 298.69431
A18: CRYPTO Ergebnis | B18: 2814.401 | C18: 15.962148 | D18: 896.29628
A20: FUND
A21: Core MSCI EM IMI USD (Acc) | B21: 14.461017 | C21: 48.937 | D21: 707.67879
A22: Core S&P 500 USD (Acc) | B22: 1.335873 | C22: 749.4 | D22: 1001.1032
A23: Core Stoxx Europe 600 EUR (Acc) | B23: 2.337223 | C23: 311.45 | D23: 727.9281
A24: Defense USD (Acc) | B24: 7.182102 | C24: 50.12 | D24: 359.96695
A25: Drone USD (ACC) | B25: 102.7994 | C25: 4.4925 | D25: 461.82631
A26: MSCI Robotics & AI ESG Screened EUR (Acc) | B26: 4 | C26: 156.42 | D26: 625.68
A27: MSCI World Consumer Staples USD (Acc) | B27: 8.333333 | C27: 48.55 | D27: 404.58332
A28: MSCI World Health Care USD (Acc) | B28: 10.354191 | C28: 54.55 | D28: 564.82112
A29: New Energy EUR (Dist) | B29: 8.735965 | C29: 41.255 | D29: 360.40224
A30: Quantum Computing USD (Acc) | B30: 14.72863 | C30: 25.58 | D30: 376.75836
A31: Space Innovators USD (Acc) | B31: 5.908262 | C31: 68.34 | D31: 403.77063
A32: FUND Ergebnis | B32: 180.176 | C32: 1559.0945 | D32: 5994.519
A34: STOCK
A35: Bayer | B35: 0.581914 | C35: 42.966 | D35: 25.002517
A36: Deutsche Konsum REIT | B36: 30 | C36: 1.49 | D36: 44.7
A37: DroneShield | B37: 1026.2678 | C37: 1.0004 | D37: 1026.6783
A38: D-Wave Quantum | B38: 43.787957 | C38: 13.392 | D38: 586.40832
A39: Lufthansa | B39: 43.728729 | C39: 7.274 | D39: 318.08277
A40: Netflix | B40: 7.199924 | C40: 63.5398 | D40: 457.48173
A41: Nike (B) | B41: 7.768964 | C41: 31.135 | D41: 241.88669
A42: Uranium Energy | B42: 74.851702 | C42: 8.26 | D42: 618.27506
A43: Zinzino | B43: 8.503401 | C43: 11.3337 | D43: 96.374996
A44: STOCK Ergebnis | B44: 1242.6904 | C44: 180.3909 | D44: 3414.8904
A46: Gesamtergebnis | B46: 4237.2674 | C46: 1755.4475 | D46: 10305.706

Sheet Auswertung_2026

Sheet Auswertung_2025

Sheet Definitions
A1: KPI | B1: Bedeutung
A2: Portfolio-Wert | B2: Aktueller Gesamtwert aller Positionen
A3: Investiertes Kapital | B3: Summe aller Einzahlungen und Käufe
A4: Gewinn/Verlust (P&L) | B4: Wie viel Gewinn(Proft) oder Verlust(Lost) erzielt wurde
A5: Rendite (%) | B5: Gewinn oder Verlust im Verhältnis zum eingesetzten Kapital
A6: Anzahl Positionen | B6: Wie viele Wertpapiere/Kryptos im Portfolio sind
A7: Asset-Allokation | B7: Verteilung auf Aktien, ETFs, Krypto usw.
A8: Cash-Bestand | B8: Nicht investiertes Guthaben
A9: Gebühren | B9: Summe aller Handelskosten
A10: Realisierte Gewinne | B10: Gewinne aus bereits verkauften Positionen
A11: Nicht realisierte Gewinne | B11: Gewinne/Verluste aus aktuellen Positionen

Sheet Berechnungen
A1: Ermittlung des Zielkurses
A2: Einstandskurs: | B2: 96.11
A3: Bestand: | B3: 7.237006
A4: Zielgewinn: | B4: 50
A5: Zielkurs: | B5: =IF(ABS(B3)>0,(B2*B3+B4)/B3,0) -> 103.01893
A6: Zielbestand: | B6: =B4/B5 -> 0.48534767
A7: Zielrendite | B7: =IF(ABS(B3)>0,B4/(B3*B2),0) -> 0.071885698

Sheet Manuel Revenues
A1: Asset | B1: Klasse | C1: Symbol | D1: Realisierte P&L Verkäufe € | E1: Verkauft € | F1: Kaufgebüren | G1: Verkaufsgebühren | H1: Investiertes Kapital Verkäufe €
A2: Algorand | B2: CRYPTO | C2: ALGO | D2: =0 -> 0 | E2: =0 -> 0 | F2: =SUMIFS(Daten!L:L,Daten!H:H,C2,Daten!E:E,"BUY")*-1 -> 1 | G2: =SUMIFS(Daten!L:L,Daten!H:H,C2,Daten!E:E,"SELL")*-1 -> 0 | H2: =IF(E2>0,E2+F2-D2,0) -> 0
A3: Bayer | B3: STOCK | C3: DE000BAY0017 | D3: =-0.93+1.33+116.15+0.61 -> 117.16 | E3: =0.13+37.89+620.16 -> 658.18 | F3: =SUMIFS(Daten!L:L,Daten!H:H,C3,Daten!E:E,"BUY")*-1 -> 5 | G3: =SUMIFS(Daten!L:L,Daten!H:H,C3,Daten!E:E,"SELL")*-1 -> 3 | H3: =IF(E3>0,E3+F3-D3,0) -> 546.02
A4: BP | B4: STOCK | C4: GB0007980591 | D4: =12.45+6.43+8.97+3.4 -> 31.25 | E4: =163.46+308.44+209.97 -> 681.87 | F4: =SUMIFS(Daten!L:L,Daten!H:H,C4,Daten!E:E,"BUY")*-1 -> 4 | G4: =SUMIFS(Daten!L:L,Daten!H:H,C4,Daten!E:E,"SELL")*-1 -> 3 | H4: =IF(E4>0,E4+F4-D4,0) -> 654.62
A5: BTQ Technologies | B5: STOCK | C5: CA0558691014 | D5: =88.04 -> 88.04 | E5: =726.03 -> 726.03 | F5: =SUMIFS(Daten!L:L,Daten!H:H,C5,Daten!E:E,"BUY")*-1 -> 12 | G5: =SUMIFS(Daten!L:L,Daten!H:H,C5,Daten!E:E,"SELL")*-1 -> 1 | H5: =IF(E5>0,E5+F5-D5,0) -> 649.99
A6: BYD | B6: STOCK | C6: CNE100000296 | D6: =10.15-16.69 -> -6.54 | E6: =144.2+96.26 -> 240.46 | F6: =SUMIFS(Daten!L:L,Daten!H:H,C6,Daten!E:E,"BUY")*-1 -> 3 | G6: =SUMIFS(Daten!L:L,Daten!H:H,C6,Daten!E:E,"SELL")*-1 -> 2 | H6: =IF(E6>0,E6+F6-D6,0) -> 250
A7: Cardano | B7: CRYPTO | C7: ADA | D7: =0 -> 0 | E7: =0 -> 0 | F7: =SUMIFS(Daten!L:L,Daten!H:H,C7,Daten!E:E,"BUY")*-1 -> 5 | G7: =SUMIFS(Daten!L:L,Daten!H:H,C7,Daten!E:E,"SELL")*-1 -> 0 | H7: =IF(E7>0,E7+F7-D7,0) -> 0
A8: Centrotherm Photovoltaics | B8: STOCK | C8: DE000A1TNMM9 | D8: =0.87+49.75 -> 50.62 | E8: =7.82+242.8 -> 250.62 | F8: =SUMIFS(Daten!L:L,Daten!H:H,C8,Daten!E:E,"BUY")*-1 -> 1 | G8: =SUMIFS(Daten!L:L,Daten!H:H,C8,Daten!E:E,"SELL")*-1 -> 2 | H8: =IF(E8>0,E8+F8-D8,0) -> 201
A9: Chainlink | B9: CRYPTO | C9: LINK | D9: =15.53 -> 15.53 | E9: =262.53 -> 262.53 | F9: =SUMIFS(Daten!L:L,Daten!H:H,C9,Daten!E:E,"BUY")*-1 -> 7 | G9: =SUMIFS(Daten!L:L,Daten!H:H,C9,Daten!E:E,"SELL")*-1 -> 1 | H9: =IF(E9>0,E9+F9-D9,0) -> 254
A10: Core MSCI EM IMI USD (Acc) | B10: FUND | C10: IE00BKM4GZ66 | D10: =0 -> 0 | E10: =0 -> 0 | F10: =SUMIFS(Daten!L:L,Daten!H:H,C10,Daten!E:E,"BUY")*-1 -> 1 | G10: =SUMIFS(Daten!L:L,Daten!H:H,C10,Daten!E:E,"SELL")*-1 -> 0 | H10: =IF(E10>0,E10+F10-D10,0) -> 0
A11: Core MSCI World USD (Acc) | B11: FUND | C11: IE00B4L5Y983 | D11: =62.54+22.12 -> 84.66 | E11: =894.04+267.36 -> 1161.4 | F11: =SUMIFS(Daten!L:L,Daten!H:H,C11,Daten!E:E,"BUY")*-1 -> 7 | G11: =SUMIFS(Daten!L:L,Daten!H:H,C11,Daten!E:E,"SELL")*-1 -> 2 | H11: =IF(E11>0,E11+F11-D11,0) -> 1083.74
A12: Core S&P 500 USD (Acc) | B12: FUND | C12: IE00B5BMR087 | D12: =49.93+80.78 -> 130.71 | E12: =380.84+738 -> 1118.84 | F12: =SUMIFS(Daten!L:L,Daten!H:H,C12,Daten!E:E,"BUY")*-1 -> 8 | G12: =SUMIFS(Daten!L:L,Daten!H:H,C12,Daten!E:E,"SELL")*-1 -> 2 | H12: =IF(E12>0,E12+F12-D12,0) -> 996.13
A13: Core Stoxx Europe 600 EUR (Acc) | B13: FUND | C13: LU0908500753 | D13: =0 -> 0 | E13: =0 -> 0 | F13: =SUMIFS(Daten!L:L,Daten!H:H,C13,Daten!E:E,"BUY")*-1 -> 3 | G13: =SUMIFS(Daten!L:L,Daten!H:H,C13,Daten!E:E,"SELL")*-1 -> 0 | H13: =IF(E13>0,E13+F13-D13,0) -> 0
A14: DAX EUR (Acc) | B14: FUND | C14: LU0274211480 | D14: =2.53 -> 2.53 | E14: =505.61 -> 505.61 | F14: =SUMIFS(Daten!L:L,Daten!H:H,C14,Daten!E:E,"BUY")*-1 -> 2 | G14: =SUMIFS(Daten!L:L,Daten!H:H,C14,Daten!E:E,"SELL")*-1 -> 1 | H14: =IF(E14>0,E14+F14-D14,0) -> 505.08
A15: Defense USD (Acc) | B15: FUND | C15: IE000YYE6WK5 | D15: =0 -> 0 | E15: =0 -> 0 | F15: =SUMIFS(Daten!L:L,Daten!H:H,C15,Daten!E:E,"BUY")*-1 -> 3 | G15: =SUMIFS(Daten!L:L,Daten!H:H,C15,Daten!E:E,"SELL")*-1 -> 0 | H15: =IF(E15>0,E15+F15-D15,0) -> 0
A16: Deutsche Konsum REIT | B16: STOCK | C16: DE000A14KRD3 | D16: =0 -> 0 | E16: =0 -> 0 | F16: =SUMIFS(Daten!L:L,Daten!H:H,C16,Daten!E:E,"BUY")*-1 -> 1 | G16: =SUMIFS(Daten!L:L,Daten!H:H,C16,Daten!E:E,"SELL")*-1 -> 0 | H16: =IF(E16>0,E16+F16-D16,0) -> 0
A17: Dogecoin | B17: CRYPTO | C17: DOGE | D17: =0 -> 0 | E17: =0 -> 0 | F17: =SUMIFS(Daten!L:L,Daten!H:H,C17,Daten!E:E,"BUY")*-1 -> 1 | G17: =SUMIFS(Daten!L:L,Daten!H:H,C17,Daten!E:E,"SELL")*-1 -> 0 | H17: =IF(E17>0,E17+F17-D17,0) -> 0
A18: Draganfly | B18: STOCK | C18: CA26142Q3044 | D18: =41.97 -> 41.97 | E18: =121.97 -> 121.97 | F18: =SUMIFS(Daten!L:L,Daten!H:H,C18,Daten!E:E,"BUY")*-1 -> 1 | G18: =SUMIFS(Daten!L:L,Daten!H:H,C18,Daten!E:E,"SELL")*-1 -> 1 | H18: =IF(E18>0,E18+F18-D18,0) -> 81
A19: Drone USD (ACC) | B19: FUND | C19: IE0003XW12I8 | D19: =0 -> 0 | E19: =0 -> 0 | F19: =SUMIFS(Daten!L:L,Daten!H:H,C19,Daten!E:E,"BUY")*-1 -> 8 | G19: =SUMIFS(Daten!L:L,Daten!H:H,C19,Daten!E:E,"SELL")*-1 -> 0 | H19: =IF(E19>0,E19+F19-D19,0) -> 0
A20: DroneShield | B20: STOCK | C20: AU000000DRO2 | D20: =89.5+62.46+58.92+10.2+10.33-1.96+16.47 -> 245.92 | E20: =422.71+122.46+118.92+280.03+372.38+370.52 -> 1687.02 | F20: =SUMIFS(Daten!L:L,Daten!H:H,C20,Daten!E:E,"BUY")*-1 -> 29 | G20: =SUMIFS(Daten!L:L,Daten!H:H,C20,Daten!E:E,"SELL")*-1 -> 6 | H20: =IF(E20>0,E20+F20-D20,0) -> 1470.1
A21: D-Wave Quantum | B21: STOCK | C21: US26740W1099 | D21: =59.06-1+9.66+18.75+43.67+99.76-1.13 -> 228.77 | E21: =193.45+9.77+247.61+365.72+394.67+519.76+365 -> 2095.98 | F21: =SUMIFS(Daten!L:L,Daten!H:H,C21,Daten!E:E,"BUY")*-1 -> 21 | G21: =SUMIFS(Daten!L:L,Daten!H:H,C21,Daten!E:E,"SELL")*-1 -> 7 | H21: =IF(E21>0,E21+F21-D21,0) -> 1888.21
A22: Eco Oil & Gas | B22: STOCK | C22: CA27887W1005 | D22: =14.55+3.16 -> 17.71 | E22: =165.55+204.17 -> 369.72 | F22: =SUMIFS(Daten!L:L,Daten!H:H,C22,Daten!E:E,"BUY")*-1 -> 3 | G22: =SUMIFS(Daten!L:L,Daten!H:H,C22,Daten!E:E,"SELL")*-1 -> 2 | H22: =IF(E22>0,E22+F22-D22,0) -> 355.01
A23: Evotec | B23: STOCK | C23: DE0005664809 | D23: =18.15 -> 18.15 | E23: =118.15 -> 118.15 | F23: =SUMIFS(Daten!L:L,Daten!H:H,C23,Daten!E:E,"BUY")*-1 -> 1 | G23: =SUMIFS(Daten!L:L,Daten!H:H,C23,Daten!E:E,"SELL")*-1 -> 1 | H23: =IF(E23>0,E23+F23-D23,0) -> 101
A24: Hensoldt | B24: STOCK | C24: DE000HAG0005 | D24: =3.82+4.88 -> 8.7 | E24: =49.31+50.1 -> 99.41 | F24: =SUMIFS(Daten!L:L,Daten!H:H,C24,Daten!E:E,"BUY")*-1 -> 1 | G24: =SUMIFS(Daten!L:L,Daten!H:H,C24,Daten!E:E,"SELL")*-1 -> 2 | H24: =IF(E24>0,E24+F24-D24,0) -> 91.71
A25: Infineon Technologies | B25: STOCK | C25: DE0006231004 | D25: =2.16 -> 2.16 | E25: =62.58 -> 62.58 | F25: =SUMIFS(Daten!L:L,Daten!H:H,C25,Daten!E:E,"BUY")*-1 -> 1 | G25: =SUMIFS(Daten!L:L,Daten!H:H,C25,Daten!E:E,"SELL")*-1 -> 1 | H25: =IF(E25>0,E25+F25-D25,0) -> 61.42
A26: Lufthansa | B26: STOCK | C26: DE0008232125 | D26: =8.27 -> 8.27 | E26: =209.27 -> 209.27 | F26: =SUMIFS(Daten!L:L,Daten!H:H,C26,Daten!E:E,"BUY")*-1 -> 5 | G26: =SUMIFS(Daten!L:L,Daten!H:H,C26,Daten!E:E,"SELL")*-1 -> 1 | H26: =IF(E26>0,E26+F26-D26,0) -> 206
A27: Metaplanet | B27: STOCK | C27: JP3481200008 | D27: =15.35 -> 15.35 | E27: =115.35 -> 115.35 | F27: =SUMIFS(Daten!L:L,Daten!H:H,C27,Daten!E:E,"BUY")*-1 -> 1 | G27: =SUMIFS(Daten!L:L,Daten!H:H,C27,Daten!E:E,"SELL")*-1 -> 1 | H27: =IF(E27>0,E27+F27-D27,0) -> 101
A28: MSCI Robotics & AI ESG Screened EUR (Acc) | B28: FUND | C28: LU1861132840 | D28: =45.81 -> 45.81 | E28: =303.35 -> 303.35 | F28: =SUMIFS(Daten!L:L,Daten!H:H,C28,Daten!E:E,"BUY")*-1 -> 3 | G28: =SUMIFS(Daten!L:L,Daten!H:H,C28,Daten!E:E,"SELL")*-1 -> 1 | H28: =IF(E28>0,E28+F28-D28,0) -> 260.54
A29: MSCI World Consumer Staples USD (Acc) | B29: FUND | C29: IE00BM67HN09 | D29: =0 -> 0 | E29: =0 -> 0 | F29: =SUMIFS(Daten!L:L,Daten!H:H,C29,Daten!E:E,"BUY")*-1 -> 1 | G29: =SUMIFS(Daten!L:L,Daten!H:H,C29,Daten!E:E,"SELL")*-1 -> 0 | H29: =IF(E29>0,E29+F29-D29,0) -> 0
A30: MSCI World Health Care USD (Acc) | B30: FUND | C30: IE00BM67HK77 | D30: =0 -> 0 | E30: =0 -> 0 | F30: =SUMIFS(Daten!L:L,Daten!H:H,C30,Daten!E:E,"BUY")*-1 -> 1 | G30: =SUMIFS(Daten!L:L,Daten!H:H,C30,Daten!E:E,"SELL")*-1 -> 0 | H30: =IF(E30>0,E30+F30-D30,0) -> 0
A31: Netflix | B31: STOCK | C31: US64110L1061 | D31: =0 -> 0 | E31: =0 -> 0 | F31: =SUMIFS(Daten!L:L,Daten!H:H,C31,Daten!E:E,"BUY")*-1 -> 6 | G31: =SUMIFS(Daten!L:L,Daten!H:H,C31,Daten!E:E,"SELL")*-1 -> 0 | H31: =IF(E31>0,E31+F31-D31,0) -> 0
A32: New Energy EUR (Dist) | B32: FUND | C32: FR0010524777 | D32: =0 -> 0 | E32: =0 -> 0 | F32: =SUMIFS(Daten!L:L,Daten!H:H,C32,Daten!E:E,"BUY")*-1 -> 3 | G32: =SUMIFS(Daten!L:L,Daten!H:H,C32,Daten!E:E,"SELL")*-1 -> 0 | H32: =IF(E32>0,E32+F32-D32,0) -> 0
A33: Nike (B) | B33: STOCK | C33: US6541061031 | D33: =1.77 -> 1.77 | E33: =0 -> 0 | F33: =SUMIFS(Daten!L:L,Daten!H:H,C33,Daten!E:E,"BUY")*-1 -> 3 | G33: =SUMIFS(Daten!L:L,Daten!H:H,C33,Daten!E:E,"SELL")*-1 -> 0 | H33: =IF(E33>0,E33+F33-D33,0) -> 0
A34: NVIDIA | B34: STOCK | C34: US67066G1040 | D34: =-0.89+6.08+0.01 -> 5.2 | E34: =3+198.59 -> 201.59 | F34: =SUMIFS(Daten!L:L,Daten!H:H,C34,Daten!E:E,"BUY")*-1 -> 2 | G34: =SUMIFS(Daten!L:L,Daten!H:H,C34,Daten!E:E,"SELL")*-1 -> 2 | H34: =IF(E34>0,E34+F34-D34,0) -> 198.39
A35: Palantir Technologies | B35: STOCK | C35: US69608A1088 | D35: =10.5 -> 10.5 | E35: =157.74 -> 157.74 | F35: =SUMIFS(Daten!L:L,Daten!H:H,C35,Daten!E:E,"BUY")*-1 -> 1 | G35: =SUMIFS(Daten!L:L,Daten!H:H,C35,Daten!E:E,"SELL")*-1 -> 1 | H35: =IF(E35>0,E35+F35-D35,0) -> 148.24
A36: Patterson-UTI Energy | B36: STOCK | C36: US7034811015 | D36: =10.33+17.77 -> 28.1 | E36: =312.34+318.77 -> 631.11 | F36: =SUMIFS(Daten!L:L,Daten!H:H,C36,Daten!E:E,"BUY")*-1 -> 3 | G36: =SUMIFS(Daten!L:L,Daten!H:H,C36,Daten!E:E,"SELL")*-1 -> 2 | H36: =IF(E36>0,E36+F36-D36,0) -> 606.01
A37: Pfizer | B37: STOCK | C37: US7170811035 | D37: =0.27 -> 0.27 | E37: =201.27 -> 201.27 | F37: =SUMIFS(Daten!L:L,Daten!H:H,C37,Daten!E:E,"BUY")*-1 -> 1 | G37: =SUMIFS(Daten!L:L,Daten!H:H,C37,Daten!E:E,"SELL")*-1 -> 1 | H37: =IF(E37>0,E37+F37-D37,0) -> 202
A38: Plug Power | B38: STOCK | C38: US72919P2020 | D38: =6.45 -> 6.45 | E38: =278.44 -> 278.44 | F38: =SUMIFS(Daten!L:L,Daten!H:H,C38,Daten!E:E,"BUY")*-1 -> 4 | G38: =SUMIFS(Daten!L:L,Daten!H:H,C38,Daten!E:E,"SELL")*-1 -> 1 | H38: =IF(E38>0,E38+F38-D38,0) -> 275.99
A39: Polkadot | B39: CRYPTO | C39: DOT | D39: =0 -> 0 | E39: =0 -> 0 | F39: =SUMIFS(Daten!L:L,Daten!H:H,C39,Daten!E:E,"BUY")*-1 -> 5 | G39: =SUMIFS(Daten!L:L,Daten!H:H,C39,Daten!E:E,"SELL")*-1 -> 0 | H39: =IF(E39>0,E39+F39-D39,0) -> 0
A40: Polygon | B40: CRYPTO | C40: MATIC | D40: =0 -> 0 | E40: =0 -> 0 | F40: =SUMIFS(Daten!L:L,Daten!H:H,C40,Daten!E:E,"BUY")*-1 -> 1 | G40: =SUMIFS(Daten!L:L,Daten!H:H,C40,Daten!E:E,"SELL")*-1 -> 0 | H40: =IF(E40>0,E40+F40-D40,0) -> 0
...
