Workbook

Sheet Daten
A1: datetime | B1: date | C1: account_type | D1: category | E1: type | F1: asset_class | G1: name | H1: symbol | I1: shares | J1: price | K1: amount | L1: fee | M1: tax | N1: currency | O1: original_amount | P1: original_currency | Q1: fx_rate | R1: description | S1: transaction_id | T1: counterparty_name | U1: counterparty_iban | V1: payment_reference | W1: mcc_code
A2: 2025-07-27T13:19:37.461665Z | B2: 45865 | C2: DEFAULT | D2: CASH | E2: TRANSFER_INSTANT_INBOUND | K2: 1 | N2: EUR | R2: Incoming transfer from ROMEO TALLA FOTSING | S2: 424eaa0e-2c58-4651-aa44-7b5a953a5a64
A3: 2025-07-29T13:26:57.019251Z | B3: 45867 | C3: DEFAULT | D3: CASH | E3: TRANSFER_INSTANT_INBOUND | K3: 39 | N3: EUR | R3: Incoming transfer from ROMEO TALLA FOTSING | S3: e95f0d7f-e43e-4fd6-b6ab-5dc0b1a435ce
A4: 2025-09-08T10:19:08.327Z | B4: 45908 | C4: DEFAULT | D4: TRADING | E4: BUY | F4: STOCK | G4: Hensoldt | H4: DE000HAG0005 | I4: 0.009325 | J4: 91.15 | K4: -0.85 | N4: EUR | R4: Buy trade DE000HAG0005 HENSOLDT AG INH O.N., quantity: 0.009325 | S4: 0727b23c-23a7-4222-a59d-0c9bc60ef4f3
A5: 2025-09-08T10:19:08.327Z | B5: 45908 | C5: DEFAULT | D5: TRADING | E5: BUY | F5: STOCK | G5: Hensoldt | H5: DE000HAG0005 | I5: 1 | J5: 91.15 | K5: -91.15 | L5: -1 | N5: EUR | R5: Buy trade DE000HAG0005 HENSOLDT AG INH O.N., quantity: 1 | S5: a629c8cf-59e5-427d-9d60-e150262d0229
A6: 2025-09-08T10:25:32.083692Z | B6: 45908 | C6: DEFAULT | D6: CASH | E6: TRANSFER_INSTANT_INBOUND | K6: 100 | N6: EUR | R6: Incoming transfer from ROMEO TALLA FOTSING | S6: 53ff5df6-b9e9-4706-9b7e-909c42bd2b4b
A7: 2025-09-08T10:26:00.586Z | B7: 45908 | C7: DEFAULT | D7: TRADING | E7: BUY | F7: STOCK | G7: NVIDIA | H7: US67066G1040 | I7: 0.004184 | J7: 143.4 | K7: -0.6 | N7: EUR | R7: Buy trade US67066G1040 NVIDIA CORP. DL-,001, quantity: 0.004184 | S7: 1cf6e467-defb-4230-8695-cfdce5f7c8b1
A8: 2025-09-08T10:26:00.587Z | B8: 45908 | C8: DEFAULT | D8: TRADING | E8: BUY | F8: STOCK | G8: NVIDIA | H8: US67066G1040 | I8: 1 | J8: 143.4 | K8: -143.4 | L8: -1 | N8: EUR | R8: Buy trade US67066G1040 NVIDIA CORP. DL-,001, quantity: 1 | S8: 9758550e-bb56-4291-9669-769e8743d26a
A9: 2025-09-08T15:13:05.407427Z | B9: 45908 | C9: DEFAULT | D9: CASH | E9: TRANSFER_INSTANT_INBOUND | K9: 100 | N9: EUR | R9: Incoming transfer from ROMEO TALLA FOTSING | S9: 0d9897c9-c8fd-4778-968d-1a938e62e15e
A10: 2025-09-08T15:13:28.999Z | B10: 45908 | C10: DEFAULT | D10: TRADING | E10: BUY | F10: STOCK | G10: Siemens Energy | H10: DE000ENER6Y0 | I10: 1 | J10: 88.46 | K10: -88.46 | L10: -1 | N10: EUR | R10: Buy trade DE000ENER6Y0 SIEMENS ENERGY AG NA O.N., quantity: 1 | S10: c7a53c80-2e60-48ab-9f12-9783bb111234
A11: 2025-09-08T15:13:29.017Z | B11: 45908 | C11: DEFAULT | D11: TRADING | E11: BUY | F11: STOCK | G11: Siemens Energy | H11: DE000ENER6Y0 | I11: 0.017408 | J11: 88.46 | K11: -1.54 | N11: EUR | R11: Buy trade DE000ENER6Y0 SIEMENS ENERGY AG NA O.N., quantity: 0.017408 | S11: 747eaf82-a1bb-436c-be67-e001ace15c63
A12: 2025-09-08T15:21:27.168762Z | B12: 45908 | C12: DEFAULT | D12: CASH | E12: TRANSFER_INSTANT_INBOUND | K12: 50 | N12: EUR | R12: Incoming transfer from ROMEO TALLA FOTSING | S12: 982366f6-521f-44fe-bd80-efb1401d2fee
A13: 2025-09-08T10:18:44.030553Z | B13: 45908 | C13: DEFAULT | D13: CASH | E13: TRANSFER_INSTANT_INBOUND | K13: 100 | N13: EUR | R13: Incoming transfer from ROMEO TALLA FOTSING | S13: af3b470a-85d9-43a5-a66f-f48c9956c0b5
A14: 2025-09-08T15:23:18.402Z | B14: 45908 | C14: DEFAULT | D14: TRADING | E14: BUY | F14: STOCK | G14: Infineon Technologies | H14: DE0006231004 | I14: 0.871199 | J14: 32.065 | K14: -27.93 | N14: EUR | R14: Buy trade DE0006231004 INFINEON TECH.AG NA O.N., quantity: 0.871199 | S14: 23d47dc4-4c9a-40f5-bef3-2d480cd8e83c
A15: 2025-09-08T15:23:18.424Z | B15: 45908 | C15: DEFAULT | D15: TRADING | E15: BUY | F15: STOCK | G15: Infineon Technologies | H15: DE0006231004 | I15: 1 | J15: 32.065 | K15: -32.07 | L15: -1 | N15: EUR | R15: Buy trade DE0006231004 INFINEON TECH.AG NA O.N., quantity: 1 | S15: 433c455d-7391-4e56-999a-61950885dbc2
A16: 2025-09-09T18:49:58.647684Z | B16: 45909 | C16: DEFAULT | D16: CASH | E16: TRANSFER_INSTANT_INBOUND | K16: 185 | N16: EUR | R16: Incoming transfer from ROMEO TALLA FOTSING | S16: e582d7a8-1263-40e7-9c23-1bc6a34c6822
A17: 2025-09-09T19:02:28.675360Z | B17: 45909 | C17: DEFAULT | D17: CASH | E17: TRANSFER_INSTANT_INBOUND | K17: 50 | N17: EUR | R17: Incoming transfer from ROMEO TALLA FOTSING | S17: e25dd191-37d8-403a-9c16-c0e3cbb411d0
A18: 2025-09-09T18:52:07.229629Z | B18: 45909 | C18: DEFAULT | D18: CASH | E18: TRANSFER_INSTANT_INBOUND | K18: 1 | N18: EUR | R18: Incoming transfer from ROMEO TALLA FOTSING | S18: 9cf1e7fa-4740-4383-a0c1-7766064d658d
A19: 2025-09-09T19:04:22.991Z | B19: 45909 | C19: DEFAULT | D19: TRADING | E19: BUY | F19: CRYPTO | G19: Solana | H19: SOL | I19: 1.004294 | J19: 187.214 | K19: -188.02 | L19: -1 | N19: EUR | R19: Buy trade XF000SOL0012 Solana, quantity: 1.004294 | S19: afbcad62-3fc9-4099-9e9b-8900285f53e8
A20: 2025-09-09T19:08:33.772Z | B20: 45909 | C20: DEFAULT | D20: TRADING | E20: BUY | F20: CRYPTO | G20: XRP | H20: XRP | I20: 4.324764 | J20: 2.543402 | K20: -11 | L20: -1 | N20: EUR | R20: Buy trade XF000XRP0018 XRP, quantity: 4.324764 | S20: 230d489b-9016-478a-8352-d0c5a4b91285
A21: 2025-09-09T19:13:30.463Z | B21: 45909 | C21: DEFAULT | D21: TRADING | E21: BUY | F21: CRYPTO | G21: Cardano | H21: ADA | I21: 13.490816 | J21: 0.741244 | K21: -10 | L21: -1 | N21: EUR | R21: Buy trade XF000ADA0018 Cardano, quantity: 13.490816 | S21: b14b2296-7649-45b6-96d4-0adb5bf4ccd1
A22: 2025-09-09T19:23:39.540Z | B22: 45909 | C22: DEFAULT | D22: TRADING | E22: BUY | F22: STOCK | G22: ThyssenKrupp | H22: DE0007500001 | I22: 2 | J22: 10.055 | K22: -20.11 | L22: -1 | N22: EUR | R22: Buy trade DE0007500001 THYSSENKRUPP AG O.N., quantity: 2 | S22: da29a441-a07c-49b7-9b99-80a529e4e573
A23: 2025-09-09T19:23:39.557Z | B23: 45909 | C23: DEFAULT | D23: TRADING | E23: BUY | F23: STOCK | G23: ThyssenKrupp | H23: DE0007500001 | I23: 0.186878 | J23: 10.055 | K23: -1.88 | N23: EUR | R23: Buy trade DE0007500001 THYSSENKRUPP AG O.N., quantity: 0.186878 | S23: 969d0b29-b80f-44a2-9ae6-5cd0d9357879
A24: 2025-09-10T06:30:13.603Z | B24: 45910 | C24: DEFAULT | D24: TRADING | E24: SELL | F24: STOCK | G24: NVIDIA | H24: US67066G1040 | I24: -0.026957 | J24: 148.38 | K24: 4 | L24: -1 | N24: EUR | R24: Sell trade US67066G1040 NVIDIA CORP. DL-,001, quantity: 0.026957 | S24: 70655a16-2cfd-4223-b0c9-8f308f9dd5d2
A25: 2025-09-10T06:34:03.974Z | B25: 45910 | C25: DEFAULT | D25: TRADING | E25: BUY | F25: STOCK | G25: NVIDIA | H25: US67066G1040 | I25: 0.350215 | J25: 148.48 | K25: -52 | L25: -1 | N25: EUR | R25: Buy trade US67066G1040 NVIDIA CORP. DL-,001, quantity: 0.350215 | S25: 9b0d29d2-6ed3-47ac-99ce-e87af3ec296e
A26: 2025-09-10T18:16:25.056243Z | B26: 45910 | C26: DEFAULT | D26: CASH | E26: TRANSFER_INSTANT_INBOUND | K26: 80 | N26: EUR | R26: Incoming transfer from ROMEO TALLA FOTSING | S26: de466bec-4087-4c0a-8202-9aaf20516527
A27: 2025-09-10T06:33:41.519298Z | B27: 45910 | C27: DEFAULT | D27: CASH | E27: TRANSFER_INSTANT_INBOUND | K27: 50 | N27: EUR | R27: Incoming transfer from ROMEO TALLA FOTSING | S27: 4c71c45a-503c-4c74-96ce-9f37f9f8b41a
A28: 2025-09-10T18:17:19.530Z | B28: 45910 | C28: DEFAULT | D28: TRADING | E28: BUY | F28: STOCK | G28: RENK Group | H28: DE000RENK730 | I28: 1 | J28: 69.61 | K28: -69.61 | L28: -1 | N28: EUR | R28: Buy trade DE000RENK730 RENK GROUP AG INH O.N., quantity: 1 | S28: b604100c-0247-458c-829f-5bd7424f8603
A29: 2025-09-10T18:17:19.540Z | B29: 45910 | C29: DEFAULT | D29: TRADING | E29: BUY | F29: STOCK | G29: RENK Group | H29: DE000RENK730 | I29: 0.134894 | J29: 69.61 | K29: -9.39 | N29: EUR | R29: Buy trade DE000RENK730 RENK GROUP AG INH O.N., quantity: 0.134894 | S29: 728d465d-af9d-4e7c-8d16-17bcdeade476
A30: 2025-09-11T15:38:20.212Z | B30: 45911 | C30: DEFAULT | D30: TRADING | E30: BUY | F30: STOCK | G30: Palantir Technologies | H30: US69608A1088 | I30: 0.052408 | J30: 141.58 | K30: -7.42 | N30: EUR | R30: Buy trade US69608A1088 PALANTIR TECHNOLOGIES INC, quantity: 0.052408 | S30: 33934593-6ada-44ba-a54e-3b261f040217
A31: 2025-09-11T15:38:20.242Z | B31: 45911 | C31: DEFAULT | D31: TRADING | E31: BUY | F31: STOCK | G31: Palantir Technologies | H31: US69608A1088 | I31: 1 | J31: 141.58 | K31: -141.58 | L31: -1 | N31: EUR | R31: Buy trade US69608A1088 PALANTIR TECHNOLOGIES INC, quantity: 1 | S31: 8ef7b29c-5d9e-4ffb-bfb7-9db3512a4693
A32: 2025-09-11T15:41:23.138Z | B32: 45911 | C32: DEFAULT | D32: TRADING | E32: BUY | F32: STOCK | G32: RWE | H32: DE0007037129 | I32: 1 | J32: 35.81 | K32: -35.81 | L32: -1 | N32: EUR | R32: Buy trade DE0007037129 RWE AG ST O.N., quantity: 1 | S32: c7dc6691-719e-4fc2-ab45-33cbda29778b
A33: 2025-09-11T15:41:23.139Z | B33: 45911 | C33: DEFAULT | D33: TRADING | E33: BUY | F33: STOCK | G33: RWE | H33: DE0007037129 | I33: 0.368332 | J33: 35.81 | K33: -13.19 | N33: EUR | R33: Buy trade DE0007037129 RWE AG ST O.N., quantity: 0.368332 | S33: 06d1bbf5-d51f-43e8-b726-11fcb04b32f9
A34: 2025-09-11T21:33:32.074Z | B34: 45911 | C34: DEFAULT | D34: TRADING | E34: BUY | F34: CRYPTO | G34: Chainlink | H34: LINK | I34: 2.367195 | J34: 20.6995 | K34: -49 | L34: -1 | N34: EUR | R34: Buy trade XF000LINK010 Chainlink, quantity: 2.367195 | S34: c99405ed-4454-4ee5-aa95-c21cee2c3fe4
A35: 2025-09-11T21:46:42.733325Z | B35: 45911 | C35: DEFAULT | D35: CASH | E35: TRANSFER_INSTANT_INBOUND | K35: 30 | N35: EUR | R35: Incoming transfer from ROMEO TALLA FOTSING | S35: 61d73e9b-080e-4b38-8e9c-cfa53831534d
A36: 2025-09-11T21:32:18.901194Z | B36: 45911 | C36: DEFAULT | D36: CASH | E36: TRANSFER_INSTANT_INBOUND | K36: 49.01 | N36: EUR | R36: Incoming transfer from ROMEO TALLA FOTSING | S36: 831bbaff-b1d8-4fce-ba2e-95946db4c5c9
A37: 2025-09-11T15:36:27.161817Z | B37: 45911 | C37: DEFAULT | D37: CASH | E37: TRANSFER_INSTANT_INBOUND | K37: 200 | N37: EUR | R37: Incoming transfer from ROMEO TALLA FOTSING | S37: c3f80c0e-b161-4698-a026-5e62bb5941db
A38: 2025-09-11T21:48:23.004Z | B38: 45911 | C38: DEFAULT | D38: TRADING | E38: BUY | F38: CRYPTO | G38: Render | H38: XF0RENDER015 | I38: 3.17 | J38: 3.46387 | K38: -10.98 | L38: -1 | N38: EUR | R38: Buy trade XF0RENDER015 Render Token, quantity: 3.17 | S38: 46bdf702-e375-4a1f-85a5-70d506e3a587
A39: 2025-09-11T21:48:44.149Z | B39: 45911 | C39: DEFAULT | D39: TRADING | E39: BUY | F39: CRYPTO | G39: Polkadot | H39: DOT | I39: 4.691738 | J39: 3.62339 | K39: -17 | L39: -1 | N39: EUR | R39: Buy trade XF000DOT0011 Polkadot, quantity: 4.691738 | S39: c890608d-0d09-41fc-9e89-ee26200b50dc
A40: 2025-09-16T15:08:11.260561Z | B40: 45916 | C40: DEFAULT | D40: CASH | E40: TRANSFER_INSTANT_INBOUND | K40: 81 | N40: EUR | R40: Incoming transfer from ROMEO TALLA FOTSING | S40: 61a8a189-a7cf-4d84-9a65-f99f55ab70b0
...

Sheet 2025
A1: Einnahmen Gesamt 2025: | B1: =SUMIFS(Daten!K:K,Daten!E:E,"TRANSFER_INSTANT_INBOUND",Daten!B:B,">="&DATE(2025,1,1),Daten!B:B,"<="&DATE(2025,12,31)) + SUMIFS(Daten!K:K,Daten!E:E,"TRANSFER_IN",Daten!B:B,">="&DATE(2025,1,1),Daten!B:B,"<="&DATE(2025,12,31)) + SUMIFS(Daten!K:K,Daten!E:E,"GIFT",Daten!B:B,">="&DATE(2025,1,1),Daten!B:B,"<="&DATE(2025,12,31)) + SUMIFS(Daten!K:K,Daten!E:E,"DIVIDEND",Daten!B:B,">="&DATE(2025,1,1),Daten!B:B,"<="&DATE(2025,12,31)) + SUMIFS(Daten!K:K,Daten!E:E,"CUSTOMER_INPAYMENT",Daten!B:B,">="&DATE(2025,1,1),Daten!B:B,"<="&DATE(2025,12,31)) -> 3567.11
A2: Gebüren Käufe Gesamt 2025: | B2: =SUMIFS(Daten!L:L,Daten!E:E,"BUY",Daten!B:B,">="&DATE(2025,1,1),Daten!B:B,"<="&DATE(2025,12,31)) -> -51
A3: Gebüren Verkäufe Gesamt 2025: | B3: =SUMIFS(Daten!L:L,Daten!E:E,"SELL",Daten!B:B,">="&DATE(2025,1,1),Daten!B:B,"<="&DATE(2025,12,31)) -> -15
A4: Gebüren Gesamt 2025: | B4: =SUMIFS(Daten!L:L,Daten!B:B,">="&DATE(2025,1,1),Daten!B:B,"<="&DATE(2025,12,31)) -> -66
A5: Steuern STOCK Gesamt 2025: | B5: =SUMIFS(Daten!M:M,Daten!F:F,"STOCK",Daten!B:B,">="&DATE(2025,1,1),Daten!B:B,"<="&DATE(2025,12,31)) -> -53.69
A6: Steuern CRYPTO Gesamt 2025: | B6: =SUMIFS(Daten!M:M,Daten!F:F,"CRYPTO",Daten!B:B,">="&DATE(2025,1,1),Daten!B:B,"<="&DATE(2025,12,31)) -> 0
A7: Steuern Gesamt 2025: | B7: =SUMIFS(Daten!M:M,Daten!B:B,">="&DATE(2025,1,1),Daten!B:B,"<="&DATE(2025,12,31)) -> -53.69
A8: Auszahlungen Gesamt 2025: | B8: =SUMIFS(Daten!K:K,Daten!E:E,"TRANSFER_INSTANT_OUTBOUND",Daten!B:B,">="&DATE(2025,1,1),Daten!B:B,"<="&DATE(2025,12,31)) + SUMIFS(Daten!K:K,Daten!E:E,"TRANSFER_OUT",Daten!B:B,">="&DATE(2025,1,1),Daten!B:B,"<="&DATE(2025,12,31)) + SUMIFS(Daten!K:K,Daten!E:E,"TRANSFER_OUTBOUND",Daten!B:B,">="&DATE(2025,1,1),Daten!B:B,"<="&DATE(2025,12,31)) -> -1450
A11: Investments STOCK 2025 | T11: Investments CRYPTO 2025
A12: Aktien/STOCK | B12: Käufe Gesamt 2025 | C12: Anteile Käufe Gesamt 2025 | D12: Verkäufe Gesamt 2025 | E12: Datum Verkäufe 2025 | F12: Verkäufe D-Day | G12: Anteile Verkäufe D-Day | H12: Anteile Verkäufe Gesamt 2025 | I12: Steuer Verkäufe D-Day | J12: Steuer Verkäufe Gesamt 2025 | K12: Rest-Anteile D-Day | L12: Rest-Anteile Gesamt 2025 | M12: Käufe bis D-Day | N12: Netto Verkäufe D-Day | O12: Gewinn/Verlust D-Day | P12: Rendite D-Day | T12: CRYPTO | U12: Käufe | V12: Anteile Käufe | W12: Verkäufe | X12: Anteile Verkäufe | Y12: Rest-Anteile | Z12: Gewinn/Verlust
A13: Bayer | B13: =SUMIFS(Daten!K:K,Daten!E:E,"BUY",Daten!F:F,"STOCK",Daten!G:G,"Bayer",Daten!H:H,"DE000BAY0017",Daten!B:B,">="&DATE(2025,1,1),Daten!B:B,"<="&DATE(2025,12,31)) + SUMIFS(Daten!L:L,Daten!E:E,"BUY",Daten!F:F,"STOCK",Daten!G:G,"Bayer",Daten!H:H,"DE000BAY0017",Daten!B:B,">="&DATE(2025,1,1),Daten!B:B,"<="&DATE(2025,12,31)) -> -58.98 | C13: =SUMIFS(Daten!I:I,Daten!E:E,"BUY",Daten!F:F,"STOCK",Daten!G:G,"Bayer",Daten!H:H,"DE000BAY0017",Daten!B:B,">="&DATE(2025,1,1),Daten!B:B,"<="&DATE(2025,12,31)) -> 1.604154 | T13: Cardano | U13: =SUMIFS(Daten!K:K,Daten!E:E,"BUY",Daten!F:F,"CRYPTO",Daten!G:G,"Cardano",Daten!H:H,"ADA",Daten!B:B,">="&DATE(2025,1,1),Daten!B:B,"<="&DATE(2025,12,31)) + SUMIFS(Daten!L:L,Daten!E:E,"BUY",Daten!F:F,"CRYPTO",Daten!G:G,"Cardano",Daten!H:H,"ADA",Daten!B:B,">="&DATE(2025,1,1),Daten!B:B,"<="&DATE(2025,12,31)) -> -82.99 | V13: =SUMIFS(Daten!I:I,Daten!E:E,"BUY",Daten!F:F,"CRYPTO",Daten!G:G,"Cardano",Daten!H:H,"ADA",Daten!B:B,">="&DATE(2025,1,1),Daten!B:B,"<="&DATE(2025,12,31)) -> 176.11287
A14: BTQ Technologies | B14: =SUMIFS(Daten!K:K,Daten!E:E,"BUY",Daten!F:F,"STOCK",Daten!G:G,"BTQ Technologies",Daten!H:H,"CA0558691014",Daten!B:B,">="&DATE(2025,1,1),Daten!B:B,"<="&DATE(2025,12,31)) + SUMIFS(Daten!L:L,Daten!E:E,"BUY",Daten!F:F,"STOCK",Daten!G:G,"BTQ Technologies",Daten!H:H,"CA0558691014",Daten!B:B,">="&DATE(2025,1,1),Daten!B:B,"<="&DATE(2025,12,31)) -> -258.29 | C14: =SUMIFS(Daten!I:I,Daten!E:E,"BUY",Daten!F:F,"STOCK",Daten!G:G,"BTQ Technologies",Daten!H:H,"CA0558691014",Daten!B:B,">="&DATE(2025,1,1),Daten!B:B,"<="&DATE(2025,12,31)) -> 30.829531 | T14: Chainlink | U14: =SUMIFS(Daten!K:K,Daten!E:E,"BUY",Daten!F:F,"CRYPTO",Daten!G:G,"Chainlink",Daten!H:H,"LINK",Daten!B:B,">="&DATE(2025,1,1),Daten!B:B,"<="&DATE(2025,12,31)) + SUMIFS(Daten!L:L,Daten!E:E,"BUY",Daten!F:F,"CRYPTO",Daten!G:G,"Chainlink",Daten!H:H,"LINK",Daten!B:B,">="&DATE(2025,1,1),Daten!B:B,"<="&DATE(2025,12,31)) -> -96 | V14: =SUMIFS(Daten!I:I,Daten!E:E,"BUY",Daten!F:F,"CRYPTO",Daten!G:G,"Chainlink",Daten!H:H,"LINK",Daten!B:B,">="&DATE(2025,1,1),Daten!B:B,"<="&DATE(2025,12,31)) -> 5.881008
A15: Centrotherm Photovoltaics | B15: =SUMIFS(Daten!K:K,Daten!E:E,"BUY",Daten!F:F,"STOCK",Daten!G:G,"Centrotherm Photovoltaics",Daten!H:H,"DE000A1TNMM9",Daten!B:B,">="&DATE(2025,1,1),Daten!B:B,"<="&DATE(2025,12,31)) + SUMIFS(Daten!L:L,Daten!E:E,"BUY",Daten!F:F,"STOCK",Daten!G:G,"Centrotherm Photovoltaics",Daten!H:H,"DE000A1TNMM9",Daten!B:B,">="&DATE(2025,1,1),Daten!B:B,"<="&DATE(2025,12,31)) -> -200 | C15: =SUMIFS(Daten!I:I,Daten!E:E,"BUY",Daten!F:F,"STOCK",Daten!G:G,"Centrotherm Photovoltaics",Daten!H:H,"DE000A1TNMM9",Daten!B:B,">="&DATE(2025,1,1),Daten!B:B,"<="&DATE(2025,12,31)) -> 23.832335 | T15: Polkadot | U15: =SUMIFS(Daten!K:K,Daten!E:E,"BUY",Daten!F:F,"CRYPTO",Daten!G:G,"Polkadot",Daten!H:H,"DOT",Daten!B:B,">="&DATE(2025,1,1),Daten!B:B,"<="&DATE(2025,12,31)) + SUMIFS(Daten!L:L,Daten!E:E,"BUY",Daten!F:F,"CRYPTO",Daten!G:G,"Polkadot",Daten!H:H,"DOT",Daten!B:B,">="&DATE(2025,1,1),Daten!B:B,"<="&DATE(2025,12,31)) -> -66.99 | V15: =SUMIFS(Daten!I:I,Daten!E:E,"BUY",Daten!F:F,"CRYPTO",Daten!G:G,"Polkadot",Daten!H:H,"DOT",Daten!B:B,">="&DATE(2025,1,1),Daten!B:B,"<="&DATE(2025,12,31)) -> 22.689657
A16: Deutsche Konsum REIT | B16: =SUMIFS(Daten!K:K,Daten!E:E,"BUY",Daten!F:F,"STOCK",Daten!G:G,"Deutsche Konsum REIT",Daten!H:H,"DE000A14KRD3",Daten!B:B,">="&DATE(2025,1,1),Daten!B:B,"<="&DATE(2025,12,31)) + SUMIFS(Daten!L:L,Daten!E:E,"BUY",Daten!F:F,"STOCK",Daten!G:G,"Deutsche Konsum REIT",Daten!H:H,"DE000A14KRD3",Daten!B:B,">="&DATE(2025,1,1),Daten!B:B,"<="&DATE(2025,12,31)) -> -57.55 | C16: =SUMIFS(Daten!I:I,Daten!E:E,"BUY",Daten!F:F,"STOCK",Daten!G:G,"Deutsche Konsum REIT",Daten!H:H,"DE000A14KRD3",Daten!B:B,">="&DATE(2025,1,1),Daten!B:B,"<="&DATE(2025,12,31)) -> 30 | T16: Render | U16: =SUMIFS(Daten!K:K,Daten!E:E,"BUY",Daten!F:F,"CRYPTO",Daten!G:G,"Render",Daten!H:H,"XF0RENDER015",Daten!B:B,">="&DATE(2025,1,1),Daten!B:B,"<="&DATE(2025,12,31)) + SUMIFS(Daten!L:L,Daten!E:E,"BUY",Daten!F:F,"CRYPTO",Daten!G:G,"Render",Daten!H:H,"XF0RENDER015",Daten!B:B,">="&DATE(2025,1,1),Daten!B:B,"<="&DATE(2025,12,31)) -> -58.97 | V16: =SUMIFS(Daten!I:I,Daten!E:E,"BUY",Daten!F:F,"CRYPTO",Daten!G:G,"Render",Daten!H:H,"XF0RENDER015",Daten!B:B,">="&DATE(2025,1,1),Daten!B:B,"<="&DATE(2025,12,31)) -> 24.9
A17: Draganfly | B17: =SUMIFS(Daten!K:K,Daten!E:E,"BUY",Daten!F:F,"STOCK",Daten!G:G,"Draganfly",Daten!H:H,"CA26142Q3044",Daten!B:B,">="&DATE(2025,1,1),Daten!B:B,"<="&DATE(2025,12,31)) + SUMIFS(Daten!L:L,Daten!E:E,"BUY",Daten!F:F,"STOCK",Daten!G:G,"Draganfly",Daten!H:H,"CA26142Q3044",Daten!B:B,">="&DATE(2025,1,1),Daten!B:B,"<="&DATE(2025,12,31)) -> -80 | C17: =SUMIFS(Daten!I:I,Daten!E:E,"BUY",Daten!F:F,"STOCK",Daten!G:G,"Draganfly",Daten!H:H,"CA26142Q3044",Daten!B:B,">="&DATE(2025,1,1),Daten!B:B,"<="&DATE(2025,12,31)) -> 14.90566 | T17: Solana | U17: =SUMIFS(Daten!K:K,Daten!E:E,"BUY",Daten!F:F,"CRYPTO",Daten!G:G,"Solana",Daten!H:H,"SOL",Daten!B:B,">="&DATE(2025,1,1),Daten!B:B,"<="&DATE(2025,12,31)) + SUMIFS(Daten!L:L,Daten!E:E,"BUY",Daten!F:F,"CRYPTO",Daten!G:G,"Solana",Daten!H:H,"SOL",Daten!B:B,">="&DATE(2025,1,1),Daten!B:B,"<="&DATE(2025,12,31)) -> -189.02 | V17: =SUMIFS(Daten!I:I,Daten!E:E,"BUY",Daten!F:F,"CRYPTO",Daten!G:G,"Solana",Daten!H:H,"SOL",Daten!B:B,">="&DATE(2025,1,1),Daten!B:B,"<="&DATE(2025,12,31)) -> 1.004294
A18: DroneShield | B18: =SUMIFS(Daten!K:K,Daten!E:E,"BUY",Daten!F:F,"STOCK",Daten!G:G,"DroneShield",Daten!H:H,"AU000000DRO2",Daten!B:B,">="&DATE(2025,1,1),Daten!B:B,"<="&DATE(2025,12,31)) + SUMIFS(Daten!L:L,Daten!E:E,"BUY",Daten!F:F,"STOCK",Daten!G:G,"DroneShield",Daten!H:H,"AU000000DRO2",Daten!B:B,">="&DATE(2025,1,1),Daten!B:B,"<="&DATE(2025,12,31)) -> -476.8 | C18: =SUMIFS(Daten!I:I,Daten!E:E,"BUY",Daten!F:F,"STOCK",Daten!G:G,"DroneShield",Daten!H:H,"AU000000DRO2",Daten!B:B,">="&DATE(2025,1,1),Daten!B:B,"<="&DATE(2025,12,31)) -> 232.00233 | D18: =SUMIFS(Daten!K:K,Daten!E:E,"SELL",Daten!F:F,"STOCK",Daten!G:G,"DroneShield",Daten!H:H,"AU000000DRO2",Daten!B:B,">="&DATE(2025,1,1),Daten!B:B,"<="&DATE(2025,12,31)) + SUMIFS(Daten!L:L,Daten!E:E,"SELL",Daten!F:F,"STOCK",Daten!G:G,"DroneShield",Daten!H:H,"AU000000DRO2",Daten!B:B,">="&DATE(2025,1,1),Daten!B:B,"<="&DATE(2025,12,31)) -> 446.31 | E18: 45938 | F18: =SUMIFS(Daten!K:K,Daten!E:E,"SELL",Daten!F:F,"STOCK",Daten!G:G,"DroneShield",Daten!H:H,"AU000000DRO2",Daten!B:B,"="&DATE(2025,10,8)) + SUMIFS(Daten!L:L,Daten!E:E,"SELL",Daten!F:F,"STOCK",Daten!G:G,"DroneShield",Daten!H:H,"AU000000DRO2",Daten!B:B,"="&DATE(2025,10,8)) -> 446.31 | G18: =SUMIFS(Daten!I:I,Daten!E:E,"SELL",Daten!F:F,"STOCK",Daten!G:G,"DroneShield",Daten!H:H,"AU000000DRO2",Daten!B:B,"="&DATE(2025,10,8)) -> -123.22719 | H18: =SUMIFS(Daten!I:I,Daten!E:E,"SELL",Daten!F:F,"STOCK",Daten!G:G,"DroneShield",Daten!H:H,"AU000000DRO2",Daten!B:B,">="&DATE(2025,1,1),Daten!B:B,"<="&DATE(2025,12,31)) -> -123.22719 | I18: =SUMIFS(Daten!M:M,Daten!E:E,"SELL",Daten!F:F,"STOCK",Daten!G:G,"DroneShield",Daten!H:H,"AU000000DRO2",Daten!B:B,"="&DATE(2025,10,8)) -> -23.6 | J18: =SUMIFS(Daten!M:M,Daten!E:E,"SELL",Daten!F:F,"STOCK",Daten!G:G,"DroneShield",Daten!H:H,"AU000000DRO2",Daten!B:B,">="&DATE(2025,1,1),Daten!B:B,"<="&DATE(2025,12,31)) -> -23.6 | K18: =SUMIFS(Daten!I:I,Daten!E:E,"BUY",Daten!F:F,"STOCK",Daten!G:G,"DroneShield",Daten!H:H,"AU000000DRO2",Daten!B:B,">="&DATE(2025,1,1),Daten!B:B,"<="&DATE(2025,10,8)) + SUMIFS(Daten!I:I,Daten!E:E,"SELL",Daten!F:F,"STOCK",Daten!G:G,"DroneShield",Daten!H:H,"AU000000DRO2",Daten!B:B,">="&DATE(2025,1,1),Daten!B:B,"<="&DATE(2025,10,8)) -> 0 | L18: =SUMIFS(Daten!I:I,Daten!E:E,"BUY",Daten!F:F,"STOCK",Daten!G:G,"DroneShield",Daten!H:H,"AU000000DRO2",Daten!B:B,">="&DATE(2025,1,1),Daten!B:B,"<="&DATE(2025,12,31)) + SUMIFS(Daten!I:I,Daten!E:E,"SELL",Daten!F:F,"STOCK",Daten!G:G,"DroneShield",Daten!H:H,"AU000000DRO2",Daten!B:B,">="&DATE(2025,1,1),Daten!B:B,"<="&DATE(2025,12,31)) -> 108.77514 | M18: =SUMIFS(Daten!K:K,Daten!E:E,"BUY",Daten!F:F,"STOCK",Daten!G:G,"DroneShield",Daten!H:H,"AU000000DRO2",Daten!B:B,">="&DATE(2025,1,1),Daten!B:B,"<="&DATE(2025,10,8)) + SUMIFS(Daten!L:L,Daten!E:E,"BUY",Daten!F:F,"STOCK",Daten!G:G,"DroneShield",Daten!H:H,"AU000000DRO2",Daten!B:B,">="&DATE(2025,1,1),Daten!B:B,"<="&DATE(2025,10,8)) -> -356.8 | N18: =SUMIFS(Daten!K:K,Daten!E:E,"SELL",Daten!F:F,"STOCK",Daten!G:G,"DroneShield",Daten!H:H,"AU000000DRO2",Daten!B:B,"="&DATE(2025,10,8)) + SUMIFS(Daten!L:L,Daten!E:E,"SELL",Daten!F:F,"STOCK",Daten!G:G,"DroneShield",Daten!H:H,"AU000000DRO2",Daten!B:B,"="&DATE(2025,10,8)) + SUMIFS(Daten!M:M,Daten!E:E,"SELL",Daten!F:F,"STOCK",Daten!G:G,"DroneShield",Daten!H:H,"AU000000DRO2",Daten!B:B,"="&DATE(2025,10,8)) -> 422.71 | O18: =SUMIFS(Daten!K:K,Daten!E:E,"BUY",Daten!F:F,"STOCK",Daten!G:G,"DroneShield",Daten!H:H,"AU000000DRO2",Daten!B:B,">="&DATE(2025,1,1),Daten!B:B,"<="&DATE(2025,10,8)) + SUMIFS(Daten!L:L,Daten!E:E,"BUY",Daten!F:F,"STOCK",Daten!G:G,"DroneShield",Daten!H:H,"AU000000DRO2",Daten!B:B,">="&DATE(2025,1,1),Daten!B:B,"<="&DATE(2025,10,8)) + SUMIFS(Daten!K:K,Daten!E:E,"SELL",Daten!F:F,"STOCK",Daten!G:G,"DroneShield",Daten!H:H,"AU000000DRO2",Daten!B:B,"="&DATE(2025,10,8)) + SUMIFS(Daten!L:L,Daten!E:E,"SELL",Daten!F:F,"STOCK",Daten!G:G,"DroneShield",Daten!H:H,"AU000000DRO2",Daten!B:B,"="&DATE(2025,10,8)) -> 89.51 | P18: =-( SUMIFS(Daten!K:K,Daten!E:E,"BUY",Daten!F:F,"STOCK",Daten!G:G,"DroneShield",Daten!H:H,"AU000000DRO2",Daten!B:B,">="&DATE(2025,1,1),Daten!B:B,"<="&DATE(2025,10,8)) + SUMIFS(Daten!L:L,Daten!E:E,"BUY",Daten!F:F,"STOCK",Daten!G:G,"DroneShield",Daten!H:H,"AU000000DRO2",Daten!B:B,">="&DATE(2025,1,1),Daten!B:B,"<="&DATE(2025,10,8)) + SUMIFS(Daten!K:K,Daten!E:E,"SELL",Daten!F:F,"STOCK",Daten!G:G,"DroneShield",Daten!H:H,"AU000000DRO2",Daten!B:B,"="&DATE(2025,10,8)) + SUMIFS(Daten!L:L,Daten!E:E,"SELL",Daten!F:F,"STOCK",Daten!G:G,"DroneShield",Daten!H:H,"AU000000DRO2",Daten!B:B,"="&DATE(2025,10,8)) ) / ( SUMIFS(Daten!K:K,Daten!E:E,"BUY",Daten!F:F,"STOCK",Daten!G:G,"DroneShield",Daten!H:H,"AU000000DRO2",Daten!B:B,">="&DATE(2025,1,1),Daten!B:B,"<="&DATE(2025,10,8)) + SUMIFS(Daten!L:L,Daten!E:E,"BUY",Daten!F:F,"STOCK",Daten!G:G,"DroneShield",Daten!H:H,"AU000000DRO2",Daten!B:B,">="&DATE(2025,1,1),Daten!B:B,"<="&DATE(2025,10,8)) ) -> 0.25086883 | T18: XRP | U18: =SUMIFS(Daten!K:K,Daten!E:E,"BUY",Daten!F:F,"CRYPTO",Daten!G:G,"XRP",Daten!H:H,"XRP",Daten!B:B,">="&DATE(2025,1,1),Daten!B:B,"<="&DATE(2025,12,31)) + SUMIFS(Daten!L:L,Daten!E:E,"BUY",Daten!F:F,"CRYPTO",Daten!G:G,"XRP",Daten!H:H,"XRP",Daten!B:B,">="&DATE(2025,1,1),Daten!B:B,"<="&DATE(2025,12,31)) -> -86.01 | V18: =SUMIFS(Daten!I:I,Daten!E:E,"BUY",Daten!F:F,"CRYPTO",Daten!G:G,"XRP",Daten!H:H,"XRP",Daten!B:B,">="&DATE(2025,1,1),Daten!B:B,"<="&DATE(2025,12,31)) -> 41.012137
A19: D-Wave Quantum | B19: =SUMIFS(Daten!K:K,Daten!E:E,"BUY",Daten!F:F,"STOCK",Daten!G:G,"D-Wave Quantum",Daten!H:H,"US26740W1099",Daten!B:B,">="&DATE(2025,1,1),Daten!B:B,"<="&DATE(2025,12,31)) + SUMIFS(Daten!L:L,Daten!E:E,"BUY",Daten!F:F,"STOCK",Daten!G:G,"D-Wave Quantum",Daten!H:H,"US26740W1099",Daten!B:B,">="&DATE(2025,1,1),Daten!B:B,"<="&DATE(2025,12,31)) -> -526.86 | C19: =SUMIFS(Daten!I:I,Daten!E:E,"BUY",Daten!F:F,"STOCK",Daten!G:G,"D-Wave Quantum",Daten!H:H,"US26740W1099",Daten!B:B,">="&DATE(2025,1,1),Daten!B:B,"<="&DATE(2025,12,31)) -> 22.142168 | D19: =SUMIFS(Daten!K:K,Daten!E:E,"SELL",Daten!F:F,"STOCK",Daten!G:G,"D-Wave Quantum",Daten!H:H,"US26740W1099",Daten!B:B,">="&DATE(2025,1,1),Daten!B:B,"<="&DATE(2025,12,31)) + SUMIFS(Daten!L:L,Daten!E:E,"SELL",Daten!F:F,"STOCK",Daten!G:G,"D-Wave Quantum",Daten!H:H,"US26740W1099",Daten!B:B,">="&DATE(2025,1,1),Daten!B:B,"<="&DATE(2025,12,31)) -> 209.03 | E19: 45938 | F19: =SUMIFS(Daten!K:K,Daten!E:E,"SELL",Daten!F:F,"STOCK",Daten!G:G,"D-Wave Quantum",Daten!H:H,"US26740W1099",Daten!B:B,"="&DATE(2025,10,8)) + SUMIFS(Daten!L:L,Daten!E:E,"SELL",Daten!F:F,"STOCK",Daten!G:G,"D-Wave Quantum",Daten!H:H,"US26740W1099",Daten!B:B,"="&DATE(2025,10,8)) -> 209.03 | G19: =SUMIFS(Daten!I:I,Daten!E:E,"SELL",Daten!F:F,"STOCK",Daten!G:G,"D-Wave Quantum",Daten!H:H,"US26740W1099",Daten!B:B,"="&DATE(2025,10,8)) -> -6.699364 | H19: =SUMIFS(Daten!I:I,Daten!E:E,"SELL",Daten!F:F,"STOCK",Daten!G:G,"D-Wave Quantum",Daten!H:H,"US26740W1099",Daten!B:B,">="&DATE(2025,1,1),Daten!B:B,"<="&DATE(2025,12,31)) -> -6.699364 | I19: =SUMIFS(Daten!M:M,Daten!E:E,"SELL",Daten!F:F,"STOCK",Daten!G:G,"D-Wave Quantum",Daten!H:H,"US26740W1099",Daten!B:B,"="&DATE(2025,10,8)) -> -15.58 | J19: =SUMIFS(Daten!M:M,Daten!E:E,"SELL",Daten!F:F,"STOCK",Daten!G:G,"D-Wave Quantum",Daten!H:H,"US26740W1099",Daten!B:B,">="&DATE(2025,1,1),Daten!B:B,"<="&DATE(2025,10,8)) -> -15.58 | K19: =SUMIFS(Daten!I:I,Daten!E:E,"BUY",Daten!F:F,"STOCK",Daten!G:G,"D-Wave Quantum",Daten!H:H,"US26740W1099",Daten!B:B,">="&DATE(2025,1,1),Daten!B:B,"<="&DATE(2025,10,8)) + SUMIFS(Daten!I:I,Daten!E:E,"SELL",Daten!F:F,"STOCK",Daten!G:G,"D-Wave Quantum",Daten!H:H,"US26740W1099",Daten!B:B,">="&DATE(2025,1,1),Daten!B:B,"<="&DATE(2025,10,8)) -> 0 | L19: =SUMIFS(Daten!I:I,Daten!E:E,"BUY",Daten!F:F,"STOCK",Daten!G:G,"D-Wave Quantum",Daten!H:H,"US26740W1099",Daten!B:B,">="&DATE(2025,1,1),Daten!B:B,"<="&DATE(2025,12,31)) + SUMIFS(Daten!I:I,Daten!E:E,"SELL",Daten!F:F,"STOCK",Daten!G:G,"D-Wave Quantum",Daten!H:H,"US26740W1099",Daten!B:B,">="&DATE(2025,1,1),Daten!B:B,"<="&DATE(2025,12,31)) -> 15.442804 | M19: =SUMIFS(Daten!K:K,Daten!E:E,"BUY",Daten!F:F,"STOCK",Daten!G:G,"D-Wave Quantum",Daten!H:H,"US26740W1099",Daten!B:B,">="&DATE(2025,1,1),Daten!B:B,"<="&DATE(2025,10,8)) + SUMIFS(Daten!L:L,Daten!E:E,"BUY",Daten!F:F,"STOCK",Daten!G:G,"D-Wave Quantum",Daten!H:H,"US26740W1099",Daten!B:B,">="&DATE(2025,1,1),Daten!B:B,"<="&DATE(2025,10,8)) -> -149.96 | N19: =SUMIFS(Daten!K:K,Daten!E:E,"SELL",Daten!F:F,"STOCK",Daten!G:G,"D-Wave Quantum",Daten!H:H,"US26740W1099",Daten!B:B,"="&DATE(2025,10,8)) + SUMIFS(Daten!L:L,Daten!E:E,"SELL",Daten!F:F,"STOCK",Daten!G:G,"D-Wave Quantum",Daten!H:H,"US26740W1099",Daten!B:B,"="&DATE(2025,10,8)) + SUMIFS(Daten!M:M,Daten!E:E,"SELL",Daten!F:F,"STOCK",Daten!G:G,"D-Wave Quantum",Daten!H:H,"US26740W1099",Daten!B:B,"="&DATE(2025,10,8)) -> 193.45 | O19: =SUMIFS(Daten!K:K,Daten!E:E,"BUY",Daten!F:F,"STOCK",Daten!G:G,"D-Wave Quantum",Daten!H:H,"US26740W1099",Daten!B:B,">="&DATE(2025,1,1),Daten!B:B,"<="&DATE(2025,10,8)) + SUMIFS(Daten!L:L,Daten!E:E,"BUY",Daten!F:F,"STOCK",Daten!G:G,"D-Wave Quantum",Daten!H:H,"US26740W1099",Daten!B:B,">="&DATE(2025,1,1),Daten!B:B,"<="&DATE(2025,10,8)) + SUMIFS(Daten!K:K,Daten!E:E,"SELL",Daten!F:F,"STOCK",Daten!G:G,"D-Wave Quantum",Daten!H:H,"US26740W1099",Daten!B:B,"="&DATE(2025,10,8)) + SUMIFS(Daten!L:L,Daten!E:E,"SELL",Daten!F:F,"STOCK",Daten!G:G,"D-Wave Quantum",Daten!H:H,"US26740W1099",Daten!B:B,"="&DATE(2025,10,8)) -> 59.07 | P19: =-( SUMIFS(Daten!K:K,Daten!E:E,"BUY",Daten!F:F,"STOCK",Daten!G:G,"D-Wave Quantum",Daten!H:H,"US26740W1099",Daten!B:B,">="&DATE(2025,1,1),Daten!B:B,"<="&DATE(2025,10,8)) + SUMIFS(Daten!L:L,Daten!E:E,"BUY",Daten!F:F,"STOCK",Daten!G:G,"D-Wave Quantum",Daten!H:H,"US26740W1099",Daten!B:B,">="&DATE(2025,1,1),Daten!B:B,"<="&DATE(2025,10,8)) + SUMIFS(Daten!K:K,Daten!E:E,"SELL",Daten!F:F,"STOCK",Daten!G:G,"D-Wave Quantum",Daten!H:H,"US26740W1099",Daten!B:B,"="&DATE(2025,10,8)) + SUMIFS(Daten!L:L,Daten!E:E,"SELL",Daten!F:F,"STOCK",Daten!G:G,"D-Wave Quantum",Daten!H:H,"US26740W1099",Daten!B:B,"="&DATE(2025,10,8)) ) / ( SUMIFS(Daten!K:K,Daten!E:E,"BUY",Daten!F:F,"STOCK",Daten!G:G,"D-Wave Quantum",Daten!H:H,"US26740W1099",Daten!B:B,">="&DATE(2025,1,1),Daten!B:B,"<="&DATE(2025,10,8)) + SUMIFS(Daten!L:L,Daten!E:E,"BUY",Daten!F:F,"STOCK",Daten!G:G,"D-Wave Quantum",Daten!H:H,"US26740W1099",Daten!B:B,">="&DATE(2025,1,1),Daten!B:B,"<="&DATE(2025,10,8)) ) -> 0.39390504
A20: Evotec | B20: =SUMIFS(Daten!K:K,Daten!E:E,"BUY",Daten!F:F,"STOCK",Daten!G:G,"Evotec",Daten!H:H,"DE0005664809",Daten!B:B,">="&DATE(2025,1,1),Daten!B:B,"<="&DATE(2025,12,31)) + SUMIFS(Daten!L:L,Daten!E:E,"BUY",Daten!F:F,"STOCK",Daten!G:G,"Evotec",Daten!H:H,"DE0005664809",Daten!B:B,">="&DATE(2025,1,1),Daten!B:B,"<="&DATE(2025,12,31)) -> -100 | C20: =SUMIFS(Daten!I:I,Daten!E:E,"BUY",Daten!F:F,"STOCK",Daten!G:G,"Evotec",Daten!H:H,"DE0005664809",Daten!B:B,">="&DATE(2025,1,1),Daten!B:B,"<="&DATE(2025,12,31)) -> 18.553223
A21: Hensoldt | B21: =SUMIFS(Daten!K:K,Daten!E:E,"BUY",Daten!F:F,"STOCK",Daten!G:G,"Hensoldt",Daten!H:H,"DE000HAG0005",Daten!B:B,">="&DATE(2025,1,1),Daten!B:B,"<="&DATE(2025,12,31)) + SUMIFS(Daten!L:L,Daten!E:E,"BUY",Daten!F:F,"STOCK",Daten!G:G,"Hensoldt",Daten!H:H,"DE000HAG0005",Daten!B:B,">="&DATE(2025,1,1),Daten!B:B,"<="&DATE(2025,12,31)) -> -93 | C21: =SUMIFS(Daten!I:I,Daten!E:E,"BUY",Daten!F:F,"STOCK",Daten!G:G,"Hensoldt",Daten!H:H,"DE000HAG0005",Daten!B:B,">="&DATE(2025,1,1),Daten!B:B,"<="&DATE(2025,12,31)) -> 1.009325 | D21: =SUMIFS(Daten!K:K,Daten!E:E,"SELL",Daten!F:F,"STOCK",Daten!G:G,"Hensoldt",Daten!H:H,"DE000HAG0005",Daten!B:B,">="&DATE(2025,1,1),Daten!B:B,"<="&DATE(2025,12,31)) + SUMIFS(Daten!L:L,Daten!E:E,"SELL",Daten!F:F,"STOCK",Daten!G:G,"Hensoldt",Daten!H:H,"DE000HAG0005",Daten!B:B,">="&DATE(2025,1,1),Daten!B:B,"<="&DATE(2025,12,31)) -> 101.7 | E21: 45924 | F21: =SUMIFS(Daten!K:K,Daten!E:E,"SELL",Daten!F:F,"STOCK",Daten!G:G,"Hensoldt",Daten!H:H,"DE000HAG0005",Daten!B:B,"="&DATE(2025,9,24)) + SUMIFS(Daten!L:L,Daten!E:E,"SELL",Daten!F:F,"STOCK",Daten!G:G,"Hensoldt",Daten!H:H,"DE000HAG0005",Daten!B:B,"="&DATE(2025,9,24)) -> 101.7 | G21: =SUMIFS(Daten!I:I,Daten!E:E,"SELL",Daten!F:F,"STOCK",Daten!G:G,"Hensoldt",Daten!H:H,"DE000HAG0005",Daten!B:B,"="&DATE(2025,9,24)) -> -1.009325 | H21: =SUMIFS(Daten!I:I,Daten!E:E,"SELL",Daten!F:F,"STOCK",Daten!G:G,"Hensoldt",Daten!H:H,"DE000HAG0005",Daten!B:B,">="&DATE(2025,1,1),Daten!B:B,"<="&DATE(2025,12,31)) -> -1.009325 | I21: =SUMIFS(Daten!M:M,Daten!E:E,"SELL",Daten!F:F,"STOCK",Daten!G:G,"Hensoldt",Daten!H:H,"DE000HAG0005",Daten!B:B,"="&DATE(2025,9,24)) -> -2.29 | J21: =SUMIFS(Daten!M:M,Daten!E:E,"SELL",Daten!F:F,"STOCK",Daten!G:G,"Hensoldt",Daten!H:H,"DE000HAG0005",Daten!B:B,">="&DATE(2025,1,1),Daten!B:B,"<="&DATE(2025,12,31)) -> -2.29 | K21: =SUMIFS(Daten!I:I,Daten!E:E,"BUY",Daten!F:F,"STOCK",Daten!G:G,"Hensoldt",Daten!H:H,"DE000HAG0005",Daten!B:B,">="&DATE(2025,1,1),Daten!B:B,"<="&DATE(2025,9,24)) + SUMIFS(Daten!I:I,Daten!E:E,"SELL",Daten!F:F,"STOCK",Daten!G:G,"Hensoldt",Daten!H:H,"DE000HAG0005",Daten!B:B,">="&DATE(2025,1,1),Daten!B:B,"<="&DATE(2025,9,24)) -> 0 | L21: =SUMIFS(Daten!I:I,Daten!E:E,"BUY",Daten!F:F,"STOCK",Daten!G:G,"Hensoldt",Daten!H:H,"DE000HAG0005",Daten!B:B,">="&DATE(2025,1,1),Daten!B:B,"<="&DATE(2025,12,31)) + SUMIFS(Daten!I:I,Daten!E:E,"SELL",Daten!F:F,"STOCK",Daten!G:G,"Hensoldt",Daten!H:H,"DE000HAG0005",Daten!B:B,">="&DATE(2025,1,1),Daten!B:B,"<="&DATE(2025,12,31)) -> 0 | M21: =SUMIFS(Daten!K:K,Daten!E:E,"BUY",Daten!F:F,"STOCK",Daten!G:G,"Hensoldt",Daten!H:H,"DE000HAG0005",Daten!B:B,">="&DATE(2025,1,1),Daten!B:B,"<="&DATE(2025,9,24)) + SUMIFS(Daten!L:L,Daten!E:E,"BUY",Daten!F:F,"STOCK",Daten!G:G,"Hensoldt",Daten!H:H,"DE000HAG0005",Daten!B:B,">="&DATE(2025,1,1),Daten!B:B,"<="&DATE(2025,9,24)) -> -93 | N21: =SUMIFS(Daten!K:K,Daten!E:E,"SELL",Daten!F:F,"STOCK",Daten!G:G,"Hensoldt",Daten!H:H,"DE000HAG0005",Daten!B:B,"="&DATE(2025,9,24)) + SUMIFS(Daten!L:L,Daten!E:E,"SELL",Daten!F:F,"STOCK",Daten!G:G,"Hensoldt",Daten!H:H,"DE000HAG0005",Daten!B:B,"="&DATE(2025,9,24)) + SUMIFS(Daten!M:M,Daten!E:E,"SELL",Daten!F:F,"STOCK",Daten!G:G,"Hensoldt",Daten!H:H,"DE000HAG0005",Daten!B:B,"="&DATE(2025,9,24)) -> 99.41 | O21: =SUMIFS(Daten!K:K,Daten!E:E,"BUY",Daten!F:F,"STOCK",Daten!G:G,"Hensoldt",Daten!H:H,"DE000HAG0005",Daten!B:B,">="&DATE(2025,1,1),Daten!B:B,"<="&DATE(2025,9,24)) + SUMIFS(Daten!L:L,Daten!E:E,"BUY",Daten!F:F,"STOCK",Daten!G:G,"Hensoldt",Daten!H:H,"DE000HAG0005",Daten!B:B,">="&DATE(2025,1,1),Daten!B:B,"<="&DATE(2025,9,24)) + SUMIFS(Daten!K:K,Daten!E:E,"SELL",Daten!F:F,"STOCK",Daten!G:G,"Hensoldt",Daten!H:H,"DE000HAG0005",Daten!B:B,"="&DATE(2025,9,24)) + SUMIFS(Daten!L:L,Daten!E:E,"SELL",Daten!F:F,"STOCK",Daten!G:G,"Hensoldt",Daten!H:H,"DE000HAG0005",Daten!B:B,"="&DATE(2025,9,24)) -> 8.7 | P21: =-( SUMIFS(Daten!K:K,Daten!E:E,"BUY",Daten!F:F,"STOCK",Daten!G:G,"Hensoldt",Daten!H:H,"DE000HAG0005",Daten!B:B,">="&DATE(2025,1,1),Daten!B:B,"<="&DATE(2025,9,24)) + SUMIFS(Daten!L:L,Daten!E:E,"BUY",Daten!F:F,"STOCK",Daten!G:G,"Hensoldt",Daten!H:H,"DE000HAG0005",Daten!B:B,">="&DATE(2025,1,1),Daten!B:B,"<="&DATE(2025,9,24)) + SUMIFS(Daten!K:K,Daten!E:E,"SELL",Daten!F:F,"STOCK",Daten!G:G,"Hensoldt",Daten!H:H,"DE000HAG0005",Daten!B:B,"="&DATE(2025,9,24)) + SUMIFS(Daten!L:L,Daten!E:E,"SELL",Daten!F:F,"STOCK",Daten!G:G,"Hensoldt",Daten!H:H,"DE000HAG0005",Daten!B:B,"="&DATE(2025,9,24)) ) / ( SUMIFS(Daten!K:K,Daten!E:E,"BUY",Daten!F:F,"STOCK",Daten!G:G,"Hensoldt",Daten!H:H,"DE000HAG0005",Daten!B:B,">="&DATE(2025,1,1),Daten!B:B,"<="&DATE(2025,9,24)) + SUMIFS(Daten!L:L,Daten!E:E,"BUY",Daten!F:F,"STOCK",Daten!G:G,"Hensoldt",Daten!H:H,"DE000HAG0005",Daten!B:B,">="&DATE(2025,1,1),Daten!B:B,"<="&DATE(2025,9,24)) ) -> 0.093548387 | T21: CRYPTO Gesamt 2025: | U21: =SUMIFS(Daten!K:K,Daten!E:E,"BUY",Daten!F:F,"CRYPTO",Daten!B:B,">="&DATE(2025,1,1),Daten!B:B,"<="&DATE(2025,12,31)) + SUMIFS(Daten!L:L,Daten!E:E,"BUY",Daten!F:F,"CRYPTO",Daten!B:B,">="&DATE(2025,1,1),Daten!B:B,"<="&DATE(2025,12,31)) -> -579.98 | V21: =SUMIFS(Daten!I:I,Daten!E:E,"BUY",Daten!F:F,"CRYPTO",Daten!B:B,">="&DATE(2025,1,1),Daten!B:B,"<="&DATE(2025,12,31)) -> 271.59997
A22: Infineon Technologies | B22: =SUMIFS(Daten!K:K,Daten!E:E,"BUY",Daten!F:F,"STOCK",Daten!G:G,"Infineon Technologies",Daten!H:H,"DE0006231004",Daten!B:B,">="&DATE(2025,1,1),Daten!B:B,"<="&DATE(2025,12,31)) + SUMIFS(Daten!L:L,Daten!E:E,"BUY",Daten!F:F,"STOCK",Daten!G:G,"Infineon Technologies",Daten!H:H,"DE0006231004",Daten!B:B,">="&DATE(2025,1,1),Daten!B:B,"<="&DATE(2025,12,31)) -> -61 | C22: =SUMIFS(Daten!I:I,Daten!E:E,"BUY",Daten!F:F,"STOCK",Daten!G:G,"Infineon Technologies",Daten!H:H,"DE0006231004",Daten!B:B,">="&DATE(2025,1,1),Daten!B:B,"<="&DATE(2025,12,31)) -> 1.871199 | D22: =SUMIFS(Daten!K:K,Daten!E:E,"SELL",Daten!F:F,"STOCK",Daten!G:G,"Infineon Technologies",Daten!H:H,"DE0006231004",Daten!B:B,">="&DATE(2025,1,1),Daten!B:B,"<="&DATE(2025,12,31)) + SUMIFS(Daten!L:L,Daten!E:E,"SELL",Daten!F:F,"STOCK",Daten!G:G,"Infineon Technologies",Daten!H:H,"DE0006231004",Daten!B:B,">="&DATE(2025,1,1),Daten!B:B,"<="&DATE(2025,12,31)) -> 63.16 | E22: 45932 | F22: =SUMIFS(Daten!K:K,Daten!E:E,"SELL",Daten!F:F,"STOCK",Daten!G:G,"Infineon Technologies",Daten!H:H,"DE0006231004",Daten!B:B,"="&DATE(2025,10,2)) + SUMIFS(Daten!L:L,Daten!E:E,"SELL",Daten!F:F,"STOCK",Daten!G:G,"Infineon Technologies",Daten!H:H,"DE0006231004",Daten!B:B,"="&DATE(2025,10,2)) -> 63.16 | G22: =SUMIFS(Daten!I:I,Daten!E:E,"SELL",Daten!F:F,"STOCK",Daten!G:G,"Infineon Technologies",Daten!H:H,"DE0006231004",Daten!B:B,"="&DATE(2025,10,2)) -> -1.871199 | H22: =SUMIFS(Daten!I:I,Daten!E:E,"SELL",Daten!F:F,"STOCK",Daten!G:G,"Infineon Technologies",Daten!H:H,"DE0006231004",Daten!B:B,">="&DATE(2025,1,1),Daten!B:B,"<="&DATE(2025,12,31)) -> -1.871199 | I22: =SUMIFS(Daten!M:M,Daten!E:E,"SELL",Daten!F:F,"STOCK",Daten!G:G,"Infineon Technologies",Daten!H:H,"DE0006231004",Daten!B:B,"="&DATE(2025,10,2)) -> -0.57 | J22: =SUMIFS(Daten!M:M,Daten!E:E,"SELL",Daten!F:F,"STOCK",Daten!G:G,"Infineon Technologies",Daten!H:H,"DE0006231004",Daten!B:B,">="&DATE(2025,1,1),Daten!B:B,"<="&DATE(2025,12,31)) -> -0.57 | K22: =SUMIFS(Daten!I:I,Daten!E:E,"BUY",Daten!F:F,"STOCK",Daten!G:G,"Infineon Technologies",Daten!H:H,"DE0006231004",Daten!B:B,">="&DATE(2025,1,1),Daten!B:B,"<="&DATE(2025,10,2)) + SUMIFS(Daten!I:I,Daten!E:E,"SELL",Daten!F:F,"STOCK",Daten!G:G,"Infineon Technologies",Daten!H:H,"DE0006231004",Daten!B:B,">="&DATE(2025,1,1),Daten!B:B,"<="&DATE(2025,10,2)) -> 0 | L22: =SUMIFS(Daten!I:I,Daten!E:E,"BUY",Daten!F:F,"STOCK",Daten!G:G,"Infineon Technologies",Daten!H:H,"DE0006231004",Daten!B:B,">="&DATE(2025,1,1),Daten!B:B,"<="&DATE(2025,12,31)) + SUMIFS(Daten!I:I,Daten!E:E,"SELL",Daten!F:F,"STOCK",Daten!G:G,"Infineon Technologies",Daten!H:H,"DE0006231004",Daten!B:B,">="&DATE(2025,1,1),Daten!B:B,"<="&DATE(2025,12,31)) -> 0 | M22: =SUMIFS(Daten!K:K,Daten!E:E,"BUY",Daten!F:F,"STOCK",Daten!G:G,"Infineon Technologies",Daten!H:H,"DE0006231004",Daten!B:B,">="&DATE(2025,1,1),Daten!B:B,"<="&DATE(2025,10,2)) + SUMIFS(Daten!L:L,Daten!E:E,"BUY",Daten!F:F,"STOCK",Daten!G:G,"Infineon Technologies",Daten!H:H,"DE0006231004",Daten!B:B,">="&DATE(2025,1,1),Daten!B:B,"<="&DATE(2025,10,2)) -> -61 | N22: =SUMIFS(Daten!K:K,Daten!E:E,"SELL",Daten!F:F,"STOCK",Daten!G:G,"Infineon Technologies",Daten!H:H,"DE0006231004",Daten!B:B,"="&DATE(2025,10,2)) + SUMIFS(Daten!L:L,Daten!E:E,"SELL",Daten!F:F,"STOCK",Daten!G:G,"Infineon Technologies",Daten!H:H,"DE0006231004",Daten!B:B,"="&DATE(2025,10,2)) + SUMIFS(Daten!M:M,Daten!E:E,"SELL",Daten!F:F,"STOCK",Daten!G:G,"Infineon Technologies",Daten!H:H,"DE0006231004",Daten!B:B,"="&DATE(2025,10,2)) -> 62.59 | O22: =SUMIFS(Daten!K:K,Daten!E:E,"BUY",Daten!F:F,"STOCK",Daten!G:G,"Infineon Technologies",Daten!H:H,"DE0006231004",Daten!B:B,">="&DATE(2025,1,1),Daten!B:B,"<="&DATE(2025,10,2)) + SUMIFS(Daten!L:L,Daten!E:E,"BUY",Daten!F:F,"STOCK",Daten!G:G,"Infineon Technologies",Daten!H:H,"DE0006231004",Daten!B:B,">="&DATE(2025,1,1),Daten!B:B,"<="&DATE(2025,10,2)) + SUMIFS(Daten!K:K,Daten!E:E,"SELL",Daten!F:F,"STOCK",Daten!G:G,"Infineon Technologies",Daten!H:H,"DE0006231004",Daten!B:B,"="&DATE(2025,10,2)) + SUMIFS(Daten!L:L,Daten!E:E,"SELL",Daten!F:F,"STOCK",Daten!G:G,"Infineon Technologies",Daten!H:H,"DE0006231004",Daten!B:B,"="&DATE(2025,10,2)) -> 2.16 | P22: =-( SUMIFS(Daten!K:K,Daten!E:E,"BUY",Daten!F:F,"STOCK",Daten!G:G,"Infineon Technologies",Daten!H:H,"DE0006231004",Daten!B:B,">="&DATE(2025,1,1),Daten!B:B,"<="&DATE(2025,10,2)) + SUMIFS(Daten!L:L,Daten!E:E,"BUY",Daten!F:F,"STOCK",Daten!G:G,"Infineon Technologies",Daten!H:H,"DE0006231004",Daten!B:B,">="&DATE(2025,1,1),Daten!B:B,"<="&DATE(2025,10,2)) + SUMIFS(Daten!K:K,Daten!E:E,"SELL",Daten!F:F,"STOCK",Daten!G:G,"Infineon Technologies",Daten!H:H,"DE0006231004",Daten!B:B,"="&DATE(2025,10,2)) + SUMIFS(Daten!L:L,Daten!E:E,"SELL",Daten!F:F,"STOCK",Daten!G:G,"Infineon Technologies",Daten!H:H,"DE0006231004",Daten!B:B,"="&DATE(2025,10,2)) ) / ( SUMIFS(Daten!K:K,Daten!E:E,"BUY",Daten!F:F,"STOCK",Daten!G:G,"Infineon Technologies",Daten!H:H,"DE0006231004",Daten!B:B,">="&DATE(2025,1,1),Daten!B:B,"<="&DATE(2025,10,2)) + SUMIFS(Daten!L:L,Daten!E:E,"BUY",Daten!F:F,"STOCK",Daten!G:G,"Infineon Technologies",Daten!H:H,"DE0006231004",Daten!B:B,">="&DATE(2025,1,1),Daten!B:B,"<="&DATE(2025,10,2)) ) -> 0.035409836
A23: NVIDIA | B23: =SUMIFS(Daten!K:K,Daten!E:E,"BUY",Daten!F:F,"STOCK",Daten!G:G,"NVIDIA",Daten!H:H,"US67066G1040",Daten!B:B,">="&DATE(2025,1,1),Daten!B:B,"<="&DATE(2025,12,31)) + SUMIFS(Daten!L:L,Daten!E:E,"BUY",Daten!F:F,"STOCK",Daten!G:G,"NVIDIA",Daten!H:H,"US67066G1040",Daten!B:B,">="&DATE(2025,1,1),Daten!B:B,"<="&DATE(2025,12,31)) -> -198 | C23: =SUMIFS(Daten!I:I,Daten!E:E,"BUY",Daten!F:F,"STOCK",Daten!G:G,"NVIDIA",Daten!H:H,"US67066G1040",Daten!B:B,">="&DATE(2025,1,1),Daten!B:B,"<="&DATE(2025,12,31)) -> 1.354399 | D23: =SUMIFS(Daten!K:K,Daten!E:E,"SELL",Daten!F:F,"STOCK",Daten!G:G,"NVIDIA",Daten!H:H,"US67066G1040",Daten!B:B,">="&DATE(2025,1,1),Daten!B:B,"<="&DATE(2025,12,31)) + SUMIFS(Daten!L:L,Daten!E:E,"SELL",Daten!F:F,"STOCK",Daten!G:G,"NVIDIA",Daten!H:H,"US67066G1040",Daten!B:B,">="&DATE(2025,1,1),Daten!B:B,"<="&DATE(2025,12,31)) -> 203.19 | E23: 45910 | F23: =SUMIFS(Daten!K:K,Daten!E:E,"SELL",Daten!F:F,"STOCK",Daten!G:G,"NVIDIA",Daten!H:H,"US67066G1040",Daten!B:B,"="&DATE(2025,9,10)) + SUMIFS(Daten!L:L,Daten!E:E,"SELL",Daten!F:F,"STOCK",Daten!G:G,"NVIDIA",Daten!H:H,"US67066G1040",Daten!B:B,"="&DATE(2025,9,10)) -> 3 | G23: =SUMIFS(Daten!I:I,Daten!E:E,"SELL",Daten!F:F,"STOCK",Daten!G:G,"NVIDIA",Daten!H:H,"US67066G1040",Daten!B:B,"="&DATE(2025,9,10)) -> -0.026957 | H23: =SUMIFS(Daten!I:I,Daten!E:E,"SELL",Daten!F:F,"STOCK",Daten!G:G,"NVIDIA",Daten!H:H,"US67066G1040",Daten!B:B,">="&DATE(2025,1,1),Daten!B:B,"<="&DATE(2025,12,31)) -> -1.354399 | I23: =SUMIFS(Daten!M:M,Daten!E:E,"SELL",Daten!F:F,"STOCK",Daten!G:G,"NVIDIA",Daten!H:H,"US67066G1040",Daten!B:B,"="&DATE(2025,9,10)) -> 0 | J23: =SUMIFS(Daten!M:M,Daten!E:E,"SELL",Daten!F:F,"STOCK",Daten!G:G,"NVIDIA",Daten!H:H,"US67066G1040",Daten!B:B,">="&DATE(2025,1,1),Daten!B:B,"<="&DATE(2025,12,31)) -> -1.6 | K23: =SUMIFS(Daten!I:I,Daten!E:E,"BUY",Daten!F:F,"STOCK",Daten!G:G,"NVIDIA",Daten!H:H,"US67066G1040",Daten!B:B,">="&DATE(2025,1,1),Daten!B:B,"<="&DATE(2025,9,10)) + SUMIFS(Daten!I:I,Daten!E:E,"SELL",Daten!F:F,"STOCK",Daten!G:G,"NVIDIA",Daten!H:H,"US67066G1040",Daten!B:B,">="&DATE(2025,1,1),Daten!B:B,"<="&DATE(2025,9,10)) -> 1.327442 | L23: =SUMIFS(Daten!I:I,Daten!E:E,"BUY",Daten!F:F,"STOCK",Daten!G:G,"NVIDIA",Daten!H:H,"US67066G1040",Daten!B:B,">="&DATE(2025,1,1),Daten!B:B,"<="&DATE(2025,12,31)) + SUMIFS(Daten!I:I,Daten!E:E,"SELL",Daten!F:F,"STOCK",Daten!G:G,"NVIDIA",Daten!H:H,"US67066G1040",Daten!B:B,">="&DATE(2025,1,1),Daten!B:B,"<="&DATE(2025,12,31)) -> 0 | M23: =SUMIFS(Daten!K:K,Daten!E:E,"BUY",Daten!F:F,"STOCK",Daten!G:G,"NVIDIA",Daten!H:H,"US67066G1040",Daten!B:B,">="&DATE(2025,1,1),Daten!B:B,"<="&DATE(2025,9,10)) + SUMIFS(Daten!L:L,Daten!E:E,"BUY",Daten!F:F,"STOCK",Daten!G:G,"NVIDIA",Daten!H:H,"US67066G1040",Daten!B:B,">="&DATE(2025,1,1),Daten!B:B,"<="&DATE(2025,9,10)) -> -198 | N23: =SUMIFS(Daten!K:K,Daten!E:E,"SELL",Daten!F:F,"STOCK",Daten!G:G,"NVIDIA",Daten!H:H,"US67066G1040",Daten!B:B,"="&DATE(2025,9,10)) + SUMIFS(Daten!L:L,Daten!E:E,"SELL",Daten!F:F,"STOCK",Daten!G:G,"NVIDIA",Daten!H:H,"US67066G1040",Daten!B:B,"="&DATE(2025,9,10)) + SUMIFS(Daten!M:M,Daten!E:E,"SELL",Daten!F:F,"STOCK",Daten!G:G,"NVIDIA",Daten!H:H,"US67066G1040",Daten!B:B,"="&DATE(2025,9,10)) -> 3 | O23: =SUMIFS(Daten!K:K,Daten!E:E,"BUY",Daten!F:F,"STOCK",Daten!G:G,"NVIDIA",Daten!H:H,"US67066G1040",Daten!B:B,">="&DATE(2025,1,1),Daten!B:B,"<="&DATE(2025,9,10)) + SUMIFS(Daten!L:L,Daten!E:E,"BUY",Daten!F:F,"STOCK",Daten!G:G,"NVIDIA",Daten!H:H,"US67066G1040",Daten!B:B,">="&DATE(2025,1,1),Daten!B:B,"<="&DATE(2025,9,10)) + SUMIFS(Daten!K:K,Daten!E:E,"SELL",Daten!F:F,"STOCK",Daten!G:G,"NVIDIA",Daten!H:H,"US67066G1040",Daten!B:B,"="&DATE(2025,9,10)) + SUMIFS(Daten!L:L,Daten!E:E,"SELL",Daten!F:F,"STOCK",Daten!G:G,"NVIDIA",Daten!H:H,"US67066G1040",Daten!B:B,"="&DATE(2025,9,10)) -> -195 | P23: =-( SUMIFS(Daten!K:K,Daten!E:E,"BUY",Daten!F:F,"STOCK",Daten!G:G,"NVIDIA",Daten!H:H,"US67066G1040",Daten!B:B,">="&DATE(2025,1,1),Daten!B:B,"<="&DATE(2025,9,10)) + SUMIFS(Daten!L:L,Daten!E:E,"BUY",Daten!F:F,"STOCK",Daten!G:G,"NVIDIA",Daten!H:H,"US67066G1040",Daten!B:B,">="&DATE(2025,1,1),Daten!B:B,"<="&DATE(2025,9,10)) + SUMIFS(Daten!K:K,Daten!E:E,"SELL",Daten!F:F,"STOCK",Daten!G:G,"NVIDIA",Daten!H:H,"US67066G1040",Daten!B:B,"="&DATE(2025,9,10)) + SUMIFS(Daten!L:L,Daten!E:E,"SELL",Daten!F:F,"STOCK",Daten!G:G,"NVIDIA",Daten!H:H,"US67066G1040",Daten!B:B,"="&DATE(2025,9,10)) ) / ( SUMIFS(Daten!K:K,Daten!E:E,"BUY",Daten!F:F,"STOCK",Daten!G:G,"NVIDIA",Daten!H:H,"US67066G1040",Daten!B:B,">="&DATE(2025,1,1),Daten!B:B,"<="&DATE(2025,9,10)) + SUMIFS(Daten!L:L,Daten!E:E,"BUY",Daten!F:F,"STOCK",Daten!G:G,"NVIDIA",Daten!H:H,"US67066G1040",Daten!B:B,">="&DATE(2025,1,1),Daten!B:B,"<="&DATE(2025,9,10)) ) -> -0.98484848
A24: NVIDIA | E24: 45924 | F24: =SUMIFS(Daten!K:K,Daten!E:E,"SELL",Daten!F:F,"STOCK",Daten!G:G,"NVIDIA",Daten!H:H,"US67066G1040",Daten!B:B,"="&DATE(2025,9,24)) + SUMIFS(Daten!L:L,Daten!E:E,"SELL",Daten!F:F,"STOCK",Daten!G:G,"NVIDIA",Daten!H:H,"US67066G1040",Daten!B:B,"="&DATE(2025,9,24)) -> 200.19 | G24: =SUMIFS(Daten!I:I,Daten!E:E,"SELL",Daten!F:F,"STOCK",Daten!G:G,"NVIDIA",Daten!H:H,"US67066G1040",Daten!B:B,"="&DATE(2025,9,24)) -> -1.327442 | I24: =SUMIFS(Daten!M:M,Daten!E:E,"SELL",Daten!F:F,"STOCK",Daten!G:G,"NVIDIA",Daten!H:H,"US67066G1040",Daten!B:B,"="&DATE(2025,9,24)) -> -1.6 | K24: =SUMIFS(Daten!I:I,Daten!E:E,"BUY",Daten!F:F,"STOCK",Daten!G:G,"NVIDIA",Daten!H:H,"US67066G1040",Daten!B:B,">="&DATE(2025,1,1),Daten!B:B,"<="&DATE(2025,9,24)) + SUMIFS(Daten!I:I,Daten!E:E,"SELL",Daten!F:F,"STOCK",Daten!G:G,"NVIDIA",Daten!H:H,"US67066G1040",Daten!B:B,">="&DATE(2025,1,1),Daten!B:B,"<="&DATE(2025,9,24)) -> 0 | M24: =SUMIFS(Daten!K:K,Daten!E:E,"BUY",Daten!F:F,"STOCK",Daten!G:G,"NVIDIA",Daten!H:H,"US67066G1040",Daten!B:B,">="&DATE(2025,1,1),Daten!B:B,"<="&DATE(2025,9,24)) + SUMIFS(Daten!L:L,Daten!E:E,"BUY",Daten!F:F,"STOCK",Daten!G:G,"NVIDIA",Daten!H:H,"US67066G1040",Daten!B:B,">="&DATE(2025,1,1),Daten!B:B,"<="&DATE(2025,9,24)) -> -198 | N24: =SUMIFS(Daten!K:K,Daten!E:E,"SELL",Daten!F:F,"STOCK",Daten!G:G,"NVIDIA",Daten!H:H,"US67066G1040",Daten!B:B,"="&DATE(2025,9,24)) + SUMIFS(Daten!L:L,Daten!E:E,"SELL",Daten!F:F,"STOCK",Daten!G:G,"NVIDIA",Daten!H:H,"US67066G1040",Daten!B:B,"="&DATE(2025,9,24)) + SUMIFS(Daten!M:M,Daten!E:E,"SELL",Daten!F:F,"STOCK",Daten!G:G,"NVIDIA",Daten!H:H,"US67066G1040",Daten!B:B,"="&DATE(2025,9,24)) -> 198.59 | O24: =SUMIFS(Daten!K:K,Daten!E:E,"BUY",Daten!F:F,"STOCK",Daten!G:G,"NVIDIA",Daten!H:H,"US67066G1040",Daten!B:B,">="&DATE(2025,1,1),Daten!B:B,"<="&DATE(2025,9,24)) + SUMIFS(Daten!L:L,Daten!E:E,"BUY",Daten!F:F,"STOCK",Daten!G:G,"NVIDIA",Daten!H:H,"US67066G1040",Daten!B:B,">="&DATE(2025,1,1),Daten!B:B,"<="&DATE(2025,9,24)) + SUMIFS(Daten!K:K,Daten!E:E,"SELL",Daten!F:F,"STOCK",Daten!G:G,"NVIDIA",Daten!H:H,"US67066G1040",Daten!B:B,"="&DATE(2025,9,24)) + SUMIFS(Daten!L:L,Daten!E:E,"SELL",Daten!F:F,"STOCK",Daten!G:G,"NVIDIA",Daten!H:H,"US67066G1040",Daten!B:B,"="&DATE(2025,9,24)) -> 2.19
A25: Palantir Technologies | B25: =SUMIFS(Daten!K:K,Daten!E:E,"BUY",Daten!F:F,"STOCK",Daten!G:G,"Palantir Technologies",Daten!H:H,"US69608A1088",Daten!B:B,">="&DATE(2025,1,1),Daten!B:B,"<="&DATE(2025,12,31)) + SUMIFS(Daten!L:L,Daten!E:E,"BUY",Daten!F:F,"STOCK",Daten!G:G,"Palantir Technologies",Daten!H:H,"US69608A1088",Daten!B:B,">="&DATE(2025,1,1),Daten!B:B,"<="&DATE(2025,12,31)) -> -150 | C25: =SUMIFS(Daten!I:I,Daten!E:E,"BUY",Daten!F:F,"STOCK",Daten!G:G,"Palantir Technologies",Daten!H:H,"US69608A1088",Daten!B:B,">="&DATE(2025,1,1),Daten!B:B,"<="&DATE(2025,12,31)) -> 1.052408
A26: Plug Power | B26: =SUMIFS(Daten!K:K,Daten!E:E,"BUY",Daten!F:F,"STOCK",Daten!G:G,"Plug Power",Daten!H:H,"US72919P2020",Daten!B:B,">="&DATE(2025,1,1),Daten!B:B,"<="&DATE(2025,12,31)) + SUMIFS(Daten!L:L,Daten!E:E,"BUY",Daten!F:F,"STOCK",Daten!G:G,"Plug Power",Daten!H:H,"US72919P2020",Daten!B:B,">="&DATE(2025,1,1),Daten!B:B,"<="&DATE(2025,12,31)) -> -101 | C26: =SUMIFS(Daten!I:I,Daten!E:E,"BUY",Daten!F:F,"STOCK",Daten!G:G,"Plug Power",Daten!H:H,"US72919P2020",Daten!B:B,">="&DATE(2025,1,1),Daten!B:B,"<="&DATE(2025,12,31)) -> 30.562347
A27: Quantum eMotion | B27: =SUMIFS(Daten!K:K,Daten!E:E,"BUY",Daten!F:F,"STOCK",Daten!G:G,"Quantum eMotion",Daten!H:H,"CA74767K1030",Daten!B:B,">="&DATE(2025,1,1),Daten!B:B,"<="&DATE(2025,12,31)) + SUMIFS(Daten!L:L,Daten!E:E,"BUY",Daten!F:F,"STOCK",Daten!G:G,"Quantum eMotion",Daten!H:H,"CA74767K1030",Daten!B:B,">="&DATE(2025,1,1),Daten!B:B,"<="&DATE(2025,12,31)) -> -90 | C27: =SUMIFS(Daten!I:I,Daten!E:E,"BUY",Daten!F:F,"STOCK",Daten!G:G,"Quantum eMotion",Daten!H:H,"CA74767K1030",Daten!B:B,">="&DATE(2025,1,1),Daten!B:B,"<="&DATE(2025,12,31)) -> 28.343949
A28: Red Cat | B28: =SUMIFS(Daten!K:K,Daten!E:E,"BUY",Daten!F:F,"STOCK",Daten!G:G,"Red Cat",Daten!H:H,"US75644T1007",Daten!B:B,">="&DATE(2025,1,1),Daten!B:B,"<="&DATE(2025,12,31)) + SUMIFS(Daten!L:L,Daten!E:E,"BUY",Daten!F:F,"STOCK",Daten!G:G,"Red Cat",Daten!H:H,"US75644T1007",Daten!B:B,">="&DATE(2025,1,1),Daten!B:B,"<="&DATE(2025,12,31)) -> -99.71 | C28: =SUMIFS(Daten!I:I,Daten!E:E,"BUY",Daten!F:F,"STOCK",Daten!G:G,"Red Cat",Daten!H:H,"US75644T1007",Daten!B:B,">="&DATE(2025,1,1),Daten!B:B,"<="&DATE(2025,12,31)) -> 14.265129
A29: RENK Group | B29: =SUMIFS(Daten!K:K,Daten!E:E,"BUY",Daten!F:F,"STOCK",Daten!G:G,"RENK Group",Daten!H:H,"DE000RENK730",Daten!B:B,">="&DATE(2025,1,1),Daten!B:B,"<="&DATE(2025,12,31)) + SUMIFS(Daten!L:L,Daten!E:E,"BUY",Daten!F:F,"STOCK",Daten!G:G,"RENK Group",Daten!H:H,"DE000RENK730",Daten!B:B,">="&DATE(2025,1,1),Daten!B:B,"<="&DATE(2025,12,31)) -> -80 | C29: =SUMIFS(Daten!I:I,Daten!E:E,"BUY",Daten!F:F,"STOCK",Daten!G:G,"RENK Group",Daten!H:H,"DE000RENK730",Daten!B:B,">="&DATE(2025,1,1),Daten!B:B,"<="&DATE(2025,12,31)) -> 1.134894
A30: RWE | B30: =SUMIFS(Daten!K:K,Daten!E:E,"BUY",Daten!F:F,"STOCK",Daten!G:G,"RWE",Daten!H:H,"DE0007037129",Daten!B:B,">="&DATE(2025,1,1),Daten!B:B,"<="&DATE(2025,12,31)) + SUMIFS(Daten!L:L,Daten!E:E,"BUY",Daten!F:F,"STOCK",Daten!G:G,"RWE",Daten!H:H,"DE0007037129",Daten!B:B,">="&DATE(2025,1,1),Daten!B:B,"<="&DATE(2025,12,31)) -> -50 | C30: =SUMIFS(Daten!I:I,Daten!E:E,"BUY",Daten!F:F,"STOCK",Daten!G:G,"RWE",Daten!H:H,"DE0007037129",Daten!B:B,">="&DATE(2025,1,1),Daten!B:B,"<="&DATE(2025,12,31)) -> 1.368332
A31: Siemens Energy | B31: =SUMIFS(Daten!K:K,Daten!E:E,"BUY",Daten!F:F,"STOCK",Daten!G:G,"Siemens Energy",Daten!H:H,"DE000ENER6Y0",Daten!B:B,">="&DATE(2025,1,1),Daten!B:B,"<="&DATE(2025,12,31)) + SUMIFS(Daten!L:L,Daten!E:E,"BUY",Daten!F:F,"STOCK",Daten!G:G,"Siemens Energy",Daten!H:H,"DE000ENER6Y0",Daten!B:B,">="&DATE(2025,1,1),Daten!B:B,"<="&DATE(2025,12,31)) -> -91 | C31: =SUMIFS(Daten!I:I,Daten!E:E,"BUY",Daten!F:F,"STOCK",Daten!G:G,"Siemens Energy",Daten!H:H,"DE000ENER6Y0",Daten!B:B,">="&DATE(2025,1,1),Daten!B:B,"<="&DATE(2025,12,31)) -> 1.017408
A32: Siltronic | B32: =SUMIFS(Daten!K:K,Daten!E:E,"BUY",Daten!F:F,"STOCK",Daten!G:G,"Siltronic",Daten!H:H,"DE000WAF3001",Daten!B:B,">="&DATE(2025,1,1),Daten!B:B,"<="&DATE(2025,12,31)) + SUMIFS(Daten!L:L,Daten!E:E,"BUY",Daten!F:F,"STOCK",Daten!G:G,"Siltronic",Daten!H:H,"DE000WAF3001",Daten!B:B,">="&DATE(2025,1,1),Daten!B:B,"<="&DATE(2025,12,31)) -> -81 | C32: =SUMIFS(Daten!I:I,Daten!E:E,"BUY",Daten!F:F,"STOCK",Daten!G:G,"Siltronic",Daten!H:H,"DE000WAF3001",Daten!B:B,">="&DATE(2025,1,1),Daten!B:B,"<="&DATE(2025,12,31)) -> 2
A33: TeamViewer | B33: =SUMIFS(Daten!K:K,Daten!E:E,"BUY",Daten!F:F,"STOCK",Daten!G:G,"TeamViewer",Daten!H:H,"DE000A2YN900",Daten!B:B,">="&DATE(2025,1,1),Daten!B:B,"<="&DATE(2025,12,31)) + SUMIFS(Daten!L:L,Daten!E:E,"BUY",Daten!F:F,"STOCK",Daten!G:G,"TeamViewer",Daten!H:H,"DE000A2YN900",Daten!B:B,">="&DATE(2025,1,1),Daten!B:B,"<="&DATE(2025,12,31)) -> -100 | C33: =SUMIFS(Daten!I:I,Daten!E:E,"BUY",Daten!F:F,"STOCK",Daten!G:G,"TeamViewer",Daten!H:H,"DE000A2YN900",Daten!B:B,">="&DATE(2025,1,1),Daten!B:B,"<="&DATE(2025,12,31)) -> 16.737109
A34: ThyssenKrupp | B34: =SUMIFS(Daten!K:K,Daten!E:E,"BUY",Daten!F:F,"STOCK",Daten!G:G,"ThyssenKrupp",Daten!H:H,"DE0007500001",Daten!B:B,">="&DATE(2025,1,1),Daten!B:B,"<="&DATE(2025,12,31)) + SUMIFS(Daten!L:L,Daten!E:E,"BUY",Daten!F:F,"STOCK",Daten!G:G,"ThyssenKrupp",Daten!H:H,"DE0007500001",Daten!B:B,">="&DATE(2025,1,1),Daten!B:B,"<="&DATE(2025,12,31)) -> -22.99 | C34: =SUMIFS(Daten!I:I,Daten!E:E,"BUY",Daten!F:F,"STOCK",Daten!G:G,"ThyssenKrupp",Daten!H:H,"DE0007500001",Daten!B:B,">="&DATE(2025,1,1),Daten!B:B,"<="&DATE(2025,12,31)) -> 2.186878
A35: UiPath | B35: =SUMIFS(Daten!K:K,Daten!E:E,"BUY",Daten!F:F,"STOCK",Daten!H:H,"US90364P1057",Daten!B:B,">="&DATE(2025,1,1),Daten!B:B,"<="&DATE(2025,12,31)) + SUMIFS(Daten!L:L,Daten!E:E,"BUY",Daten!F:F,"STOCK",Daten!H:H,"US90364P1057",Daten!B:B,">="&DATE(2025,1,1),Daten!B:B,"<="&DATE(2025,12,31)) -> -116.99 | C35: =SUMIFS(Daten!I:I,Daten!E:E,"BUY",Daten!F:F,"STOCK",Daten!H:H,"US90364P1057",Daten!B:B,">="&DATE(2025,1,1),Daten!B:B,"<="&DATE(2025,12,31)) -> 7.211239
A36: Volatus Aerospace | B36: =SUMIFS(Daten!K:K,Daten!E:E,"BUY",Daten!F:F,"STOCK",Daten!G:G,"Volatus Aerospace",Daten!H:H,"CA92865M1023",Daten!B:B,">="&DATE(2025,1,1),Daten!B:B,"<="&DATE(2025,12,31)) + SUMIFS(Daten!L:L,Daten!E:E,"BUY",Daten!F:F,"STOCK",Daten!G:G,"Volatus Aerospace",Daten!H:H,"CA92865M1023",Daten!B:B,">="&DATE(2025,1,1),Daten!B:B,"<="&DATE(2025,12,31)) -> -18.8 | C36: =SUMIFS(Daten!I:I,Daten!E:E,"BUY",Daten!F:F,"STOCK",Daten!G:G,"Volatus Aerospace",Daten!H:H,"CA92865M1023",Daten!B:B,">="&DATE(2025,1,1),Daten!B:B,"<="&DATE(2025,12,31)) -> 50
A37: Voltabox | B37: =SUMIFS(Daten!K:K,Daten!E:E,"BUY",Daten!F:F,"STOCK",Daten!G:G,"Voltabox",Daten!H:H,"DE000A2E4LE9",Daten!B:B,">="&DATE(2025,1,1),Daten!B:B,"<="&DATE(2025,12,31)) + SUMIFS(Daten!L:L,Daten!E:E,"BUY",Daten!F:F,"STOCK",Daten!G:G,"Voltabox",Daten!H:H,"DE000A2E4LE9",Daten!B:B,">="&DATE(2025,1,1),Daten!B:B,"<="&DATE(2025,12,31)) -> -70 | C37: =SUMIFS(Daten!I:I,Daten!E:E,"BUY",Daten!F:F,"STOCK",Daten!G:G,"Voltabox",Daten!H:H,"DE000A2E4LE9",Daten!B:B,">="&DATE(2025,1,1),Daten!B:B,"<="&DATE(2025,12,31)) -> 15.401785
A38: Vulcan Energy Resources | B38: =SUMIFS(Daten!K:K,Daten!E:E,"BUY",Daten!F:F,"STOCK",Daten!G:G,"Vulcan Energy Resources",Daten!H:H,"AU0000066086",Daten!B:B,">="&DATE(2025,1,1),Daten!B:B,"<="&DATE(2025,12,31)) + SUMIFS(Daten!L:L,Daten!E:E,"BUY",Daten!F:F,"STOCK",Daten!G:G,"Vulcan Energy Resources",Daten!H:H,"AU0000066086",Daten!B:B,">="&DATE(2025,1,1),Daten!B:B,"<="&DATE(2025,12,31)) -> -29 | C38: =SUMIFS(Daten!I:I,Daten!E:E,"BUY",Daten!F:F,"STOCK",Daten!G:G,"Vulcan Energy Resources",Daten!H:H,"AU0000066086",Daten!B:B,">="&DATE(2025,1,1),Daten!B:B,"<="&DATE(2025,12,31)) -> 12.345679
A40: STOCK Gesamt 2025: | B40: =SUMIFS(Daten!K:K,Daten!E:E,"BUY",Daten!F:F,"STOCK",Daten!B:B,">="&DATE(2025,1,1),Daten!B:B,"<="&DATE(2025,12,31)) + SUMIFS(Daten!L:L,Daten!E:E,"BUY",Daten!F:F,"STOCK",Daten!B:B,">="&DATE(2025,1,1),Daten!B:B,"<="&DATE(2025,12,31)) -> -3210.97 | C40: =SUMIFS(Daten!I:I,Daten!E:E,"BUY",Daten!F:F,"STOCK",Daten!B:B,">="&DATE(2025,1,1),Daten!B:B,"<="&DATE(2025,12,31)) -> 561.73148
A43: =ISNUMBER(Daten!B2) -> TRUE
N44: =D18+I18 -> 422.71 | O44: =M18+F18 -> 89.51 | P44: =-O18/M18 -> 0.25086883

Sheet 2026
A1: Einnahmen 2026: | B1: =SUMIFS(Daten!K:K,Daten!E:E,"TRANSFER_INSTANT_INBOUND",Daten!B:B,">="&DATE(2026,1,1),Daten!B:B,"<="&DATE(2026,12,31)) + SUMIFS(Daten!K:K,Daten!E:E,"TRANSFER_IN",Daten!B:B,">="&DATE(2026,1,1),Daten!B:B,"<="&DATE(2026,12,31)) + SUMIFS(Daten!K:K,Daten!E:E,"GIFT",Daten!B:B,">="&DATE(2026,1,1),Daten!B:B,"<="&DATE(2026,12,31)) + SUMIFS(Daten!K:K,Daten!E:E,"DIVIDEND",Daten!B:B,">="&DATE(2026,1,1),Daten!B:B,"<="&DATE(2026,12,31)) + SUMIFS(Daten!K:K,Daten!E:E,"CUSTOMER_INPAYMENT",Daten!B:B,">="&DATE(2026,1,1),Daten!B:B,"<="&DATE(2026,12,31)) -> 18337.03
A2: Gebüren Käufe 2026: | B2: =SUMIFS(Daten!L:L,Daten!E:E,"BUY",Daten!B:B,">="&DATE(2026,1,1),Daten!B:B,"<="&DATE(2026,12,31)) -> -161
A3: Gebüren Verkäufe 2026: | B3: =SUMIFS(Daten!L:L,Daten!E:E,"SELL",Daten!B:B,">="&DATE(2026,1,1),Daten!B:B,"<="&DATE(2026,12,31)) -> -46
A4: Gebüren 2026: | B4: =SUMIFS(Daten!L:L,Daten!B:B,">="&DATE(2026,1,1),Daten!B:B,"<="&DATE(2026,12,31)) -> -207
A5: Steuern STOCK Gesamt 2026: | B5: =SUMIFS(Daten!M:M,Daten!F:F,"STOCK",Daten!B:B,">="&DATE(2026,1,1),Daten!B:B,"<="&DATE(2026,12,31)) -> -16.47
A6: Steuern CRYPTO Gesamt 2026: | B6: =SUMIFS(Daten!M:M,Daten!F:F,"CRYPTO",Daten!B:B,">="&DATE(2026,1,1),Daten!B:B,"<="&DATE(2026,12,31)) -> 0
A7: Steuern Gesamt 2026: | B7: =SUMIFS(Daten!M:M,Daten!B:B,">="&DATE(2026,1,1),Daten!B:B,"<="&DATE(2026,12,31)) -> 0
A8: Auszahlungen Gesamt 2026: | B8: =SUMIFS(Daten!K:K,Daten!E:E,"TRANSFER_INSTANT_OUTBOUND",Daten!B:B,">="&DATE(2026,1,1),Daten!B:B,"<="&DATE(2026,12,31)) + SUMIFS(Daten!K:K,Daten!E:E,"TRANSFER_OUT",Daten!B:B,">="&DATE(2026,1,1),Daten!B:B,"<="&DATE(2026,12,31)) + SUMIFS(Daten!K:K,Daten!E:E,"TRANSFER_OUTBOUND",Daten!B:B,">="&DATE(2026,1,1),Daten!B:B,"<="&DATE(2026,12,31)) -> -7382.68

Sheet Einnahmen
A1: Alle Einnahmen | B1: =SUMIFS(Daten!K:K,Daten!E:E,"TRANSFER_INSTANT_INBOUND") + SUMIFS(Daten!K:K,Daten!E:E,"TRANSFER_IN") -> 21829.12

Sheet Käufe

Sheet Verkäufe

Sheet Ausgaben

Sheet Dividende
